Workbook

Sheet Summary
A1: Carry1st x Yuno · LatAm Shop launch · Business case summary
A2: Brazil, Argentina, Mexico, Bolivia, Colombia · EBANX direct vs EBANX + dLocal through Yuno · $10 average ticket, $5 median · USD · Confidential, prepared for Carry1st, 15 Oct 2026
B4: Run-rate transactions / month | C4: Run-rate TPV / year | D4: Option A cost / year (run rate) | E4: Option B cost / year (provider + Yuno) | F4: Net benefit / year, base (contribution) | G4: Break-even tx / month, base
B5: =Model!I5 | C5: =Model!I6*12 | D5: =Model!I44 | E5: =Model!I45 | F5: =Model!I48 | G5: =BreakEven!C6
B7: Base scenario by volume tier (monthly) | D7: =Inputs!$D$8 | E7: =Inputs!$D$9 | F7: =Inputs!$D$10 | G7: =Inputs!$D$11
B8: Net TPV a month | D8: =Model!F6 | E8: =Model!G6 | F8: =Model!H6 | G8: =Model!I6
B9: Option A cost | D9: =Model!F9 | E9: =Model!G9 | F9: =Model!H9 | G9: =Model!I9
B10: Option B cost (provider + Yuno) | D10: =Model!F25 | E10: =Model!G25 | F10: =Model!H25 | G10: =Model!I25
B11: of which Yuno | D11: =Model!F22 | E11: =Model!G22 | F11: =Model!H22 | G11: =Model!I22
B12: Yuno, % of TPV | D12: =Model!F23 | E12: =Model!G23 | F12: =Model!H23 | G12: =Model!I23
B13: Option A, $ per $1,000 TPV | D13: =Model!F10 | E13: =Model!G10 | F13: =Model!H10 | G13: =Model!I10
B14: Option B, $ per $1,000 TPV | D14: =Model!F26 | E14: =Model!G26 | F14: =Model!H26 | G14: =Model!I26
B15: Option B after levers, $ per $1,000 | D15: =Model!F40 | E15: =Model!G40 | F15: =Model!H40 | G15: =Model!I40
B16: Gross benefit (contribution) | D16: =Model!F36 | E16: =Model!G36 | F16: =Model!H36 | G16: =Model!I36
B17: Net benefit (contribution) | D17: =Model!F38 | E17: =Model!G38 | F17: =Model!H38 | G17: =Model!I38
B18: Net benefit (GMV view) | D18: =Model!F39 | E18: =Model!G39 | F18: =Model!H39 | G18: =Model!I39
B20: Three scenarios (contribution view) | D20: Conservative | E20: Base | F20: Optimistic
B21: Net a month at launch (tier 1) | D21: =Model!B38 | E21: =Model!F38 | F21: =Model!J38
B22: Net a month at run rate (tier 4) | D22: =Model!E38 | E22: =Model!I38 | F22: =Model!M38
B23: Net a year at run rate | D23: =Model!E48 | E23: =Model!I48 | F23: =Model!M48
B24: Gross / Yuno cost at run rate | D24: =Model!E42 | E24: =Model!I42 | F24: =Model!M42
B25: Break-even transactions a month | D25: =BreakEven!C5 | E25: =BreakEven!C6 | F25: =BreakEven!C7
B26: Payback month on the ramp | D26: =Ramp!C5 | E26: =Ramp!C6 | F26: =Ramp!C7
B28: How to read: Option A = EBANX direct at the baseline all-in cost (ESTIMATE until EBANX's quote replaces the baseline on Inputs). Option B = EBANX primary + dLocal second MoR through Yuno; its provider cost is the baseline minus the MDR reduction, plus Yuno's flat platform fee and usage in bps on the Net TPV above the included block. Levers: L1 MDR saving (100% contribution), L2 retries and routing, L3 local methods, L4 engineering saved. Contribution view nets the take rate and processing cost on incremental GMV. Yuno-wide figures used only as guardrails: 7% authorization uplift, 30% recovered revenue (y.uno).

Sheet Inputs
A1: Carry1st x Yuno · LatAm Shop launch · Inputs (single source of truth)
A2: Blue = input you can change. Yellow = ESTIMATE to validate. Green = linked. Every value carries its source or an ESTIMATE tag and an owner. USD only. 15 Oct 2026.
B4: Assumption | C4: Unit | D4: Conservative | E4: Base | F4: Optimistic | G4: Source · tag | H4: Owner to validate
B5: 1 · Volume and ticket (Carry1st)
B6: Average ticket | C6: USD | D6: 10 | E6: =D6 | F6: =D6 | G6: Carry1st, Cordel, discovery call 15 Oct 2026 (estimate). Drives TPV = transactions x ticket. | H6: Cordel (written volumes owed)
B7: Median ticket (small-ticket sensitivity) | C7: USD | D7: 5 | E7: =D7 | F7: =D7 | G7: Carry1st, Cordel, 15 Oct 2026 (estimate). Used on the Pricing and Sensitivity sheets only. | H7: Cordel
B8: Tier 1 · successful transactions a month (launch) | C8: tx | D8: 50000 | E8: =D8 | F8: =D8 | G8: Modeling tier agreed with Justo Benetti (CRO), 15 Oct 2026. Launch volume unknown; Cordel owes volumes by country. | H8: Cordel
B9: Tier 2 · successful transactions a month | C9: tx | D9: 100000 | E9: =D9 | F9: =D9 | G9: Modeling tier (ramp step).
B10: Tier 3 · successful transactions a month | C10: tx | D10: 200000 | E10: =D10 | F10: =D10 | G10: Modeling tier (ramp step).
B11: Tier 4 · successful transactions a month (run rate) | C11: tx | D11: 450000 | E11: =D11 | F11: =D11 | G11: Carry1st estimate, Cordel, Oct 2026, not yet aligned internally: $4 to 5M a month in LatAm by end 2027, about 450K transactions at a $10 ticket. | H11: Cordel
B12: Run-rate TPV a month (derived) | C12: USD | D12: =D11*D6 | E12: =D12 | F12: =D12 | G12: Derived: tier 4 x average ticket. Compare with Cordel's $4 to 5M a month (Carry1st estimate, Oct 2026).
B13: Carry1st take rate on GMV (contribution per $1 of ticket) | C13: % | D13: 0.15 | E13: =D13 | F13: =D13 | G13: ESTIMATE, TO VALIDATE with Cordel. Carry1st Shop resells third-party top-ups and gift cards, so its economics are a margin on GMV, not the full ticket. Public reseller benchmarks: 5 to 15% above wholesale for mainstream gift cards, 3 to 8% workable range on Google Play cards (marix.app guides, 2026). | H13: German with Cordel
B14: Net incremental GMV of processing cost? (1 = yes, 0 = no) | C14: flag | D14: 1 | E14: =D14 | F14: =D14 | G14: Yuno modeling choice. With 1, contribution on incremental GMV = GMV x (take rate minus Option B all-in processing %). With 0, contribution = GMV x take rate (the simpler, higher view). | H14: German
B15: 2 · Baseline provider cost (EBANX direct, cross-border MoR all-in incl. FX and local taxes passed through)
B16: Baseline provider all-in cost, % of TPV <<< REPLACE FIRST with EBANX's quote to Carry1st | C16: % | D16: 0.045 | E16: =D16 | F16: =D16 | G16: ESTIMATE, range 3 to 6% of TPV. Anchors: dLocal FY2025 revenue / TPV = 2.68% (2.92% in 2024), a blended figure across pay-ins, pay-outs and very large merchants, so a low anchor for a $0.5 to 4.5M a month digital-goods merchant (FXC Intelligence, 26 Mar 2026, on dLocal's results of 18 Mar 2026). EBANX reviewer: about 5% per transaction plus a $200 monthly fee (Capterra, Nov 2021). FX spread of 1 to 3% on top of processing (Nuvei, 2026). Brazil IOF on FX 3.5% (Decree 12,466/2025, PayPro Global). | H16: Cordel (EBANX quote) · Justo
B17: Baseline provider cost · low end (sensitivity) | C17: % | D17: 0.03 | E17: =D17 | F17: =D17 | G17: Low end of the sourced range (dLocal blended take rate, large-merchant pricing).
B18: Baseline provider cost · high end (sensitivity) | C18: % | D18: 0.06 | E18: =D18 | F18: =D18 | G18: High end of the sourced range (small-ticket digital goods, FX spread and taxes passed through).
B19: 3 · Lever 1 · MDR reduction with a second provider in play
B20: MDR reduction on total TPV (second MoR in play + routing share to the cheaper route) | C20: bps | D20: 25 | E20: 50 | F20: 75 | G20: Yuno estimate. Brief from Justo Benetti, 15 Oct 2026. Reference ranges: multi-acquirer negotiating leverage 7.5 to 12.5 bps mid-market; cross-border to local reclassification about 60 bps (Yuno value model). 100% contribution: a cost saving, not a GMV effect. | H20: Justo · EBANX and dLocal rates through Yuno (open)
B21: 4 · Lever 2 · Retries and routing recovery
B22: Baseline approval rate on a single MoR route (blended methods) | C22: % | D22: 0.75 | E22: =D22 | F22: =D22 | G22: ESTIMATE, range 70 to 85%. Public anchors: Mexico local acquiring 80%+ vs cross-border 50 to 60% (Nuvei, 2026); Brazil cross-border card authorization under 60% vs 90%+ on local rails (Antom, 2025); approval gap of 10 to 20 points by processing setup (Rapyd LatAm playbook, May 2026). A MoR processes locally, so 75% sits between the cross-border and local figures. | H22: Cordel (Saudi/Africa approval as proxy) · EBANX
B23: Approval uplift on attempted volume (soft-decline retries, outage failover, second-provider retry) | C23: pp | D23: 0.015 | E23: 0.03 | F23: 0.05 | G23: Yuno estimate. Ceiling = Yuno published 7% authorization uplift (y.uno); the optimistic case stays below it. Soft declines are 80 to 90% of failed payments (Paddle); 20 to 40% of soft declines are recoverable with retries (vendor benchmarks, 2025). On a 75% baseline that supports 4 to 8 points; the model uses 1.5 / 3 / 5. | H23: Yuno (routing data after launch)
B24: 5 · Lever 3 · Local-method coverage uplift
B25: Incremental GMV from local methods the single-provider route lacks, % of TPV | C25: % | D25: 0.005 | E25: 0.01 | F25: 0.02 | G25: ESTIMATE. Methods carried through Yuno via dLocal and not on the EBANX connection (docs.y.uno Payment Type list, 14 Oct 2026): Argentina MODO, Rapipago, Pago Facil; Colombia Bre-B, Nequi, PSE, Efecty; Bolivia Multipago, Pago al Paso; Mexico CoDi, Paynet, 7-Eleven. Context: Pix = 42% of Brazil e-commerce value in 2025 (Worldpay GPR 2026 via Poder360); account-to-account 15% and wallets 39% of Argentina e-commerce value 2025 (GPR 2026 via LetsMoney); QR = 36% of payments in Bolivia in 2025 (Banco Central de Bolivia via Los Tiempos, Jun 2026). EBANX direct coverage per country TO VALIDATE against its quote. | H25: German · research agent (coverage)
B26: 6 · Lever 4 · Engineering saved (one integration for five countries)
B27: Direct integrations avoided over the horizon (dLocal as second provider, then local-entity processors) | C27: count | D27: 1 | E27: 2 | F27: 3 | G27: Yuno estimate. Option A needs a second direct integration (dLocal) for failover and leverage, then re-integration to local processors when Phase 2 (local entities) lands. Under Option B each is a routing change. The launch integration itself is not counted (both options need one). | H27: Fatih (Carry1st tech)
B28: Engineer-weeks per direct PSP integration (build, certification, QA) | C28: weeks | D28: 4 | E28: 6 | F28: 8 | G28: Server-to-server PSP integration 4 to 8 weeks; orchestration or direct acquiring 8 to 12+ weeks (spd.tech, 2026). Razorpay: 2 to 3 developer-weeks per gateway for code alone (dev.to, 2025). Gateway migration 2 to 4 weeks (mctaba.com). | H28: Fatih
B29: Loaded cost per engineer-week | C29: USD | D29: 2000 | E29: =D29 | F29: =D29 | G29: ESTIMATE, about $104K a year loaded. Sits between Cape Town senior engineer market pay (PayScale, 2026; Carry1st engineers are in Cape Town) and LatAm loaded cost of $87.5K to $100.8K a year (Second Talent, 2026); US fully loaded is $200K to $280K (Revelo, 2026). | H29: Fatih
B30: Annual maintenance, % of build cost per integration | C30: % | D30: 0.2 | E30: 0.25 | F30: 0.3 | G30: Yuno estimate; 20 to 30% upkeep is the convention used in Yuno business cases (Oct 2026).
B31: Horizon to spread one-time engineering (months) | C31: months | D31: 24 | E31: =D31 | F31: =D31 | G31: Yuno modeling choice: build cost plus maintenance spread over 24 months, shown as a monthly equivalent.
B32: 7 · Yuno cost line (the proposal, pricing v4: bps on monthly Net TPV)
B33: Platform fee a month (flat) | C33: USD | D33: 7500 | E33: =D33 | F33: =D33 | G33: Justo Benetti, 15 Oct 2026: $7,500 a month flat platform fee that includes a block of monthly Net TPV. Net TPV = successful transactions only, no declines, no chargebacks. | H33: Justo · Finance (approval pending)
B34: Monthly Net TPV included in the platform fee (single month, no rollover) | C34: USD | D34: 500000 | E34: =D34 | F34: =D34 | G34: Pricing v4, German's decision, 15 Oct 2026. Justo's rule: pay-ins are billed in bps on TPV, so the included block is in TPV, never in transactions (units must match). At a $10 ticket this block is about 50,000 transactions; at $5, about 100,000. | H34: Justo · Finance
B35: Tranche 1 · monthly Net TPV ceiling | C35: USD | D35: 2000000 | E35: =D35 | F35: =D35 | G35: Proposal (ladder: each tranche applies only to the Net TPV inside it). | H35: Justo
B36: Tranche 1 · usage rate on Net TPV above the included block | C36: % | D36: 0.004 | E36: =D36 | F36: =D36 | G36: Proposal: 40 bps. At a $10 ticket this is $0.040 per successful transaction; at $5, $0.020. | H36: Justo · Finance
B37: Tranche 2 · monthly Net TPV ceiling | C37: USD | D37: 5000000 | E37: =D37 | F37: =D37 | G37: Proposal. | H37: Justo
B38: Tranche 2 · usage rate | C38: % | D38: 0.003 | E38: =D38 | F38: =D38 | G38: Proposal: 30 bps. $0.030 per transaction at a $10 ticket; $0.015 at $5. | H38: Justo · Finance
B39: Tranche 3 · monthly Net TPV ceiling | C39: USD | D39: 10000000 | E39: =D39 | F39: =D39 | G39: Proposal. | H39: Justo
B40: Tranche 3 · usage rate | C40: % | D40: 0.002 | E40: =D40 | F40: =D40 | G40: Proposal: 20 bps. $0.020 per transaction at a $10 ticket; $0.010 at $5. | H40: Justo · Finance
B41: Tranche 4 · usage rate above tranche 3 | C41: % | D41: 0.001 | E41: =D41 | F41: =D41 | G41: Proposal: 10 bps. $0.010 per transaction at a $10 ticket; $0.005 at $5. | H41: Justo · Finance
...

Sheet Pricing
A1: Pricing · Yuno proposal: $7,500 a month flat including the first block of monthly Net TPV, usage above it in bps on Net TPV (ladder)
A2: Billable event = successful transaction. Net TPV = successful transactions only, no declines, no chargebacks. Each tranche applies only to the Net TPV inside it. Add-ons (network tokens, 3DS) billed on usage and not in these totals.
A4: Proposal terms
A5: Platform fee a month (flat) | B5: =Inputs!$E$33
A6: Monthly Net TPV included in the platform fee | B6: =Inputs!$E$34
A7: Tranche 1 · Net TPV ceiling | B7: =Inputs!$E$35
A8: Tranche 1 · rate | B8: =Inputs!$E$36
A9: Tranche 2 · Net TPV ceiling | B9: =Inputs!$E$37
A10: Tranche 2 · rate | B10: =Inputs!$E$38
A11: Tranche 3 · Net TPV ceiling | B11: =Inputs!$E$39
A12: Tranche 3 · rate | B12: =Inputs!$E$40
A13: Tranche 4 · rate above tranche 3 | B13: =Inputs!$E$41
A14: Included block, transactions at the average ticket | B14: =Inputs!$E$34/Inputs!$E$6
A15: Tranche 1 rate, $ per transaction at the average ticket | B15: =Inputs!$E$36*Inputs!$E$6
A16: Tranche 2 rate, $ per transaction at the average ticket | B16: =Inputs!$E$38*Inputs!$E$6
A17: Tranche 3 rate, $ per transaction at the average ticket | B17: =Inputs!$E$40*Inputs!$E$6
A18: Tranche 4 rate, $ per transaction at the average ticket | B18: =Inputs!$E$41*Inputs!$E$6
A19: Tranche 1 rate, $ per transaction at the median ticket | B19: =Inputs!$E$36*Inputs!$E$7
A20: Tranche 2 rate, $ per transaction at the median ticket | B20: =Inputs!$E$38*Inputs!$E$7
A21: Tranche 3 rate, $ per transaction at the median ticket | B21: =Inputs!$E$40*Inputs!$E$7
A22: Tranche 4 rate, $ per transaction at the median ticket | B22: =Inputs!$E$41*Inputs!$E$7
A24: What it means for Carry1st at the AVERAGE ticket ($10)
A25: Line | B25: =Inputs!$E$8 | C25: =Inputs!$E$9 | D25: =Inputs!$E$10 | E25: =Inputs!$E$11
A26: Successful transactions a month | B26: =Inputs!$E$8 | C26: =Inputs!$E$9 | D26: =Inputs!$E$10 | E26: =Inputs!$E$11
A27: Net TPV a month | B27: =B26*Inputs!$E$6 | C27: =C26*Inputs!$E$6 | D27: =D26*Inputs!$E$6 | E27: =E26*Inputs!$E$6
A28: Net TPV inside the included block | B28: =MIN(B27,Inputs!$E$34) | C28: =MIN(C27,Inputs!$E$34) | D28: =MIN(D27,Inputs!$E$34) | E28: =MIN(E27,Inputs!$E$34)
A29: Billable Net TPV · tranche 1 | B29: =MAX(0,MIN(B27,Inputs!$E$35)-MAX(0,B28)) | C29: =MAX(0,MIN(C27,Inputs!$E$35)-MAX(0,C28)) | D29: =MAX(0,MIN(D27,Inputs!$E$35)-MAX(0,D28)) | E29: =MAX(0,MIN(E27,Inputs!$E$35)-MAX(0,E28))
A30: Billable Net TPV · tranche 2 | B30: =MAX(0,MIN(B27,Inputs!$E$37)-MAX(Inputs!$E$35,B28)) | C30: =MAX(0,MIN(C27,Inputs!$E$37)-MAX(Inputs!$E$35,C28)) | D30: =MAX(0,MIN(D27,Inputs!$E$37)-MAX(Inputs!$E$35,D28)) | E30: =MAX(0,MIN(E27,Inputs!$E$37)-MAX(Inputs!$E$35,E28))
A31: Billable Net TPV · tranche 3 | B31: =MAX(0,MIN(B27,Inputs!$E$39)-MAX(Inputs!$E$37,B28)) | C31: =MAX(0,MIN(C27,Inputs!$E$39)-MAX(Inputs!$E$37,C28)) | D31: =MAX(0,MIN(D27,Inputs!$E$39)-MAX(Inputs!$E$37,D28)) | E31: =MAX(0,MIN(E27,Inputs!$E$39)-MAX(Inputs!$E$37,E28))
A32: Billable Net TPV · tranche 4 | B32: =MAX(0,B27-MAX(Inputs!$E$39,B28)) | C32: =MAX(0,C27-MAX(Inputs!$E$39,C28)) | D32: =MAX(0,D27-MAX(Inputs!$E$39,D28)) | E32: =MAX(0,E27-MAX(Inputs!$E$39,E28))
A33: Usage fee | B33: =B29*Inputs!$E$36+B30*Inputs!$E$38+B31*Inputs!$E$40+B32*Inputs!$E$41 | C33: =C29*Inputs!$E$36+C30*Inputs!$E$38+C31*Inputs!$E$40+C32*Inputs!$E$41 | D33: =D29*Inputs!$E$36+D30*Inputs!$E$38+D31*Inputs!$E$40+D32*Inputs!$E$41 | E33: =E29*Inputs!$E$36+E30*Inputs!$E$38+E31*Inputs!$E$40+E32*Inputs!$E$41
A34: Platform fee | B34: =Inputs!$E$33 | C34: =Inputs!$E$33 | D34: =Inputs!$E$33 | E34: =Inputs!$E$33
A35: Yuno total a month | B35: =B33+B34 | C35: =C33+C34 | D35: =D33+D34 | E35: =E33+E34
A36: Yuno total a year | B36: =B35*12 | C36: =C35*12 | D36: =D35*12 | E36: =E35*12
A37: Yuno cost, % of TPV | B37: =B35/B27 | C37: =C35/C27 | D37: =D35/D27 | E37: =E35/E27
A38: Yuno cost per successful transaction | B38: =B35/B26 | C38: =C35/C26 | D38: =D35/D26 | E38: =E35/E26
A39: Hypothetical fixed fee A a month (comparison) | B39: =B26*Inputs!$E$42 | C39: =C26*Inputs!$E$42 | D39: =D26*Inputs!$E$42 | E39: =E26*Inputs!$E$42
A40: Fixed fee A, % of TPV | B40: =B39/B27 | C40: =C39/C27 | D40: =D39/D27 | E40: =E39/E27
A41: Hypothetical fixed fee B a month (comparison) | B41: =B26*Inputs!$E$43 | C41: =C26*Inputs!$E$43 | D41: =D26*Inputs!$E$43 | E41: =E26*Inputs!$E$43
A42: Fixed fee B, % of TPV | B42: =B41/B27 | C42: =C41/C27 | D42: =D41/D27 | E42: =E41/E27
...

Sheet Model
A1: Model · Option A (EBANX direct) vs Option B (EBANX + dLocal through Yuno) · monthly, USD
A2: Columns = scenario x volume tier. All cells are formulas on Inputs. Contribution view = GMV levers x (take rate minus processing %) when the net flag is 1; GMV view counts the full incremental GMV.
B4: Conservative | F4: Base | J4: Optimistic
A5: Successful transactions a month | B5: =Inputs!$D$8 | C5: =Inputs!$D$9 | D5: =Inputs!$D$10 | E5: =Inputs!$D$11 | F5: =Inputs!$E$8 | G5: =Inputs!$E$9 | H5: =Inputs!$E$10 | I5: =Inputs!$E$11 | J5: =Inputs!$F$8 | K5: =Inputs!$F$9 | L5: =Inputs!$F$10 | M5: =Inputs!$F$11
A6: Net TPV a month (transactions x average ticket) | B6: =B5*Inputs!$D$6 | C6: =C5*Inputs!$D$6 | D6: =D5*Inputs!$D$6 | E6: =E5*Inputs!$D$6 | F6: =F5*Inputs!$E$6 | G6: =G5*Inputs!$E$6 | H6: =H5*Inputs!$E$6 | I6: =I5*Inputs!$E$6 | J6: =J5*Inputs!$F$6 | K6: =K5*Inputs!$F$6 | L6: =L5*Inputs!$F$6 | M6: =M5*Inputs!$F$6
A7: OPTION A · EBANX direct
A8: Provider all-in cost, % of TPV | B8: =Inputs!$D$16 | C8: =Inputs!$D$16 | D8: =Inputs!$D$16 | E8: =Inputs!$D$16 | F8: =Inputs!$E$16 | G8: =Inputs!$E$16 | H8: =Inputs!$E$16 | I8: =Inputs!$E$16 | J8: =Inputs!$F$16 | K8: =Inputs!$F$16 | L8: =Inputs!$F$16 | M8: =Inputs!$F$16
A9: Option A total cost a month | B9: =B6*B8 | C9: =C6*C8 | D9: =D6*D8 | E9: =E6*E8 | F9: =F6*F8 | G9: =G6*G8 | H9: =H6*H8 | I9: =I6*I8 | ... M9: =M6*M8
A10: Option A cost per $1,000 TPV | B10: =B9/B6*1000 | C10: =C9/C6*1000 | D10: =D9/D6*1000 | E10: =E9/E6*1000 | F10: =F9/F6*1000 | G10: =G9/G6*1000 | H10: =H9/H6*1000 | I10: =I9/I6*1000 | ... M10: =M9/M6*1000
A11: OPTION B · EBANX + dLocal through Yuno
A12: MDR reduction, bps of TPV | B12: =Inputs!$D$20 | C12: =Inputs!$D$20 | D12: =Inputs!$D$20 | E12: =Inputs!$D$20 | F12: =Inputs!$E$20 | G12: =Inputs!$E$20 | H12: =Inputs!$E$20 | I12: =Inputs!$E$20 | J12: =Inputs!$F$20 | K12: =Inputs!$F$20 | L12: =Inputs!$F$20 | M12: =Inputs!$F$20
A13: Provider cost after reduction, % of TPV | B13: =B8-B12/10000 | C13: =C8-C12/10000 | D13: =D8-D12/10000 | E13: =E8-E12/10000 | F13: =F8-F12/10000 | G13: =G8-G12/10000 | H13: =H8-H12/10000 | I13: =I8-I12/10000 | ... M13: =M8-M12/10000
A14: Provider cost a month | B14: =B6*B13 | C14: =C6*C13 | D14: =D6*D13 | E14: =E6*E13 | F14: =F6*F13 | G14: =G6*G13 | H14: =H6*H13 | I14: =I6*I13 | ... M14: =M6*M13
A15: Yuno · Net TPV inside the included block | B15: =MIN(B6,Inputs!$E$34) | C15: =MIN(C6,Inputs!$E$34) | D15: =MIN(D6,Inputs!$E$34) | E15: =MIN(E6,Inputs!$E$34) | F15: =MIN(F6,Inputs!$E$34) | G15: =MIN(G6,Inputs!$E$34) | H15: =MIN(H6,Inputs!$E$34) | I15: =MIN(I6,Inputs!$E$34) | ... M15: =MIN(M6,Inputs!$E$34)
A16: Yuno · billable Net TPV in tranche 1 | B16: =MAX(0,MIN(B6,Inputs!$E$35)-MAX(0,B15)) | C16: =MAX(0,MIN(C6,Inputs!$E$35)-MAX(0,C15)) | D16: =MAX(0,MIN(D6,Inputs!$E$35)-MAX(0,D15)) | E16: =MAX(0,MIN(E6,Inputs!$E$35)-MAX(0,E15)) | F16: =MAX(0,MIN(F6,Inputs!$E$35)-MAX(0,F15)) | G16: =MAX(0,MIN(G6,Inputs!$E$35)-MAX(0,G15)) | H16: =MAX(0,MIN(H6,Inputs!$E$35)-MAX(0,H15)) | I16: =MAX(0,MIN(I6,Inputs!$E$35)-MAX(0,I15)) | ... M16: =MAX(0,MIN(M6,Inputs!$E$35)-MAX(0,M15))
A17: Yuno · billable Net TPV in tranche 2 | B17: =MAX(0,MIN(B6,Inputs!$E$37)-MAX(Inputs!$E$35,B15)) | C17: =MAX(0,MIN(C6,Inputs!$E$37)-MAX(Inputs!$E$35,C15)) | D17: =MAX(0,MIN(D6,Inputs!$E$37)-MAX(Inputs!$E$35,D15)) | E17: =MAX(0,MIN(E6,Inputs!$E$37)-MAX(Inputs!$E$35,E15)) | F17: =MAX(0,MIN(F6,Inputs!$E$37)-MAX(Inputs!$E$35,F15)) | G17: =MAX(0,MIN(G6,Inputs!$E$37)-MAX(Inputs!$E$35,G15)) | H17: =MAX(0,MIN(H6,Inputs!$E$37)-MAX(Inputs!$E$35,H15)) | I17: =MAX(0,MIN(I6,Inputs!$E$37)-MAX(Inputs!$E$35,I15)) | ... M17: =MAX(0,MIN(M6,Inputs!$E$37)-MAX(Inputs!$E$35,M15))
A18: Yuno · billable Net TPV in tranche 3 | B18: =MAX(0,MIN(B6,Inputs!$E$39)-MAX(Inputs!$E$37,B15)) | C18: =MAX(0,MIN(C6,Inputs!$E$39)-MAX(Inputs!$E$37,C15)) | D18: =MAX(0,MIN(D6,Inputs!$E$39)-MAX(Inputs!$E$37,D15)) | E18: =MAX(0,MIN(E6,Inputs!$E$39)-MAX(Inputs!$E$37,E15)) | F18: =MAX(0,MIN(F6,Inputs!$E$39)-MAX(Inputs!$E$37,F15)) | G18: =MAX(0,MIN(G6,Inputs!$E$39)-MAX(Inputs!$E$37,G15)) | H18: =MAX(0,MIN(H6,Inputs!$E$39)-MAX(Inputs!$E$37,H15)) | I18: =MAX(0,MIN(I6,Inputs!$E$39)-MAX(Inputs!$E$37,I15)) | ... M18: =MAX(0,MIN(M6,Inputs!$E$39)-MAX(Inputs!$E$37,M15))
A19: Yuno · billable Net TPV in tranche 4 | B19: =MAX(0,B6-MAX(Inputs!$E$39,B15)) | C19: =MAX(0,C6-MAX(Inputs!$E$39,C15)) | D19: =MAX(0,D6-MAX(Inputs!$E$39,D15)) | E19: =MAX(0,E6-MAX(Inputs!$E$39,E15)) | F19: =MAX(0,F6-MAX(Inputs!$E$39,F15)) | G19: =MAX(0,G6-MAX(Inputs!$E$39,G15)) | H19: =MAX(0,H6-MAX(Inputs!$E$39,H15)) | I19: =MAX(0,I6-MAX(Inputs!$E$39,I15)) | ... M19: =MAX(0,M6-MAX(Inputs!$E$39,M15))
A20: Yuno · usage fee | B20: =B16*Inputs!$D$36+B17*Inputs!$D$38+B18*Inputs!$D$40+B19*Inputs!$D$41 | C20: =C16*Inputs!$D$36+C17*Inputs!$D$38+C18*Inputs!$D$40+C19*Inputs!$D$41 | D20: =D16*Inputs!$D$36+D17*Inputs!$D$38+D18*Inputs!$D$40+D19*Inputs!$D$41 | E20: =E16*Inputs!$D$36+E17*Inputs!$D$38+E18*Inputs!$D$40+E19*Inputs!$D$41 | F20: =F16*Inputs!$E$36+F17*Inputs!$E$38+F18*Inputs!$E$40+F19*Inputs!$E$41 | G20: =G16*Inputs!$E$36+G17*Inputs!$E$38+G18*Inputs!$E$40+G19*Inputs!$E$41 | H20: =H16*Inputs!$E$36+H17*Inputs!$E$38+H18*Inputs!$E$40+H19*Inputs!$E$41 | I20: =I16*Inputs!$E$36+I17*Inputs!$E$38+I18*Inputs!$E$40+I19*Inputs!$E$41 | J20: =J16*Inputs!$F$36+J17*Inputs!$F$38+J18*Inputs!$F$40+J19*Inputs!$F$41 | K20: =K16*Inputs!$F$36+K17*Inputs!$F$38+K18*Inputs!$F$40+K19*Inputs!$F$41 | L20: =L16*Inputs!$F$36+L17*Inputs!$F$38+L18*Inputs!$F$40+L19*Inputs!$F$41 | M20: =M16*Inputs!$F$36+M17*Inputs!$F$38+M18*Inputs!$F$40+M19*Inputs!$F$41
A21: Yuno · platform fee | B21: =Inputs!$D$33 | C21: =Inputs!$D$33 | D21: =Inputs!$D$33 | E21: =Inputs!$D$33 | F21: =Inputs!$E$33 | G21: =Inputs!$E$33 | H21: =Inputs!$E$33 | I21: =Inputs!$E$33 | J21: =Inputs!$F$33 | K21: =Inputs!$F$33 | L21: =Inputs!$F$33 | M21: =Inputs!$F$33
A22: Yuno total cost a month | B22: =B20+B21 | C22: =C20+C21 | D22: =D20+D21 | E22: =E20+E21 | F22: =F20+F21 | G22: =G20+G21 | H22: =H20+H21 | I22: =I20+I21 | ... M22: =M20+M21
A23: Yuno cost, % of TPV | B23: =B22/B6 | C23: =C22/C6 | D23: =D22/D6 | E23: =E22/E6 | F23: =F22/F6 | G23: =G22/G6 | H23: =H22/H6 | I23: =I22/I6 | ... M23: =M22/M6
A24: Yuno cost per successful transaction | B24: =B22/B5 | C24: =C22/C5 | D24: =D22/D5 | E24: =E22/E5 | F24: =F22/F5 | G24: =G22/G5 | H24: =H22/H5 | I24: =I22/I5 | ... M24: =M22/M5
A25: Option B total cost a month (provider + Yuno) | B25: =B14+B22 | C25: =C14+C22 | D25: =D14+D22 | E25: =E14+E22 | F25: =F14+F22 | G25: =G14+G22 | H25: =H14+H22 | I25: =I14+I22 | ... M25: =M14+M22
A26: Option B cost per $1,000 TPV | B26: =B25/B6*1000 | C26: =C25/C6*1000 | D26: =D25/D6*1000 | E26: =E25/E6*1000 | F26: =F25/F6*1000 | G26: =G25/G6*1000 | H26: =H25/H6*1000 | I26: =I25/I6*1000 | ... M26: =M25/M6*1000
A27: Option B all-in, % of TPV | B27: =B25/B6 | C27: =C25/C6 | D27: =D25/D6 | E27: =E25/E6 | F27: =F25/F6 | G27: =G25/G6 | H27: =H25/H6 | I27: =I25/I6 | ... M27: =M25/M6
A28: LEVERS (monthly)
A29: L1 · MDR saving (100% contribution) | B29: =B9-B14 | C29: =C9-C14 | D29: =D9-D14 | E29: =E9-E14 | F29: =F9-F14 | G29: =G9-G14 | H29: =H9-H14 | I29: =I9-I14 | ... M29: =M9-M14
A30: Attempted volume (TPV / baseline approval) | B30: =B6/Inputs!$D$22 | C30: =C6/Inputs!$D$22 | D30: =D6/Inputs!$D$22 | E30: =E6/Inputs!$D$22 | F30: =F6/Inputs!$E$22 | G30: =G6/Inputs!$E$22 | H30: =H6/Inputs!$E$22 | I30: =I6/Inputs!$E$22 | J30: =J6/Inputs!$F$22 | K30: =K6/Inputs!$F$22 | L30: =L6/Inputs!$F$22 | M30: =M6/Inputs!$F$22
A31: L2 · retries and routing · incremental GMV | B31: =B30*Inputs!$D$23 | C31: =C30*Inputs!$D$23 | D31: =D30*Inputs!$D$23 | E31: =E30*Inputs!$D$23 | F31: =F30*Inputs!$E$23 | G31: =G30*Inputs!$E$23 | H31: =H30*Inputs!$E$23 | I31: =I30*Inputs!$E$23 | J31: =J30*Inputs!$F$23 | K31: =K30*Inputs!$F$23 | L31: =L30*Inputs!$F$23 | M31: =M30*Inputs!$F$23
A32: L2 · retries and routing · contribution | B32: =B31*(Inputs!$D$13-Inputs!$D$14*B27) | C32: =C31*(Inputs!$D$13-Inputs!$D$14*C27) | D32: =D31*(Inputs!$D$13-Inputs!$D$14*D27) | E32: =E31*(Inputs!$D$13-Inputs!$D$14*E27) | F32: =F31*(Inputs!$E$13-Inputs!$E$14*F27) | G32: =G31*(Inputs!$E$13-Inputs!$E$14*G27) | H32: =H31*(Inputs!$E$13-Inputs!$E$14*H27) | I32: =I31*(Inputs!$E$13-Inputs!$E$14*I27) | J32: =J31*(Inputs!$F$13-Inputs!$F$14*J27) | K32: =K31*(Inputs!$F$13-Inputs!$F$14*K27) | L32: =L31*(Inputs!$F$13-Inputs!$F$14*L27) | M32: =M31*(Inputs!$F$13-Inputs!$F$14*M27)
A33: L3 · local methods · incremental GMV | B33: =B6*Inputs!$D$25 | C33: =C6*Inputs!$D$25 | D33: =D6*Inputs!$D$25 | E33: =E6*Inputs!$D$25 | F33: =F6*Inputs!$E$25 | G33: =G6*Inputs!$E$25 | H33: =H6*Inputs!$E$25 | I33: =I6*Inputs!$E$25 | J33: =J6*Inputs!$F$25 | K33: =K6*Inputs!$F$25 | L33: =L6*Inputs!$F$25 | M33: =M6*Inputs!$F$25
A34: L3 · local methods · contribution | B34: =B33*(Inputs!$D$13-Inputs!$D$14*B27) | C34: =C33*(Inputs!$D$13-Inputs!$D$14*C27) | D34: =D33*(Inputs!$D$13-Inputs!$D$14*D27) | E34: =E33*(Inputs!$D$13-Inputs!$D$14*E27) | F34: =F33*(Inputs!$E$13-Inputs!$E$14*F27) | G34: =G33*(Inputs!$E$13-Inputs!$E$14*G27) | H34: =H33*(Inputs!$E$13-Inputs!$E$14*H27) | I34: =I33*(Inputs!$E$13-Inputs!$E$14*I27) | J34: =J33*(Inputs!$F$13-Inputs!$F$14*J27) | K34: =K33*(Inputs!$F$13-Inputs!$F$14*K27) | L34: =L33*(Inputs!$F$13-Inputs!$F$14*L27) | M34: =M33*(Inputs!$F$13-Inputs!$F$14*M27)
A35: L4 · engineering saved, monthly equivalent over the horizon | B35: =Inputs!$D$27*Inputs!$D$28*Inputs!$D$29*(1+Inputs!$D$30*Inputs!$D$31/12)/Inputs!$D$31 | C35: =Inputs!$D$27*Inputs!$D$28*Inputs!$D$29*(1+Inputs!$D$30*Inputs!$D$31/12)/Inputs!$D$31 | D35: =Inputs!$D$27*Inputs!$D$28*Inputs!$D$29*(1+Inputs!$D$30*Inputs!$D$31/12)/Inputs!$D$31 | E35: =Inputs!$D$27*Inputs!$D$28*Inputs!$D$29*(1+Inputs!$D$30*Inputs!$D$31/12)/Inputs!$D$31 | F35: =Inputs!$E$27*Inputs!$E$28*Inputs!$E$29*(1+Inputs!$E$30*Inputs!$E$31/12)/Inputs!$E$31 | G35: =Inputs!$E$27*Inputs!$E$28*Inputs!$E$29*(1+Inputs!$E$30*Inputs!$E$31/12)/Inputs!$E$31 | H35: =Inputs!$E$27*Inputs!$E$28*Inputs!$E$29*(1+Inputs!$E$30*Inputs!$E$31/12)/Inputs!$E$31 | I35: =Inputs!$E$27*Inputs!$E$28*Inputs!$E$29*(1+Inputs!$E$30*Inputs!$E$31/12)/Inputs!$E$31 | J35: =Inputs!$F$27*Inputs!$F$28*Inputs!$F$29*(1+Inputs!$F$30*Inputs!$F$31/12)/Inputs!$F$31 | K35: =Inputs!$F$27*Inputs!$F$28*Inputs!$F$29*(1+Inputs!$F$30*Inputs!$F$31/12)/Inputs!$F$31 | L35: =Inputs!$F$27*Inputs!$F$28*Inputs!$F$29*(1+Inputs!$F$30*Inputs!$F$31/12)/Inputs!$F$31 | M35: =Inputs!$F$27*Inputs!$F$28*Inputs!$F$29*(1+Inputs!$F$30*Inputs!$F$31/12)/Inputs!$F$31
A36: Gross benefit · contribution view | B36: =B29+B32+B34+B35 | C36: =C29+C32+C34+C35 | D36: =D29+D32+D34+D35 | E36: =E29+E32+E34+E35 | F36: =F29+F32+F34+F35 | G36: =G29+G32+G34+G35 | H36: =H29+H32+H34+H35 | I36: =I29+I32+I34+I35 | ... M36: =M29+M32+M34+M35
A37: Gross benefit · GMV view | B37: =B29+B31+B33+B35 | C37: =C29+C31+C33+C35 | D37: =D29+D31+D33+D35 | E37: =E29+E31+E33+E35 | F37: =F29+F31+F33+F35 | G37: =G29+G31+G33+G35 | H37: =H29+H31+H33+H35 | I37: =I29+I31+I33+I35 | ... M37: =M29+M31+M33+M35
A38: Net benefit · contribution view (gross minus Yuno cost) | B38: =B36-B22 | C38: =C36-C22 | D38: =D36-D22 | E38: =E36-E22 | F38: =F36-F22 | G38: =G36-G22 | H38: =H36-H22 | I38: =I36-I22 | ... M38: =M36-M22
A39: Net benefit · GMV view (gross minus Yuno cost) | B39: =B37-B22 | C39: =C37-C22 | D39: =D37-D22 | E39: =E37-E22 | F39: =F37-F22 | G39: =G37-G22 | H39: =H37-H22 | I39: =I37-I22 | ... M39: =M37-M22
A40: Option B cost per $1,000 TPV after levers (contribution) | B40: =(B25-B32-B34-B35)/B6*1000 | C40: =(C25-C32-C34-C35)/C6*1000 | D40: =(D25-D32-D34-D35)/D6*1000 | E40: =(E25-E32-E34-E35)/E6*1000 | F40: =(F25-F32-F34-F35)/F6*1000 | G40: =(G25-G32-G34-G35)/G6*1000 | H40: =(H25-H32-H34-H35)/H6*1000 | I40: =(I25-I32-I34-I35)/I6*1000 | ... M40: =(M25-M32-M34-M35)/M6*1000
A41: Advantage vs Option A per $1,000 TPV (contribution) | B41: =B10-B40 | C41: =C10-C40 | D41: =D10-D40 | E41: =E10-E40 | F41: =F10-F40 | G41: =G10-G40 | H41: =H10-H40 | I41: =I10-I40 | ... M41: =M10-M40
...

Sheet BreakEven
A1: Break-even · successful transactions a month where the net benefit covers the Yuno cost (platform fee included)
A2: Grid of 5,000-transaction steps at the average ticket; break-even interpolated between the last negative and first non-negative row. Contribution view.
A4: Scenario | C4: Break-even tx / month | E4: Break-even TPV / month | G4: Net at tier 1 | I4: Net at tier 4
A5: Conservative | C5: =IFERROR(IF(MATCH(1,H12:H111,0)=1,INDEX($A$12:$A$111,1),INDEX($A$12:$A$111,MATCH(1,H12:H111,0)-1)+(INDEX($A$12:$A$111,MATCH(1,H12:H111,0))-INDEX($A$12:$A$111,MATCH(1,H12:H111,0)-1))*(0-INDEX(G12:G111,MATCH(1,H12:H111,0)-1))/(INDEX(G12:G111,MATCH(1,H12:H111,0))-INDEX(G12:G111,MATCH(1,H12:H111,0)-1))),"above 500,000") | E5: =IFERROR(C5*Inputs!$E$6,"n/a") | G5: =Model!B38 | I5: =Model!E38
A6: Base | C6: =IFERROR(IF(MATCH(1,M12:M111,0)=1,INDEX($A$12:$A$111,1),INDEX($A$12:$A$111,MATCH(1,M12:M111,0)-1)+(INDEX($A$12:$A$111,MATCH(1,M12:M111,0))-INDEX($A$12:$A$111,MATCH(1,M12:M111,0)-1))*(0-INDEX(L12:L111,MATCH(1,M12:M111,0)-1))/(INDEX(L12:L111,MATCH(1,M12:M111,0))-INDEX(L12:L111,MATCH(1,M12:M111,0)-1))),"above 500,000") | E6: =IFERROR(C6*Inputs!$E$6,"n/a") | G6: =Model!F38 | I6: =Model!I38
A7: Optimistic | C7: =IFERROR(IF(MATCH(1,R12:R111,0)=1,INDEX($A$12:$A$111,1),INDEX($A$12:$A$111,MATCH(1,R12:R111,0)-1)+(INDEX($A$12:$A$111,MATCH(1,R12:R111,0))-INDEX($A$12:$A$111,MATCH(1,R12:R111,0)-1))*(0-INDEX(Q12:Q111,MATCH(1,R12:R111,0)-1))/(INDEX(Q12:Q111,MATCH(1,R12:R111,0))-INDEX(Q12:Q111,MATCH(1,R12:R111,0)-1))),"above 500,000") | E7: =IFERROR(C7*Inputs!$E$6,"n/a") | G7: =Model!J38 | I7: =Model!M38
A9: Break-even = first monthly transaction count at which L1 + L2 + L3 + L4 (contribution view) >= Yuno platform fee + usage. Inside the included block, usage is zero, so the test is simply gross benefit >= $7,500.
D10: Conservative | I10: Base | N10: Optimistic
A11: Transactions | B11: Net TPV | C11: Included TPV | D11: Yuno cost | E11: Option B % | F11: Gross contribution | G11: Net benefit | H11: Net >= 0 | I11: Yuno cost | J11: Option B % | K11: Gross contribution | L11: Net benefit | M11: Net >= 0 | N11: Yuno cost | O11: Option B % | P11: Gross contribution | Q11: Net benefit | R11: Net >= 0
A12: 5000 | B12: =A12*Inputs!$E$6 | C12: =MIN(B12,Inputs!$E$34) | D12: =Inputs!$E$33+MAX(0,MIN(B12,Inputs!$E$35)-MAX(0,C12))*Inputs!$E$36+MAX(0,MIN(B12,Inputs!$E$37)-MAX(Inputs!$E$35,C12))*Inputs!$E$38+MAX(0,MIN(B12,Inputs!$E$39)-MAX(Inputs!$E$37,C12))*Inputs!$E$40+MAX(0,B12-MAX(Inputs!$E$39,C12))*Inputs!$E$41 | E12: =(B12*(Inputs!$D$16-Inputs!$D$20/10000)+D12)/B12 | F12: =B12*Inputs!$D$20/10000+(B12/Inputs!$D$22*Inputs!$D$23+B12*Inputs!$D$25)*(Inputs!$D$13-Inputs!$D$14*E12)+Inputs!$D$27*Inputs!$D$28*Inputs!$D$29*(1+Inputs!$D$30*Inputs!$D$31/12)/Inputs!$D$31 | G12: =F12-D12 | H12: =IF(G12>=0,1,0) | I12: =Inputs!$E$33+MAX(0,MIN(B12,Inputs!$E$35)-MAX(0,C12))*Inputs!$E$36+MAX(0,MIN(B12,Inputs!$E$37)-MAX(Inputs!$E$35,C12))*Inputs!$E$38+MAX(0,MIN(B12,Inputs!$E$39)-MAX(Inputs!$E$37,C12))*Inputs!$E$40+MAX(0,B12-MAX(Inputs!$E$39,C12))*Inputs!$E$41 | J12: =(B12*(Inputs!$E$16-Inputs!$E$20/10000)+I12)/B12 | K12: =B12*Inputs!$E$20/10000+(B12/Inputs!$E$22*Inputs!$E$23+B12*Inputs!$E$25)*(Inputs!$E$13-Inputs!$E$14*J12)+Inputs!$E$27*Inputs!$E$28*Inputs!$E$29*(1+Inputs!$E$30*Inputs!$E$31/12)/Inputs!$E$31 | L12: =K12-I12 | M12: =IF(L12>=0,1,0) | N12: =Inputs!$E$33+MAX(0,MIN(B12,Inputs!$E$35)-MAX(0,C12))*Inputs!$E$36+MAX(0,MIN(B12,Inputs!$E$37)-MAX(Inputs!$E$35,C12))*Inputs!$E$38+MAX(0,MIN(B12,Inputs!$E$39)-MAX(Inputs!$E$37,C12))*Inputs!$E$40+MAX(0,B12-MAX(Inputs!$E$39,C12))*Inputs!$E$41 | O12: =(B12*(Inputs!$F$16-Inputs!$F$20/10000)+N12)/B12 | P12: =B12*Inputs!$F$20/10000+(B12/Inputs!$F$22*Inputs!$F$23+B12*Inputs!$F$25)*(Inputs!$F$13-Inputs!$F$14*O12)+Inputs!$F$27*Inputs!$F$28*Inputs!$F$29*(1+Inputs!$F$30*Inputs!$F$31/12)/Inputs!$F$31 | Q12: =P12-N12 | R12: =IF(Q12>=0,1,0)
A13: =A12+5000 | B13: =A13*Inputs!$E$6 | C13: =MIN(B13,Inputs!$E$34) | D13: =Inputs!$E$33+MAX(0,MIN(B13,Inputs!$E$35)-MAX(0,C13))*Inputs!$E$36+MAX(0,MIN(B13,Inputs!$E$37)-MAX(Inputs!$E$35,C13))*Inputs!$E$38+MAX(0,MIN(B13,Inputs!$E$39)-MAX(Inputs!$E$37,C13))*Inputs!$E$40+MAX(0,B13-MAX(Inputs!$E$39,C13))*Inputs!$E$41 | E13: =(B13*(Inputs!$D$16-Inputs!$D$20/10000)+D13)/B13 | F13: =B13*Inputs!$D$20/10000+(B13/Inputs!$D$22*Inputs!$D$23+B13*Inputs!$D$25)*(Inputs!$D$13-Inputs!$D$14*E13)+Inputs!$D$27*Inputs!$D$28*Inputs!$D$29*(1+Inputs!$D$30*Inputs!$D$31/12)/Inputs!$D$31 | G13: =F13-D13 | H13: =IF(G13>=0,1,0) | I13: =Inputs!$E$33+MAX(0,MIN(B13,Inputs!$E$35)-MAX(0,C13))*Inputs!$E$36+MAX(0,MIN(B13,Inputs!$E$37)-MAX(Inputs!$E$35,C13))*Inputs!$E$38+MAX(0,MIN(B13,Inputs!$E$39)-MAX(Inputs!$E$37,C13))*Inputs!$E$40+MAX(0,B13-MAX(Inputs!$E$39,C13))*Inputs!$E$41 | J13: =(B13*(Inputs!$E$16-Inputs!$E$20/10000)+I13)/B13 | K13: =B13*Inputs!$E$20/10000+(B13/Inputs!$E$22*Inputs!$E$23+B13*Inputs!$E$25)*(Inputs!$E$13-Inputs!$E$14*J13)+Inputs!$E$27*Inputs!$E$28*Inputs!$E$29*(1+Inputs!$E$30*Inputs!$E$31/12)/Inputs!$E$31 | L13: =K13-I13 | M13: =IF(L13>=0,1,0) | N13: =Inputs!$E$33+MAX(0,MIN(B13,Inputs!$E$35)-MAX(0,C13))*Inputs!$E$36+MAX(0,MIN(B13,Inputs!$E$37)-MAX(Inputs!$E$35,C13))*Inputs!$E$38+MAX(0,MIN(B13,Inputs!$E$39)-MAX(Inputs!$E$37,C13))*Inputs!$E$40+MAX(0,B13-MAX(Inputs!$E$39,C13))*Inputs!$E$41 | O13: =(B13*(Inputs!$F$16-Inputs!$F$20/10000)+N13)/B13 | P13: =B13*Inputs!$F$20/10000+(B13/Inputs!$F$22*Inputs!$F$23+B13*Inputs!$F$25)*(Inputs!$F$13-Inputs!$F$14*O13)+Inputs!$F$27*Inputs!$F$28*Inputs!$F$29*(1+Inputs!$F$30*Inputs!$F$31/12)/Inputs!$F$31 | Q13: =P13-N13 | R13: =IF(Q13>=0,1,0)
A14: =A13+5000 | B14: =A14*Inputs!$E$6 | C14: =MIN(B14,Inputs!$E$34) | D14: =Inputs!$E$33+MAX(0,MIN(B14,Inputs!$E$35)-MAX(0,C14))*Inputs!$E$36+MAX(0,MIN(B14,Inputs!$E$37)-MAX(Inputs!$E$35,C14))*Inputs!$E$38+MAX(0,MIN(B14,Inputs!$E$39)-MAX(Inputs!$E$37,C14))*Inputs!$E$40+MAX(0,B14-MAX(Inputs!$E$39,C14))*Inputs!$E$41 | E14: =(B14*(Inputs!$D$16-Inputs!$D$20/10000)+D14)/B14 | F14: =B14*Inputs!$D$20/10000+(B14/Inputs!$D$22*Inputs!$D$23+B14*Inputs!$D$25)*(Inputs!$D$13-Inputs!$D$14*E14)+Inputs!$D$27*Inputs!$D$28*Inputs!$D$29*(1+Inputs!$D$30*Inputs!$D$31/12)/Inputs!$D$31 | G14: =F14-D14 | H14: =IF(G14>=0,1,0) | I14: =Inputs!$E$33+MAX(0,MIN(B14,Inputs!$E$35)-MAX(0,C14))*Inputs!$E$36+MAX(0,MIN(B14,Inputs!$E$37)-MAX(Inputs!$E$35,C14))*Inputs!$E$38+MAX(0,MIN(B14,Inputs!$E$39)-MAX(Inputs!$E$37,C14))*Inputs!$E$40+MAX(0,B14-MAX(Inputs!$E$39,C14))*Inputs!$E$41 | J14: =(B14*(Inputs!$E$16-Inputs!$E$20/10000)+I14)/B14 | K14: =B14*Inputs!$E$20/10000+(B14/Inputs!$E$22*Inputs!$E$23+B14*Inputs!$E$25)*(Inputs!$E$13-Inputs!$E$14*J14)+Inputs!$E$27*Inputs!$E$28*Inputs!$E$29*(1+Inputs!$E$30*Inputs!$E$31/12)/Inputs!$E$31 | L14: =K14-I14 | M14: =IF(L14>=0,1,0) | N14: =Inputs!$E$33+MAX(0,MIN(B14,Inputs!$E$35)-MAX(0,C14))*Inputs!$E$36+MAX(0,MIN(B14,Inputs!$E$37)-MAX(Inputs!$E$35,C14))*Inputs!$E$38+MAX(0,MIN(B14,Inputs!$E$39)-MAX(Inputs!$E$37,C14))*Inputs!$E$40+MAX(0,B14-MAX(Inputs!$E$39,C14))*Inputs!$E$41 | O14: =(B14*(Inputs!$F$16-Inputs!$F$20/10000)+N14)/B14 | P14: =B14*Inputs!$F$20/10000+(B14/Inputs!$F$22*Inputs!$F$23+B14*Inputs!$F$25)*(Inputs!$F$13-Inputs!$F$14*O14)+Inputs!$F$27*Inputs!$F$28*Inputs!$F$29*(1+Inputs!$F$30*Inputs!$F$31/12)/Inputs!$F$31 | Q14: =P14-N14 | R14: =IF(Q14>=0,1,0)
A15: =A14+5000 | B15: =A15*Inputs!$E$6 | C15: =MIN(B15,Inputs!$E$34) | D15: =Inputs!$E$33+MAX(0,MIN(B15,Inputs!$E$35)-MAX(0,C15))*Inputs!$E$36+MAX(0,MIN(B15,Inputs!$E$37)-MAX(Inputs!$E$35,C15))*Inputs!$E$38+MAX(0,MIN(B15,Inputs!$E$39)-MAX(Inputs!$E$37,C15))*Inputs!$E$40+MAX(0,B15-MAX(Inputs!$E$39,C15))*Inputs!$E$41 | E15: =(B15*(Inputs!$D$16-Inputs!$D$20/10000)+D15)/B15 | F15: =B15*Inputs!$D$20/10000+(B15/Inputs!$D$22*Inputs!$D$23+B15*Inputs!$D$25)*(Inputs!$D$13-Inputs!$D$14*E15)+Inputs!$D$27*Inputs!$D$28*Inputs!$D$29*(1+Inputs!$D$30*Inputs!$D$31/12)/Inputs!$D$31 | G15: =F15-D15 | H15: =IF(G15>=0,1,0) | I15: =Inputs!$E$33+MAX(0,MIN(B15,Inputs!$E$35)-MAX(0,C15))*Inputs!$E$36+MAX(0,MIN(B15,Inputs!$E$37)-MAX(Inputs!$E$35,C15))*Inputs!$E$38+MAX(0,MIN(B15,Inputs!$E$39)-MAX(Inputs!$E$37,C15))*Inputs!$E$40+MAX(0,B15-MAX(Inputs!$E$39,C15))*Inputs!$E$41 | J15: =(B15*(Inputs!$E$16-Inputs!$E$20/10000)+I15)/B15 | K15: =B15*Inputs!$E$20/10000+(B15/Inputs!$E$22*Inputs!$E$23+B15*Inputs!$E$25)*(Inputs!$E$13-Inputs!$E$14*J15)+Inputs!$E$27*Inputs!$E$28*Inputs!$E$29*(1+Inputs!$E$30*Inputs!$E$31/12)/Inputs!$E$31 | L15: =K15-I15 | M15: =IF(L15>=0,1,0) | N15: =Inputs!$E$33+MAX(0,MIN(B15,Inputs!$E$35)-MAX(0,C15))*Inputs!$E$36+MAX(0,MIN(B15,Inputs!$E$37)-MAX(Inputs!$E$35,C15))*Inputs!$E$38+MAX(0,MIN(B15,Inputs!$E$39)-MAX(Inputs!$E$37,C15))*Inputs!$E$40+MAX(0,B15-MAX(Inputs!$E$39,C15))*Inputs!$E$41 | O15: =(B15*(Inputs!$F$16-Inputs!$F$20/10000)+N15)/B15 | P15: =B15*Inputs!$F$20/10000+(B15/Inputs!$F$22*Inputs!$F$23+B15*Inputs!$F$25)*(Inputs!$F$13-Inputs!$F$14*O15)+Inputs!$F$27*Inputs!$F$28*Inputs!$F$29*(1+Inputs!$F$30*Inputs!$F$31/12)/Inputs!$F$31 | Q15: =P15-N15 | R15: =IF(Q15>=0,1,0)
A16: =A15+5000 | B16: =A16*Inputs!$E$6 | C16: =MIN(B16,Inputs!$E$34) | D16: =Inputs!$E$33+MAX(0,MIN(B16,Inputs!$E$35)-MAX(0,C16))*Inputs!$E$36+MAX(0,MIN(B16,Inputs!$E$37)-MAX(Inputs!$E$35,C16))*Inputs!$E$38+MAX(0,MIN(B16,Inputs!$E$39)-MAX(Inputs!$E$37,C16))*Inputs!$E$40+MAX(0,B16-MAX(Inputs!$E$39,C16))*Inputs!$E$41 | E16: =(B16*(Inputs!$D$16-Inputs!$D$20/10000)+D16)/B16 | F16: =B16*Inputs!$D$20/10000+(B16/Inputs!$D$22*Inputs!$D$23+B16*Inputs!$D$25)*(Inputs!$D$13-Inputs!$D$14*E16)+Inputs!$D$27*Inputs!$D$28*Inputs!$D$29*(1+Inputs!$D$30*Inputs!$D$31/12)/Inputs!$D$31 | G16: =F16-D16 | H16: =IF(G16>=0,1,0) | I16: =Inputs!$E$33+MAX(0,MIN(B16,Inputs!$E$35)-MAX(0,C16))*Inputs!$E$36+MAX(0,MIN(B16,Inputs!$E$37)-MAX(Inputs!$E$35,C16))*Inputs!$E$38+MAX(0,MIN(B16,Inputs!$E$39)-MAX(Inputs!$E$37,C16))*Inputs!$E$40+MAX(0,B16-MAX(Inputs!$E$39,C16))*Inputs!$E$41 | J16: =(B16*(Inputs!$E$16-Inputs!$E$20/10000)+I16)/B16 | K16: =B16*Inputs!$E$20/10000+(B16/Inputs!$E$22*Inputs!$E$23+B16*Inputs!$E$25)*(Inputs!$E$13-Inputs!$E$14*J16)+Inputs!$E$27*Inputs!$E$28*Inputs!$E$29*(1+Inputs!$E$30*Inputs!$E$31/12)/Inputs!$E$31 | L16: =K16-I16 | M16: =IF(L16>=0,1,0) | N16: =Inputs!$E$33+MAX(0,MIN(B16,Inputs!$E$35)-MAX(0,C16))*Inputs!$E$36+MAX(0,MIN(B16,Inputs!$E$37)-MAX(Inputs!$E$35,C16))*Inputs!$E$38+MAX(0,MIN(B16,Inputs!$E$39)-MAX(Inputs!$E$37,C16))*Inputs!$E$40+MAX(0,B16-MAX(Inputs!$E$39,C16))*Inputs!$E$41 | O16: =(B16*(Inputs!$F$16-Inputs!$F$20/10000)+N16)/B16 | P16: =B16*Inputs!$F$20/10000+(B16/Inputs!$F$22*Inputs!$F$23+B16*Inputs!$F$25)*(Inputs!$F$13-Inputs!$F$14*O16)+Inputs!$F$27*Inputs!$F$28*Inputs!$F$29*(1+Inputs!$F$30*Inputs!$F$31/12)/Inputs!$F$31 | Q16: =P16-N16 | R16: =IF(Q16>=0,1,0)
A17: =A16+5000 | B17: =A17*Inputs!$E$6 | C17: =MIN(B17,Inputs!$E$34) | D17: =Inputs!$E$33+MAX(0,MIN(B17,Inputs!$E$35)-MAX(0,C17))*Inputs!$E$36+MAX(0,MIN(B17,Inputs!$E$37)-MAX(Inputs!$E$35,C17))*Inputs!$E$38+MAX(0,MIN(B17,Inputs!$E$39)-MAX(Inputs!$E$37,C17))*Inputs!$E$40+MAX(0,B17-MAX(Inputs!$E$39,C17))*Inputs!$E$41 | E17: =(B17*(Inputs!$D$16-Inputs!$D$20/10000)+D17)/B17 | F17: =B17*Inputs!$D$20/10000+(B17/Inputs!$D$22*Inputs!$D$23+B17*Inputs!$D$25)*(Inputs!$D$13-Inputs!$D$14*E17)+Inputs!$D$27*Inputs!$D$28*Inputs!$D$29*(1+Inputs!$D$30*Inputs!$D$31/12)/Inputs!$D$31 | G17: =F17-D17 | H17: =IF(G17>=0,1,0) | I17: =Inputs!$E$33+MAX(0,MIN(B17,Inputs!$E$35)-MAX(0,C17))*Inputs!$E$36+MAX(0,MIN(B17,Inputs!$E$37)-MAX(Inputs!$E$35,C17))*Inputs!$E$38+MAX(0,MIN(B17,Inputs!$E$39)-MAX(Inputs!$E$37,C17))*Inputs!$E$40+MAX(0,B17-MAX(Inputs!$E$39,C17))*Inputs!$E$41 | J17: =(B17*(Inputs!$E$16-Inputs!$E$20/10000)+I17)/B17 | K17: =B17*Inputs!$E$20/10000+(B17/Inputs!$E$22*Inputs!$E$23+B17*Inputs!$E$25)*(Inputs!$E$13-Inputs!$E$14*J17)+Inputs!$E$27*Inputs!$E$28*Inputs!$E$29*(1+Inputs!$E$30*Inputs!$E$31/12)/Inputs!$E$31 | L17: =K17-I17 | M17: =IF(L17>=0,1,0) | N17: =Inputs!$E$33+MAX(0,MIN(B17,Inputs!$E$35)-MAX(0,C17))*Inputs!$E$36+MAX(0,MIN(B17,Inputs!$E$37)-MAX(Inputs!$E$35,C17))*Inputs!$E$38+MAX(0,MIN(B17,Inputs!$E$39)-MAX(Inputs!$E$37,C17))*Inputs!$E$40+MAX(0,B17-MAX(Inputs!$E$39,C17))*Inputs!$E$41 | O17: =(B17*(Inputs!$F$16-Inputs!$F$20/10000)+N17)/B17 | P17: =B17*Inputs!$F$20/10000+(B17/Inputs!$F$22*Inputs!$F$23+B17*Inputs!$F$25)*(Inputs!$F$13-Inputs!$F$14*O17)+Inputs!$F$27*Inputs!$F$28*Inputs!$F$29*(1+Inputs!$F$30*Inputs!$F$31/12)/Inputs!$F$31 | Q17: =P17-N17 | R17: =IF(Q17>=0,1,0)
A18: =A17+5000 | B18: =A18*Inputs!$E$6 | C18: =MIN(B18,Inputs!$E$34) | D18: =Inputs!$E$33+MAX(0,MIN(B18,Inputs!$E$35)-MAX(0,C18))*Inputs!$E$36+MAX(0,MIN(B18,Inputs!$E$37)-MAX(Inputs!$E$35,C18))*Inputs!$E$38+MAX(0,MIN(B18,Inputs!$E$39)-MAX(Inputs!$E$37,C18))*Inputs!$E$40+MAX(0,B18-MAX(Inputs!$E$39,C18))*Inputs!$E$41 | E18: =(B18*(Inputs!$D$16-Inputs!$D$20/10000)+D18)/B18 | F18: =B18*Inputs!$D$20/10000+(B18/Inputs!$D$22*Inputs!$D$23+B18*Inputs!$D$25)*(Inputs!$D$13-Inputs!$D$14*E18)+Inputs!$D$27*Inputs!$D$28*Inputs!$D$29*(1+Inputs!$D$30*Inputs!$D$31/12)/Inputs!$D$31 | G18: =F18-D18 | H18: =IF(G18>=0,1,0) | I18: =Inputs!$E$33+MAX(0,MIN(B18,Inputs!$E$35)-MAX(0,C18))*Inputs!$E$36+MAX(0,MIN(B18,Inputs!$E$37)-MAX(Inputs!$E$35,C18))*Inputs!$E$38+MAX(0,MIN(B18,Inputs!$E$39)-MAX(Inputs!$E$37,C18))*Inputs!$E$40+MAX(0,B18-MAX(Inputs!$E$39,C18))*Inputs!$E$41 | J18: =(B18*(Inputs!$E$16-Inputs!$E$20/10000)+I18)/B18 | K18: =B18*Inputs!$E$20/10000+(B18/Inputs!$E$22*Inputs!$E$23+B18*Inputs!$E$25)*(Inputs!$E$13-Inputs!$E$14*J18)+Inputs!$E$27*Inputs!$E$28*Inputs!$E$29*(1+Inputs!$E$30*Inputs!$E$31/12)/Inputs!$E$31 | L18: =K18-I18 | M18: =IF(L18>=0,1,0) | N18: =Inputs!$E$33+MAX(0,MIN(B18,Inputs!$E$35)-MAX(0,C18))*Inputs!$E$36+MAX(0,MIN(B18,Inputs!$E$37)-MAX(Inputs!$E$35,C18))*Inputs!$E$38+MAX(0,MIN(B18,Inputs!$E$39)-MAX(Inputs!$E$37,C18))*Inputs!$E$40+MAX(0,B18-MAX(Inputs!$E$39,C18))*Inputs!$E$41 | O18: =(B18*(Inputs!$F$16-Inputs!$F$20/10000)+N18)/B18 | P18: =B18*Inputs!$F$20/10000+(B18/Inputs!$F$22*Inputs!$F$23+B18*Inputs!$F$25)*(Inputs!$F$13-Inputs!$F$14*O18)+Inputs!$F$27*Inputs!$F$28*Inputs!$F$29*(1+Inputs!$F$30*Inputs!$F$31/12)/Inputs!$F$31 | Q18: =P18-N18 | R18: =IF(Q18>=0,1,0)
A19: =A18+5000 | B19: =A19*Inputs!$E$6 | C19: =MIN(B19,Inputs!$E$34) | D19: =Inputs!$E$33+MAX(0,MIN(B19,Inputs!$E$35)-MAX(0,C19))*Inputs!$E$36+MAX(0,MIN(B19,Inputs!$E$37)-MAX(Inputs!$E$35,C19))*Inputs!$E$38+MAX(0,MIN(B19,Inputs!$E$39)-MAX(Inputs!$E$37,C19))*Inputs!$E$40+MAX(0,B19-MAX(Inputs!$E$39,C19))*Inputs!$E$41 | E19: =(B19*(Inputs!$D$16-Inputs!$D$20/10000)+D19)/B19 | F19: =B19*Inputs!$D$20/10000+(B19/Inputs!$D$22*Inputs!$D$23+B19*Inputs!$D$25)*(Inputs!$D$13-Inputs!$D$14*E19)+Inputs!$D$27*Inputs!$D$28*Inputs!$D$29*(1+Inputs!$D$30*Inputs!$D$31/12)/Inputs!$D$31 | G19: =F19-D19 | H19: =IF(G19>=0,1,0) | I19: =Inputs!$E$33+MAX(0,MIN(B19,Inputs!$E$35)-MAX(0,C19))*Inputs!$E$36+MAX(0,MIN(B19,Inputs!$E$37)-MAX(Inputs!$E$35,C19))*Inputs!$E$38+MAX(0,MIN(B19,Inputs!$E$39)-MAX(Inputs!$E$37,C19))*Inputs!$E$40+MAX(0,B19-MAX(Inputs!$E$39,C19))*Inputs!$E$41 | J19: =(B19*(Inputs!$E$16-Inputs!$E$20/10000)+I19)/B19 | K19: =B19*Inputs!$E$20/10000+(B19/Inputs!$E$22*Inputs!$E$23+B19*Inputs!$E$25)*(Inputs!$E$13-Inputs!$E$14*J19)+Inputs!$E$27*Inputs!$E$28*Inputs!$E$29*(1+Inputs!$E$30*Inputs!$E$31/12)/Inputs!$E$31 | L19: =K19-I19 | M19: =IF(L19>=0,1,0) | N19: =Inputs!$E$33+MAX(0,MIN(B19,Inputs!$E$35)-MAX(0,C19))*Inputs!$E$36+MAX(0,MIN(B19,Inputs!$E$37)-MAX(Inputs!$E$35,C19))*Inputs!$E$38+MAX(0,MIN(B19,Inputs!$E$39)-MAX(Inputs!$E$37,C19))*Inputs!$E$40+MAX(0,B19-MAX(Inputs!$E$39,C19))*Inputs!$E$41 | O19: =(B19*(Inputs!$F$16-Inputs!$F$20/10000)+N19)/B19 | P19: =B19*Inputs!$F$20/10000+(B19/Inputs!$F$22*Inputs!$F$23+B19*Inputs!$F$25)*(Inputs!$F$13-Inputs!$F$14*O19)+Inputs!$F$27*Inputs!$F$28*Inputs!$F$29*(1+Inputs!$F$30*Inputs!$F$31/12)/Inputs!$F$31 | Q19: =P19-N19 | R19: =IF(Q19>=0,1,0)
A20: =A19+5000 | B20: =A20*Inputs!$E$6 | C20: =MIN(B20,Inputs!$E$34) | D20: =Inputs!$E$33+MAX(0,MIN(B20,Inputs!$E$35)-MAX(0,C20))*Inputs!$E$36+MAX(0,MIN(B20,Inputs!$E$37)-MAX(Inputs!$E$35,C20))*Inputs!$E$38+MAX(0,MIN(B20,Inputs!$E$39)-MAX(Inputs!$E$37,C20))*Inputs!$E$40+MAX(0,B20-MAX(Inputs!$E$39,C20))*Inputs!$E$41 | E20: =(B20*(Inputs!$D$16-Inputs!$D$20/10000)+D20)/B20 | F20: =B20*Inputs!$D$20/10000+(B20/Inputs!$D$22*Inputs!$D$23+B20*Inputs!$D$25)*(Inputs!$D$13-Inputs!$D$14*E20)+Inputs!$D$27*Inputs!$D$28*Inputs!$D$29*(1+Inputs!$D$30*Inputs!$D$31/12)/Inputs!$D$31 | G20: =F20-D20 | H20: =IF(G20>=0,1,0) | I20: =Inputs!$E$33+MAX(0,MIN(B20,Inputs!$E$35)-MAX(0,C20))*Inputs!$E$36+MAX(0,MIN(B20,Inputs!$E$37)-MAX(Inputs!$E$35,C20))*Inputs!$E$38+MAX(0,MIN(B20,Inputs!$E$39)-MAX(Inputs!$E$37,C20))*Inputs!$E$40+MAX(0,B20-MAX(Inputs!$E$39,C20))*Inputs!$E$41 | J20: =(B20*(Inputs!$E$16-Inputs!$E$20/10000)+I20)/B20 | K20: =B20*Inputs!$E$20/10000+(B20/Inputs!$E$22*Inputs!$E$23+B20*Inputs!$E$25)*(Inputs!$E$13-Inputs!$E$14*J20)+Inputs!$E$27*Inputs!$E$28*Inputs!$E$29*(1+Inputs!$E$30*Inputs!$E$31/12)/Inputs!$E$31 | L20: =K20-I20 | M20: =IF(L20>=0,1,0) | N20: =Inputs!$E$33+MAX(0,MIN(B20,Inputs!$E$35)-MAX(0,C20))*Inputs!$E$36+MAX(0,MIN(B20,Inputs!$E$37)-MAX(Inputs!$E$35,C20))*Inputs!$E$38+MAX(0,MIN(B20,Inputs!$E$39)-MAX(Inputs!$E$37,C20))*Inputs!$E$40+MAX(0,B20-MAX(Inputs!$E$39,C20))*Inputs!$E$41 | O20: =(B20*(Inputs!$F$16-Inputs!$F$20/10000)+N20)/B20 | P20: =B20*Inputs!$F$20/10000+(B20/Inputs!$F$22*Inputs!$F$23+B20*Inputs!$F$25)*(Inputs!$F$13-Inputs!$F$14*O20)+Inputs!$F$27*Inputs!$F$28*Inputs!$F$29*(1+Inputs!$F$30*Inputs!$F$31/12)/Inputs!$F$31 | Q20: =P20-N20 | R20: =IF(Q20>=0,1,0)
A21: =A20+5000 | B21: =A21*Inputs!$E$6 | C21: =MIN(B21,Inputs!$E$34) | D21: =Inputs!$E$33+MAX(0,MIN(B21,Inputs!$E$35)-MAX(0,C21))*Inputs!$E$36+MAX(0,MIN(B21,Inputs!$E$37)-MAX(Inputs!$E$35,C21))*Inputs!$E$38+MAX(0,MIN(B21,Inputs!$E$39)-MAX(Inputs!$E$37,C21))*Inputs!$E$40+MAX(0,B21-MAX(Inputs!$E$39,C21))*Inputs!$E$41 | E21: =(B21*(Inputs!$D$16-Inputs!$D$20/10000)+D21)/B21 | F21: =B21*Inputs!$D$20/10000+(B21/Inputs!$D$22*Inputs!$D$23+B21*Inputs!$D$25)*(Inputs!$D$13-Inputs!$D$14*E21)+Inputs!$D$27*Inputs!$D$28*Inputs!$D$29*(1+Inputs!$D$30*Inputs!$D$31/12)/Inputs!$D$31 | G21: =F21-D21 | H21: =IF(G21>=0,1,0) | I21: =Inputs!$E$33+MAX(0,MIN(B21,Inputs!$E$35)-MAX(0,C21))*Inputs!$E$36+MAX(0,MIN(B21,Inputs!$E$37)-MAX(Inputs!$E$35,C21))*Inputs!$E$38+MAX(0,MIN(B21,Inputs!$E$39)-MAX(Inputs!$E$37,C21))*Inputs!$E$40+MAX(0,B21-MAX(Inputs!$E$39,C21))*Inputs!$E$41 | J21: =(B21*(Inputs!$E$16-Inputs!$E$20/10000)+I21)/B21 | K21: =B21*Inputs!$E$20/10000+(B21/Inputs!$E$22*Inputs!$E$23+B21*Inputs!$E$25)*(Inputs!$E$13-Inputs!$E$14*J21)+Inputs!$E$27*Inputs!$E$28*Inputs!$E$29*(1+Inputs!$E$30*Inputs!$E$31/12)/Inputs!$E$31 | L21: =K21-I21 | M21: =IF(L21>=0,1,0) | N21: =Inputs!$E$33+MAX(0,MIN(B21,Inputs!$E$35)-MAX(0,C21))*Inputs!$E$36+MAX(0,MIN(B21,Inputs!$E$37)-MAX(Inputs!$E$35,C21))*Inputs!$E$38+MAX(0,MIN(B21,Inputs!$E$39)-MAX(Inputs!$E$37,C21))*Inputs!$E$40+MAX(0,B21-MAX(Inputs!$E$39,C21))*Inputs!$E$41 | O21: =(B21*(Inputs!$F$16-Inputs!$F$20/10000)+N21)/B21 | P21: =B21*Inputs!$F$20/10000+(B21/Inputs!$F$22*Inputs!$F$23+B21*Inputs!$F$25)*(Inputs!$F$13-Inputs!$F$14*O21)+Inputs!$F$27*Inputs!$F$28*Inputs!$F$29*(1+Inputs!$F$30*Inputs!$F$31/12)/Inputs!$F$31 | Q21: =P21-N21 | R21: =IF(Q21>=0,1,0)
A22: =A21+5000 | B22: =A22*Inputs!$E$6 | C22: =MIN(B22,Inputs!$E$34) | D22: =Inputs!$E$33+MAX(0,MIN(B22,Inputs!$E$35)-MAX(0,C22))*Inputs!$E$36+MAX(0,MIN(B22,Inputs!$E$37)-MAX(Inputs!$E$35,C22))*Inputs!$E$38+MAX(0,MIN(B22,Inputs!$E$39)-MAX(Inputs!$E$37,C22))*Inputs!$E$40+MAX(0,B22-MAX(Inputs!$E$39,C22))*Inputs!$E$41 | E22: =(B22*(Inputs!$D$16-Inputs!$D$20/10000)+D22)/B22 | F22: =B22*Inputs!$D$20/10000+(B22/Inputs!$D$22*Inputs!$D$23+B22*Inputs!$D$25)*(Inputs!$D$13-Inputs!$D$14*E22)+Inputs!$D$27*Inputs!$D$28*Inputs!$D$29*(1+Inputs!$D$30*Inputs!$D$31/12)/Inputs!$D$31 | G22: =F22-D22 | H22: =IF(G22>=0,1,0) | I22: =Inputs!$E$33+MAX(0,MIN(B22,Inputs!$E$35)-MAX(0,C22))*Inputs!$E$36+MAX(0,MIN(B22,Inputs!$E$37)-MAX(Inputs!$E$35,C22))*Inputs!$E$38+MAX(0,MIN(B22,Inputs!$E$39)-MAX(Inputs!$E$37,C22))*Inputs!$E$40+MAX(0,B22-MAX(Inputs!$E$39,C22))*Inputs!$E$41 | J22: =(B22*(Inputs!$E$16-Inputs!$E$20/10000)+I22)/B22 | K22: =B22*Inputs!$E$20/10000+(B22/Inputs!$E$22*Inputs!$E$23+B22*Inputs!$E$25)*(Inputs!$E$13-Inputs!$E$14*J22)+Inputs!$E$27*Inputs!$E$28*Inputs!$E$29*(1+Inputs!$E$30*Inputs!$E$31/12)/Inputs!$E$31 | L22: =K22-I22 | M22: =IF(L22>=0,1,0) | N22: =Inputs!$E$33+MAX(0,MIN(B22,Inputs!$E$35)-MAX(0,C22))*Inputs!$E$36+MAX(0,MIN(B22,Inputs!$E$37)-MAX(Inputs!$E$35,C22))*Inputs!$E$38+MAX(0,MIN(B22,Inputs!$E$39)-MAX(Inputs!$E$37,C22))*Inputs!$E$40+MAX(0,B22-MAX(Inputs!$E$39,C22))*Inputs!$E$41 | O22: =(B22*(Inputs!$F$16-Inputs!$F$20/10000)+N22)/B22 | P22: =B22*Inputs!$F$20/10000+(B22/Inputs!$F$22*Inputs!$F$23+B22*Inputs!$F$25)*(Inputs!$F$13-Inputs!$F$14*O22)+Inputs!$F$27*Inputs!$F$28*Inputs!$F$29*(1+Inputs!$F$30*Inputs!$F$31/12)/Inputs!$F$31 | Q22: =P22-N22 | R22: =IF(Q22>=0,1,0)
A23: =A22+5000 | B23: =A23*Inputs!$E$6 | C23: =MIN(B23,Inputs!$E$34) | D23: =Inputs!$E$33+MAX(0,MIN(B23,Inputs!$E$35)-MAX(0,C23))*Inputs!$E$36+MAX(0,MIN(B23,Inputs!$E$37)-MAX(Inputs!$E$35,C23))*Inputs!$E$38+MAX(0,MIN(B23,Inputs!$E$39)-MAX(Inputs!$E$37,C23))*Inputs!$E$40+MAX(0,B23-MAX(Inputs!$E$39,C23))*Inputs!$E$41 | E23: =(B23*(Inputs!$D$16-Inputs!$D$20/10000)+D23)/B23 | F23: =B23*Inputs!$D$20/10000+(B23/Inputs!$D$22*Inputs!$D$23+B23*Inputs!$D$25)*(Inputs!$D$13-Inputs!$D$14*E23)+Inputs!$D$27*Inputs!$D$28*Inputs!$D$29*(1+Inputs!$D$30*Inputs!$D$31/12)/Inputs!$D$31 | G23: =F23-D23 | H23: =IF(G23>=0,1,0) | I23: =Inputs!$E$33+MAX(0,MIN(B23,Inputs!$E$35)-MAX(0,C23))*Inputs!$E$36+MAX(0,MIN(B23,Inputs!$E$37)-MAX(Inputs!$E$35,C23))*Inputs!$E$38+MAX(0,MIN(B23,Inputs!$E$39)-MAX(Inputs!$E$37,C23))*Inputs!$E$40+MAX(0,B23-MAX(Inputs!$E$39,C23))*Inputs!$E$41 | J23: =(B23*(Inputs!$E$16-Inputs!$E$20/10000)+I23)/B23 | K23: =B23*Inputs!$E$20/10000+(B23/Inputs!$E$22*Inputs!$E$23+B23*Inputs!$E$25)*(Inputs!$E$13-Inputs!$E$14*J23)+Inputs!$E$27*Inputs!$E$28*Inputs!$E$29*(1+Inputs!$E$30*Inputs!$E$31/12)/Inputs!$E$31 | L23: =K23-I23 | M23: =IF(L23>=0,1,0) | N23: =Inputs!$E$33+MAX(0,MIN(B23,Inputs!$E$35)-MAX(0,C23))*Inputs!$E$36+MAX(0,MIN(B23,Inputs!$E$37)-MAX(Inputs!$E$35,C23))*Inputs!$E$38+MAX(0,MIN(B23,Inputs!$E$39)-MAX(Inputs!$E$37,C23))*Inputs!$E$40+MAX(0,B23-MAX(Inputs!$E$39,C23))*Inputs!$E$41 | O23: =(B23*(Inputs!$F$16-Inputs!$F$20/10000)+N23)/B23 | P23: =B23*Inputs!$F$20/10000+(B23/Inputs!$F$22*Inputs!$F$23+B23*Inputs!$F$25)*(Inputs!$F$13-Inputs!$F$14*O23)+Inputs!$F$27*Inputs!$F$28*Inputs!$F$29*(1+Inputs!$F$30*Inputs!$F$31/12)/Inputs!$F$31 | Q23: =P23-N23 | R23: =IF(Q23>=0,1,0)
A24: =A23+5000 | B24: =A24*Inputs!$E$6 | C24: =MIN(B24,Inputs!$E$34) | D24: =Inputs!$E$33+MAX(0,MIN(B24,Inputs!$E$35)-MAX(0,C24))*Inputs!$E$36+MAX(0,MIN(B24,Inputs!$E$37)-MAX(Inputs!$E$35,C24))*Inputs!$E$38+MAX(0,MIN(B24,Inputs!$E$39)-MAX(Inputs!$E$37,C24))*Inputs!$E$40+MAX(0,B24-MAX(Inputs!$E$39,C24))*Inputs!$E$41 | E24: =(B24*(Inputs!$D$16-Inputs!$D$20/10000)+D24)/B24 | F24: =B24*Inputs!$D$20/10000+(B24/Inputs!$D$22*Inputs!$D$23+B24*Inputs!$D$25)*(Inputs!$D$13-Inputs!$D$14*E24)+Inputs!$D$27*Inputs!$D$28*Inputs!$D$29*(1+Inputs!$D$30*Inputs!$D$31/12)/Inputs!$D$31 | G24: =F24-D24 | H24: =IF(G24>=0,1,0) | I24: =Inputs!$E$33+MAX(0,MIN(B24,Inputs!$E$35)-MAX(0,C24))*Inputs!$E$36+MAX(0,MIN(B24,Inputs!$E$37)-MAX(Inputs!$E$35,C24))*Inputs!$E$38+MAX(0,MIN(B24,Inputs!$E$39)-MAX(Inputs!$E$37,C24))*Inputs!$E$40+MAX(0,B24-MAX(Inputs!$E$39,C24))*Inputs!$E$41 | J24: =(B24*(Inputs!$E$16-Inputs!$E$20/10000)+I24)/B24 | K24: =B24*Inputs!$E$20/10000+(B24/Inputs!$E$22*Inputs!$E$23+B24*Inputs!$E$25)*(Inputs!$E$13-Inputs!$E$14*J24)+Inputs!$E$27*Inputs!$E$28*Inputs!$E$29*(1+Inputs!$E$30*Inputs!$E$31/12)/Inputs!$E$31 | L24: =K24-I24 | M24: =IF(L24>=0,1,0) | N24: =Inputs!$E$33+MAX(0,MIN(B24,Inputs!$E$35)-MAX(0,C24))*Inputs!$E$36+MAX(0,MIN(B24,Inputs!$E$37)-MAX(Inputs!$E$35,C24))*Inputs!$E$38+MAX(0,MIN(B24,Inputs!$E$39)-MAX(Inputs!$E$37,C24))*Inputs!$E$40+MAX(0,B24-MAX(Inputs!$E$39,C24))*Inputs!$E$41 | O24: =(B24*(Inputs!$F$16-Inputs!$F$20/10000)+N24)/B24 | P24: =B24*Inputs!$F$20/10000+(B24/Inputs!$F$22*Inputs!$F$23+B24*Inputs!$F$25)*(Inputs!$F$13-Inputs!$F$14*O24)+Inputs!$F$27*Inputs!$F$28*Inputs!$F$29*(1+Inputs!$F$30*Inputs!$F$31/12)/Inputs!$F$31 | Q24: =P24-N24 | R24: =IF(Q24>=0,1,0)
... A111: =A110+5000 | B111: =A111*Inputs!$E$6 | C111: =MIN(B111,Inputs!$E$34) | D111: =Inputs!$E$33+MAX(0,MIN(B111,Inputs!$E$35)-MAX(0,C111))*Inputs!$E$36+MAX(0,MIN(B111,Inputs!$E$37)-MAX(Inputs!$E$35,C111))*Inputs!$E$38+MAX(0,MIN(B111,Inputs!$E$39)-MAX(Inputs!$E$37,C111))*Inputs!$E$40+MAX(0,B111-MAX(Inputs!$E$39,C111))*Inputs!$E$41 | E111: =(B111*(Inputs!$D$16-Inputs!$D$20/10000)+D111)/B111 | F111: =B111*Inputs!$D$20/10000+(B111/Inputs!$D$22*Inputs!$D$23+B111*Inputs!$D$25)*(Inputs!$D$13-Inputs!$D$14*E111)+Inputs!$D$27*Inputs!$D$28*Inputs!$D$29*(1+Inputs!$D$30*Inputs!$D$31/12)/Inputs!$D$31 | G111: =F111-D111 | H111: =IF(G111>=0,1,0) | I111: =Inputs!$E$33+MAX(0,MIN(B111,Inputs!$E$35)-MAX(0,C111))*Inputs!$E$36+MAX(0,MIN(B111,Inputs!$E$37)-MAX(Inputs!$E$35,C111))*Inputs!$E$38+MAX(0,MIN(B111,Inputs!$E$39)-MAX(Inputs!$E$37,C111))*Inputs!$E$40+MAX(0,B111-MAX(Inputs!$E$39,C111))*Inputs!$E$41 | J111: =(B111*(Inputs!$E$16-Inputs!$E$20/10000)+I111)/B111 | K111: =B111*Inputs!$E$20/10000+(B111/Inputs!$E$22*Inputs!$E$23+B111*Inputs!$E$25)*(Inputs!$E$13-Inputs!$E$14*J111)+Inputs!$E$27*Inputs!$E$28*Inputs!$E$29*(1+Inputs!$E$30*Inputs!$E$31/12)/Inputs!$E$31 | L111: =K111-I111 | M111: =IF(L111>=0,1,0) | N111: =Inputs!$E$33+MAX(0,MIN(B111,Inputs!$E$35)-MAX(0,C111))*Inputs!$E$36+MAX(0,MIN(B111,Inputs!$E$37)-MAX(Inputs!$E$35,C111))*Inputs!$E$38+MAX(0,MIN(B111,Inputs!$E$39)-MAX(Inputs!$E$37,C111))*Inputs!$E$40+MAX(0,B111-MAX(Inputs!$E$39,C111))*Inputs!$E$41 | O111: =(B111*(Inputs!$F$16-Inputs!$F$20/10000)+N111)/B111 | P111: =B111*Inputs!$F$20/10000+(B111/Inputs!$F$22*Inputs!$F$23+B111*Inputs!$F$25)*(Inputs!$F$13-Inputs!$F$14*O111)+Inputs!$F$27*Inputs!$F$28*Inputs!$F$29*(1+Inputs!$F$30*Inputs!$F$31/12)/Inputs!$F$31 | Q111: =P111-N111 | R111: =IF(Q111>=0,1,0)

Sheet Ramp
A1: Ramp · month by month from Black Friday 2026 to the end-2027 run rate (linear ESTIMATE) and 12 months at run rate
A2: Payback month = first month in which the cumulative net benefit (contribution view) is non-negative. The INTERNAL launch credit switch (Inputs section 9) applies on this sheet only; default off.
A4: Scenario | C4: Payback month (cumulative >= 0) | E4: Cumulative net over the ramp | G4: Yuno cost over the ramp | I4: Net a year at run rate (x12)
A5: Conservative | C5: =IFERROR(INDEX($A$12:$A$24,MATCH(1,I12:I24,0)),"not within the ramp") | E5: =H24 | G5: =E25 | I5: =Model!E48
A6: Base | C6: =IFERROR(INDEX($A$12:$A$24,MATCH(1,N12:N24,0)),"not within the ramp") | E6: =M24 | G6: =J25 | I6: =Model!I48
A7: Optimistic | C7: =IFERROR(INDEX($A$12:$A$24,MATCH(1,S12:S24,0)),"not within the ramp") | E7: =R24 | G7: =O25 | I7: =Model!M48
A9: Ramp is a Yuno ESTIMATE (linear from tier 1 to tier 4 over the ramp months on Inputs). Replace the Transactions column with Cordel's written projections when they arrive.
E10: Conservative | J10: Base | O10: Optimistic
A11: Month | B11: Transactions | C11: Net TPV | D11: Credit (if on) | E11: Yuno cost | F11: Gross contribution | G11: Net benefit | H11: Cumulative net | I11: Cum >= 0 | J11: Yuno cost | K11: Gross contribution | L11: Net benefit | M11: Cumulative net | N11: Cum >= 0 | O11: Yuno cost | P11: Gross contribution | Q11: Net benefit | R11: Cumulative net | S11: Cum >= 0
A12: Dec 2026 | B12: =Inputs!$E$8+(Inputs!$E$11-Inputs!$E$8)*0/(Inputs!$E$45-1) | C12: =B12*Inputs!$E$6 | D12: =IF(AND(Inputs!$E$47=1,1<=Inputs!$E$49),Inputs!$E$48,0) | E12: =Inputs!$E$33+MAX(0,MIN(C12,Inputs!$E$35)-MAX(0,(MIN(C12,Inputs!$E$34))))*Inputs!$E$36+MAX(0,MIN(C12,Inputs!$E$37)-MAX(Inputs!$E$35,(MIN(C12,Inputs!$E$34))))*Inputs!$E$38+MAX(0,MIN(C12,Inputs!$E$39)-MAX(Inputs!$E$37,(MIN(C12,Inputs!$E$34))))*Inputs!$E$40+MAX(0,C12-MAX(Inputs!$E$39,(MIN(C12,Inputs!$E$34))))*Inputs!$E$41-D12 | F12: =C12*Inputs!$D$20/10000+(C12/Inputs!$D$22*Inputs!$D$23+C12*Inputs!$D$25)*(Inputs!$D$13-Inputs!$D$14*((C12*(Inputs!$D$16-Inputs!$D$20/10000)+E12)/C12))+Inputs!$D$27*Inputs!$D$28*Inputs!$D$29*(1+Inputs!$D$30*Inputs!$D$31/12)/Inputs!$D$31 | G12: =F12-E12 | H12: =G12 | I12: =IF(H12>=0,1,0) | J12: =Inputs!$E$33+MAX(0,MIN(C12,Inputs!$E$35)-MAX(0,(MIN(C12,Inputs!$E$34))))*Inputs!$E$36+MAX(0,MIN(C12,Inputs!$E$37)-MAX(Inputs!$E$35,(MIN(C12,Inputs!$E$34))))*Inputs!$E$38+MAX(0,MIN(C12,Inputs!$E$39)-MAX(Inputs!$E$37,(MIN(C12,Inputs!$E$34))))*Inputs!$E$40+MAX(0,C12-MAX(Inputs!$E$39,(MIN(C12,Inputs!$E$34))))*Inputs!$E$41-D12 | K12: =C12*Inputs!$E$20/10000+(C12/Inputs!$E$22*Inputs!$E$23+C12*Inputs!$E$25)*(Inputs!$E$13-Inputs!$E$14*((C12*(Inputs!$E$16-Inputs!$E$20/10000)+J12)/C12))+Inputs!$E$27*Inputs!$E$28*Inputs!$E$29*(1+Inputs!$E$30*Inputs!$E$31/12)/Inputs!$E$31 | L12: =K12-J12 | M12: =L12 | N12: =IF(M12>=0,1,0) | O12: =Inputs!$E$33+MAX(0,MIN(C12,Inputs!$E$35)-MAX(0,(MIN(C12,Inputs!$E$34))))*Inputs!$E$36+MAX(0,MIN(C12,Inputs!$E$37)-MAX(Inputs!$E$35,(MIN(C12,Inputs!$E$34))))*Inputs!$E$38+MAX(0,MIN(C12,Inputs!$E$39)-MAX(Inputs!$E$37,(MIN(C12,Inputs!$E$34))))*Inputs!$E$40+MAX(0,C12-MAX(Inputs!$E$39,(MIN(C12,Inputs!$E$34))))*Inputs!$E$41-D12 | P12: =C12*Inputs!$F$20/10000+(C12/Inputs!$F$22*Inputs!$F$23+C12*Inputs!$F$25)*(Inputs!$F$13-Inputs!$F$14*((C12*(Inputs!$F$16-Inputs!$F$20/10000)+O12)/C12))+Inputs!$F$27*Inputs!$F$28*Inputs!$F$29*(1+Inputs!$F$30*Inputs!$F$31/12)/Inputs!$F$31 | Q12: =P12-O12 | R12: =Q12 | S12: =IF(R12>=0,1,0)
