Workbook

Sheet Resumen
A1: Presupuesto viaje San Francisco · German Tatis · 28-sep → 4-nov-2026
A2: Comparación: tope de la Travel & Expense Policy de Yuno (v1.0, abr-2026) vs costo real estimado en SF. USD.
A4: Fecha de salida (BOG → SFO) | B4: 46293 | D4: Airbnb elegido | E4: SOMA Executive Retreat Lower · 2 habitaciones / 1 baño · Clementina St (8th & 9th), SoMa · compartido con Samuel · check-in 28-sep 3PM
A5: Fecha de regreso (SFO → BOG) | B5: 46330 | D5: Aprobación | E5: Justo + Sean OK en DM (17-sep, '<$4k/mes'). Pendiente: hilo en #travel-requests para el Airbnb y aviso a Finance por estadía 7+ noches (Policy §4).
A6: Días en viaje | B6: =COUNT('Dia a dia'!A5:A42) | D6: Precio real del listing | E6: NO CONFIRMADO. Airbnb no muestra el precio sin sesión. Actualiza Supuestos!C8 con el precio por noche real y todo se recalcula.
A7: Noches totales | B7: =B6-1
A8: Noches en casa de Joaquín (sin costo) | B8: =COUNTIF('Dia a dia'!D5:D42,"Casa Joaquín")
A9: Noches en Airbnb (pagadas) | B9: =COUNTIF('Dia a dia'!D5:D42,"Airbnb")
A10: Escenario activo en 'Dia a dia' | B10: =Supuestos!B3
A11: Tu parte del Airbnb | B11: =Supuestos!B5
A13: Categoría | B13: Política (tope máximo) | C13: Realista (mercado SF) | D13: Ahorro | E13: Escenario activo (Día a día) | F13: Margen Realista vs Política | G13: Cómo se calcula
A14: Vuelo (ya pagado) | B14: =Supuestos!B18 | C14: =Supuestos!C18 | D14: =Supuestos!D18 | E14: =Supuestos!E18 | F14: =B14-C14 | G14: Fijo. Avianca Flex, comprado.
A15: Alojamiento Airbnb (tu parte, sin impuestos) | B15: =$B$9*Supuestos!B9 | C15: =$B$9*Supuestos!C9 | D15: =$B$9*Supuestos!D9 | E15: =SUMPRODUCT(('Dia a dia'!D5:D42="Airbnb")*1)*Supuestos!E9 | F15: =B15-C15 | G15: Noches Airbnb × tu parte por noche (Supuestos fila 9).
A16: Impuestos Airbnb (TOT + TID si < 30 noches) | B16: =$B$9*Supuestos!B9*Supuestos!B10 | C16: =$B$9*Supuestos!C9*Supuestos!C10 | D16: =$B$9*Supuestos!D9*Supuestos!D10 | E16: =SUM('Dia a dia'!E5:E42)-E15 | F16: =B16-C16 | G16: 16,25% sobre el alojamiento si reservas < 30 noches; 0% con 30+.
A17: Desayunos | B17: =$B$6*Supuestos!B11 | C17: =$B$6*Supuestos!C11 | D17: =$B$6*Supuestos!D11 | E17: =SUM('Dia a dia'!F5:F42) | F17: =B17-C17 | G17: Días × valor por escenario.
A18: Almuerzos | B18: =$B$6*Supuestos!B12 | C18: =$B$6*Supuestos!C12 | D18: =$B$6*Supuestos!D12 | E18: =SUM('Dia a dia'!G5:G42) | F18: =B18-C18 | G18: Días × valor por escenario.
A19: Cenas | B19: =$B$6*Supuestos!B13 | C19: =$B$6*Supuestos!C13 | D19: =$B$6*Supuestos!D13 | E19: =SUM('Dia a dia'!H5:H42) | F19: =B19-C19 | G19: Días × valor por escenario.
A20: Transporte local (diario) | B20: =$B$6*Supuestos!B14 | C20: =$B$6*Supuestos!C14 | D20: =$B$6*Supuestos!D14 | E20: =SUM('Dia a dia'!I5:I42)-Supuestos!E19-Supuestos!E20 | F20: =B20-C20 | G20: Días × valor por escenario.
A21: Traslados aeropuerto (llegada + salida) | B21: =Supuestos!B19+Supuestos!B20 | C21: =Supuestos!C19+Supuestos!C20 | D21: =Supuestos!D19+Supuestos!D20 | E21: =Supuestos!E19+Supuestos!E20 | F21: =B21-C21 | G21: En Política = 0 porque caben en el tope de $55/día.
A22: eSIM / datos móviles | B22: =Supuestos!B21 | C22: =Supuestos!C21 | D22: =Supuestos!D21 | E22: =Supuestos!E21 | F22: =B22-C22 | G22: Reembolsable con recibo (Policy §9).
A23: Otros diarios | B23: =$B$6*Supuestos!B15 | C23: =$B$6*Supuestos!C15 | D23: =$B$6*Supuestos!D15 | E23: =SUM('Dia a dia'!J5:J42)-Supuestos!E21 | F23: =B23-C23 | G23: Bolsillo propio salvo propósito de negocio.
A24: Lavandería / varios únicos | B24: =Supuestos!B22 | C24: =Supuestos!C22 | D24: =Supuestos!D22 | E24: =Supuestos!E22 | F24: =B24-C24 | G24: Una sola vez.
A25: Comidas con clientes / equipo (opcional) | B25: =Supuestos!B26 | C25: =Supuestos!B26 | D25: =Supuestos!B26 | E25: =Supuestos!B26 | F25: =B25-C25 | G25: Nº comidas × $85 (Supuestos B24). Fuera de los topes individuales.
A26: TOTAL DEL VIAJE | B26: =SUM(B14:B25) | C26: =SUM(C14:C25) | D26: =SUM(D14:D25) | E26: =SUM(E14:E25) | F26: =SUM(F14:F25)
A27: Total sin vuelo | B27: =B26-B14 | C27: =C26-C14 | D27: =D26-D14 | E27: =E26-E14
A28: Promedio por día (sin vuelo) | B28: =B27/$B$6 | C28: =C27/$B$6 | D28: =D27/$B$6 | E28: =E27/$B$6
A29: Promedio por semana (sin vuelo) | B29: =B28*7 | C29: =C28*7 | D29: =D28*7 | E29: =E28*7
A30: Total por mes de RAMP: septiembre (28–30 sep) | E30: =SUMPRODUCT((MONTH('Dia a dia'!A5:A42)=9)*'Dia a dia'!K5:K42) | G30: Reconciliar en RAMP antes del 5-oct.
A31: Total por mes de RAMP: octubre | E31: =SUMPRODUCT((MONTH('Dia a dia'!A5:A42)=10)*'Dia a dia'!K5:K42) | G31: Reconciliar antes del 5-nov.
A32: Total por mes de RAMP: noviembre (1–4 nov) | E32: =SUMPRODUCT((MONTH('Dia a dia'!A5:A42)=11)*'Dia a dia'!K5:K42) | G32: Reconciliar antes del 5-dic.
A34: Por semana (escenario activo)
A35: Semana | B35: Desde | C35: Hasta | D35: Días | E35: Total semana | F35: Tope política semana | G35: Margen
A36: S1 | B36: 46293 | C36: 46299 | D36: =COUNTIF('Dia a dia'!C5:C42,A36) | E36: =SUMIF('Dia a dia'!C5:C42,A36,'Dia a dia'!K5:K42) | F36: =SUMIF('Dia a dia'!C5:C42,A36,'Dia a dia'!L5:L42) | G36: =F36-E36
A37: S2 | B37: 46300 | C37: 46306 | D37: =COUNTIF('Dia a dia'!C5:C42,A37) | E37: =SUMIF('Dia a dia'!C5:C42,A37,'Dia a dia'!K5:K42) | F37: =SUMIF('Dia a dia'!C5:C42,A37,'Dia a dia'!L5:L42) | G37: =F37-E37
A38: S3 | B38: 46307 | C38: 46313 | D38: =COUNTIF('Dia a dia'!C5:C42,A38) | E38: =SUMIF('Dia a dia'!C5:C42,A38,'Dia a dia'!K5:K42) | F38: =SUMIF('Dia a dia'!C5:C42,A38,'Dia a dia'!L5:L42) | G38: =F38-E38
A39: S4 | B39: 46314 | C39: 46320 | D39: =COUNTIF('Dia a dia'!C5:C42,A39) | E39: =SUMIF('Dia a dia'!C5:C42,A39,'Dia a dia'!K5:K42) | F39: =SUMIF('Dia a dia'!C5:C42,A39,'Dia a dia'!L5:L42) | G39: =F39-E39
A40: S5 | B40: 46321 | C40: 46327 | D40: =COUNTIF('Dia a dia'!C5:C42,A40) | E40: =SUMIF('Dia a dia'!C5:C42,A40,'Dia a dia'!K5:K42) | F40: =SUMIF('Dia a dia'!C5:C42,A40,'Dia a dia'!L5:L42) | G40: =F40-E40
A41: S6 | B41: 46328 | C41: 46330 | D41: =COUNTIF('Dia a dia'!C5:C42,A41) | E41: =SUMIF('Dia a dia'!C5:C42,A41,'Dia a dia'!K5:K42) | F41: =SUMIF('Dia a dia'!C5:C42,A41,'Dia a dia'!L5:L42) | G41: =F41-E41
A44: Lecturas clave
A45: 1. Alojamiento: con el Airbnb compartido (~$130/noche la unidad, tu parte ~$65) estás muy por debajo del tope de $220/noche por persona. Es el mayor ahorro del viaje.
...

Sheet Supuestos
A1: Supuestos y escenarios
A2: Celdas amarillas = editables. Todo lo demás se recalcula. Montos en USD.
A3: Escenario activo (mueve la tabla Día a día) | B3: Realista
A4: Índice de escenario (auto) | B4: =IF(B3="Política",1,IF(B3="Realista",2,3))
A5: Tu parte del Airbnb (compartido con Samuel) | B5: 0.5
A7: Categoría (por día / por noche) | B7: Política (tope Yuno) | C7: Realista (mercado SF) | D7: Ahorro | E7: Valor activo | F7: Unidad | G7: Fuente / nota
A8: Airbnb: precio de la unidad por noche (2 pax, sin impuestos) | B8: 440 | C8: 130 | D8: 121 | E8: =CHOOSE($B$4,B8,C8,D8) | F8: USD/noche | G8: Política: 2 × $220 (tope hotel SF por persona). Realista: listing SOMA Executive Retreat (2BR) aprobado por Sean como '<$4k/mes' = ~$130/noche. CONFIRMAR con el precio real del listing. Ahorro: cuartil inferior Airbnb SF $121 (AirROI 2026).
A9: Airbnb: tu parte por noche (sin impuestos) | B9: =B8*$B$5 | C9: =C8*$B$5 | D9: =D8*$B$5 | E9: =CHOOSE($B$4,B9,C9,D9) | F9: USD/noche | G9: =unidad × tu parte.
A10: Impuestos Airbnb (TOT 14% + TID 2,25%) si la reserva es < 30 noches | B10: =IF(Resumen!$B$9<30,0.1625,0) | C10: =IF(Resumen!$B$9<30,0.1625,0) | D10: =IF(Resumen!$B$9<30,0.1625,0) | E10: =CHOOSE($B$4,B10,C10,D10) | F10: % | G10: SF Transient Occupancy Tax 14% + Tourism Improvement District 2,25% aplican solo a estadías < 30 noches (sftreasurer.org). Con 30+ noches queda en 0%.
A11: Desayuno | B11: 15 | C11: 12 | D11: 5 | E11: =CHOOSE($B$4,B11,C11,D11) | F11: USD/día | G11: Política: tope $15 (recibo auto <$30). Realista: café $5,50 + bagel/pastry ~$6 con tax y tip. Ahorro: mercado (Trader Joe's) en el Airbnb.
A12: Almuerzo | B12: 25 | C12: 25 | D12: 15 | E12: =CHOOSE($B$4,B12,C12,D12) | F12: USD/día | G12: Política: tope $25. Realista: casual $15–25 en menú + ~30% (tax 8,625% + SF Mandate 3–7% + tip 18–20%). Ahorro: fast-casual / bowl ~$12 + tax.
A13: Cena | B13: 50 | C13: 45 | D13: 20 | E13: =CHOOSE($B$4,B13,C13,D13) | F13: USD/día | G13: Política: tope $50 (recibo obligatorio, tip incluido). Realista: plato $20–40 + bebida + 30%. Ahorro: cocinar (groceries $400–500/mes = ~$15/día).
A14: Transporte local | B14: 55 | C14: 15 | D14: 6 | E14: =CHOOSE($B$4,B14,C14,D14) | F14: USD/día | G14: Política: tope $55/día (Uber default, transporte público primero). Realista: Muni pass 'A' $104/mes + 3–4 Uber/semana × ~$25. Ahorro: solo Muni/BART ($2,85/viaje, pass M $86).
A15: Otros diarios (snacks, agua, propinas varias, farmacia) | B15: 0 | C15: 5 | D15: 2 | E15: =CHOOSE($B$4,B15,C15,D15) | F15: USD/día | G15: No es una categoría de la política: sale de tu bolsillo salvo que tenga propósito de negocio.
A17: Gastos únicos (una sola vez en el viaje) | B17: Política (tope Yuno) | C17: Realista | D17: Ahorro | E17: Valor activo | F17: Unidad | G17: Fuente / nota
A18: Vuelo BOG–SFO ida y vuelta (YA COMPRADO) | B18: 1064 | C18: 1064 | D18: 1064 | E18: =CHOOSE($B$4,B18,C18,D18) | F18: USD | G18: Pagado. Avianca Flex vía SAL (hilo #travel-requests 14-sep). Tiquete flex: puedes volver antes.
A19: Traslado SFO → Airbnb (28-sep, llegada) | B19: 0 | C19: 45 | D19: 11.15 | E19: =CHOOSE($B$4,B19,C19,D19) | F19: USD | G19: Política: cabe dentro del tope de $55/día, por eso 0 extra. Realista: UberX SFO–downtown $35–55 (+$5,50 airport surcharge). Ahorro: BART $11,15.
A20: Traslado casa → SFO (4-nov, salida) | B20: 0 | C20: 11.15 | D20: 11.15 | E20: =CHOOSE($B$4,B20,C20,D20) | F20: USD | G20: BART desde el centro $11,15 (una vía). Sube a 45 si vas en Uber con maletas.
A21: eSIM / datos móviles (38 días) | B21: 75 | C21: 75 | D21: 57 | E21: =CHOOSE($B$4,B21,C21,D21) | F21: USD | G21: Reembolsable con recibo (Policy §9). T-Mobile US Pass $50/30 días + $25/7 días (se activa dentro de EE.UU.). Ahorro: Airalo 50 GB/30 días $42 + top-up.
A22: Lavandería / varios únicos | B22: 0 | C22: 20 | D22: 20 | E22: =CHOOSE($B$4,B22,C22,D22) | F22: USD | G22: El listing tiene lavadora. Wash & fold en SF $2,39–2,50/lb si la necesitas.
A24: Comidas con clientes / equipo (número estimado en el viaje) | B24: 0 | C24: Tope $85 por persona (SF). Requiere etiquetar asistentes en RAMP. No cuenta contra tus topes individuales. Déjalo en 0 si no lo quieres en el presupuesto.
A25: Costo por comida con clientes (tope SF por persona) | B25: 85
A26: Total comidas con clientes / equipo | B26: =B24*B25

Sheet Dia a dia
A1: Presupuesto día a día · San Francisco · 28-sep → 4-nov-2026
A2: ="Escenario activo: "&Supuestos!B3&" | Cambia el escenario en Supuestos!B3. Cambia el alojamiento de cada noche con el desplegable de la columna D."
A4: Fecha | B4: Día | C4: Semana | D4: Dónde duermes esta noche | E4: Alojamiento $ | F4: Desayuno | G4: Almuerzo | H4: Cena | I4: Transporte | J4: Otros | K4: Total del día | L4: Tope política del día | M4: Margen vs tope | N4: Notas
A5: 46293 | B5: Lunes | C5: S1 | D5: Airbnb | E5: =IF(D5="Airbnb",Supuestos!$E$9*(1+Supuestos!$E$10),0) | F5: =Supuestos!$E$11 | G5: =Supuestos!$E$12 | H5: =Supuestos!$E$13 | I5: =Supuestos!$E$14+Supuestos!$E$19 | J5: =Supuestos!$E$15+Supuestos!$E$21 | K5: =SUM(E5:J5) | L5: =IF(D5="Airbnb",Supuestos!$B$9,0)+Supuestos!$B$11+Supuestos!$B$12+Supuestos!$B$13+Supuestos!$B$14 | M5: =L5-K5 | N5: Llegada SFO. Check-in Airbnb 3PM (SoMa). Traslado + eSIM.
A6: 46294 | B6: Martes | C6: S1 | D6: Airbnb | E6: =IF(D6="Airbnb",Supuestos!$E$9*(1+Supuestos!$E$10),0) | F6: =Supuestos!$E$11 | G6: =Supuestos!$E$12 | H6: =Supuestos!$E$13 | I6: =Supuestos!$E$14 | J6: =Supuestos!$E$15 | K6: =SUM(E6:J6) | L6: =IF(D6="Airbnb",Supuestos!$B$9,0)+Supuestos!$B$11+Supuestos!$B$12+Supuestos!$B$13+Supuestos!$B$14 | M6: =L6-K6
A7: 46295 | B7: Miércoles | C7: S1 | D7: Airbnb | E7: =IF(D7="Airbnb",Supuestos!$E$9*(1+Supuestos!$E$10),0) | F7: =Supuestos!$E$11 | G7: =Supuestos!$E$12 | H7: =Supuestos!$E$13 | I7: =Supuestos!$E$14 | J7: =Supuestos!$E$15 | K7: =SUM(E7:J7) | L7: =IF(D7="Airbnb",Supuestos!$B$9,0)+Supuestos!$B$11+Supuestos!$B$12+Supuestos!$B$13+Supuestos!$B$14 | M7: =L7-K7
A8: 46296 | B8: Jueves | C8: S1 | D8: Airbnb | E8: =IF(D8="Airbnb",Supuestos!$E$9*(1+Supuestos!$E$10),0) | F8: =Supuestos!$E$11 | G8: =Supuestos!$E$12 | H8: =Supuestos!$E$13 | I8: =Supuestos!$E$14 | J8: =Supuestos!$E$15 | K8: =SUM(E8:J8) | L8: =IF(D8="Airbnb",Supuestos!$B$9,0)+Supuestos!$B$11+Supuestos!$B$12+Supuestos!$B$13+Supuestos!$B$14 | M8: =L8-K8
A9: 46297 | B9: Viernes | C9: S1 | D9: Airbnb | E9: =IF(D9="Airbnb",Supuestos!$E$9*(1+Supuestos!$E$10),0) | F9: =Supuestos!$E$11 | G9: =Supuestos!$E$12 | H9: =Supuestos!$E$13 | I9: =Supuestos!$E$14 | J9: =Supuestos!$E$15 | K9: =SUM(E9:J9) | L9: =IF(D9="Airbnb",Supuestos!$B$9,0)+Supuestos!$B$11+Supuestos!$B$12+Supuestos!$B$13+Supuestos!$B$14 | M9: =L9-K9
A10: 46298 | B10: Sábado | C10: S1 | D10: Airbnb | E10: =IF(D10="Airbnb",Supuestos!$E$9*(1+Supuestos!$E$10),0) | F10: =Supuestos!$E$11 | G10: =Supuestos!$E$12 | H10: =Supuestos!$E$13 | I10: =Supuestos!$E$14 | J10: =Supuestos!$E$15 | K10: =SUM(E10:J10) | L10: =IF(D10="Airbnb",Supuestos!$B$9,0)+Supuestos!$B$11+Supuestos!$B$12+Supuestos!$B$13+Supuestos!$B$14 | M10: =L10-K10 | N10: Fin de semana
A11: 46299 | B11: Domingo | C11: S1 | D11: Airbnb | E11: =IF(D11="Airbnb",Supuestos!$E$9*(1+Supuestos!$E$10),0) | F11: =Supuestos!$E$11 | G11: =Supuestos!$E$12 | H11: =Supuestos!$E$13 | I11: =Supuestos!$E$14 | J11: =Supuestos!$E$15 | K11: =SUM(E11:J11) | L11: =IF(D11="Airbnb",Supuestos!$B$9,0)+Supuestos!$B$11+Supuestos!$B$12+Supuestos!$B$13+Supuestos!$B$14 | M11: =L11-K11 | N11: Fin de semana
A12: 46300 | B12: Lunes | C12: S2 | D12: Airbnb | E12: =IF(D12="Airbnb",Supuestos!$E$9*(1+Supuestos!$E$10),0) | F12: =Supuestos!$E$11 | G12: =Supuestos!$E$12 | H12: =Supuestos!$E$13 | I12: =Supuestos!$E$14 | J12: =Supuestos!$E$15 | K12: =SUM(E12:J12) | L12: =IF(D12="Airbnb",Supuestos!$B$9,0)+Supuestos!$B$11+Supuestos!$B$12+Supuestos!$B$13+Supuestos!$B$14 | M12: =L12-K12 | N12: Deadline RAMP: reconciliar cargos de sep (28–30).
A13: 46301 | B13: Martes | C13: S2 | D13: Airbnb | E13: =IF(D13="Airbnb",Supuestos!$E$9*(1+Supuestos!$E$10),0) | F13: =Supuestos!$E$11 | G13: =Supuestos!$E$12 | H13: =Supuestos!$E$13 | I13: =Supuestos!$E$14 | J13: =Supuestos!$E$15 | K13: =SUM(E13:J13) | L13: =IF(D13="Airbnb",Supuestos!$B$9,0)+Supuestos!$B$11+Supuestos!$B$12+Supuestos!$B$13+Supuestos!$B$14 | M13: =L13-K13
A14: 46302 | B14: Miércoles | C14: S2 | D14: Airbnb | E14: =IF(D14="Airbnb",Supuestos!$E$9*(1+Supuestos!$E$10),0) | F14: =Supuestos!$E$11 | G14: =Supuestos!$E$12 | H14: =Supuestos!$E$13 | I14: =Supuestos!$E$14 | J14: =Supuestos!$E$15 | K14: =SUM(E14:J14) | L14: =IF(D14="Airbnb",Supuestos!$B$9,0)+Supuestos!$B$11+Supuestos!$B$12+Supuestos!$B$13+Supuestos!$B$14 | M14: =L14-K14
A15: 46303 | B15: Jueves | C15: S2 | D15: Airbnb | E15: =IF(D15="Airbnb",Supuestos!$E$9*(1+Supuestos!$E$10),0) | F15: =Supuestos!$E$11 | G15: =Supuestos!$E$12 | H15: =Supuestos!$E$13 | I15: =Supuestos!$E$14 | J15: =Supuestos!$E$15 | K15: =SUM(E15:J15) | L15: =IF(D15="Airbnb",Supuestos!$B$9,0)+Supuestos!$B$11+Supuestos!$B$12+Supuestos!$B$13+Supuestos!$B$14 | M15: =L15-K15
A16: 46304 | B16: Viernes | C16: S2 | D16: Airbnb | E16: =IF(D16="Airbnb",Supuestos!$E$9*(1+Supuestos!$E$10),0) | F16: =Supuestos!$E$11 | G16: =Supuestos!$E$12 | H16: =Supuestos!$E$13 | I16: =Supuestos!$E$14 | J16: =Supuestos!$E$15 | K16: =SUM(E16:J16) | L16: =IF(D16="Airbnb",Supuestos!$B$9,0)+Supuestos!$B$11+Supuestos!$B$12+Supuestos!$B$13+Supuestos!$B$14 | M16: =L16-K16
A17: 46305 | B17: Sábado | C17: S2 | D17: Airbnb | E17: =IF(D17="Airbnb",Supuestos!$E$9*(1+Supuestos!$E$10),0) | F17: =Supuestos!$E$11 | G17: =Supuestos!$E$12 | H17: =Supuestos!$E$13 | I17: =Supuestos!$E$14 | J17: =Supuestos!$E$15 | K17: =SUM(E17:J17) | L17: =IF(D17="Airbnb",Supuestos!$B$9,0)+Supuestos!$B$11+Supuestos!$B$12+Supuestos!$B$13+Supuestos!$B$14 | M17: =L17-K17 | N17: Fin de semana
A18: 46306 | B18: Domingo | C18: S2 | D18: Airbnb | E18: =IF(D18="Airbnb",Supuestos!$E$9*(1+Supuestos!$E$10),0) | F18: =Supuestos!$E$11 | G18: =Supuestos!$E$12 | H18: =Supuestos!$E$13 | I18: =Supuestos!$E$14 | J18: =Supuestos!$E$15 | K18: =SUM(E18:J18) | L18: =IF(D18="Airbnb",Supuestos!$B$9,0)+Supuestos!$B$11+Supuestos!$B$12+Supuestos!$B$13+Supuestos!$B$14 | M18: =L18-K18 | N18: Fin de semana
A19: 46307 | B19: Lunes | C19: S3 | D19: Airbnb | E19: =IF(D19="Airbnb",Supuestos!$E$9*(1+Supuestos!$E$10),0) | F19: =Supuestos!$E$11 | G19: =Supuestos!$E$12 | H19: =Supuestos!$E$13 | I19: =Supuestos!$E$14 | J19: =Supuestos!$E$15 | K19: =SUM(E19:J19) | L19: =IF(D19="Airbnb",Supuestos!$B$9,0)+Supuestos!$B$11+Supuestos!$B$12+Supuestos!$B$13+Supuestos!$B$14 | M19: =L19-K19
A20: 46308 | B20: Martes | C20: S3 | D20: Airbnb | E20: =IF(D20="Airbnb",Supuestos!$E$9*(1+Supuestos!$E$10),0) | F20: =Supuestos!$E$11 | G20: =Supuestos!$E$12 | H20: =Supuestos!$E$13 | I20: =Supuestos!$E$14 | J20: =Supuestos!$E$15 | K20: =SUM(E20:J20) | L20: =IF(D20="Airbnb",Supuestos!$B$9,0)+Supuestos!$B$11+Supuestos!$B$12+Supuestos!$B$13+Supuestos!$B$14 | M20: =L20-K20
A21: 46309 | B21: Miércoles | C21: S3 | D21: Airbnb | E21: =IF(D21="Airbnb",Supuestos!$E$9*(1+Supuestos!$E$10),0) | F21: =Supuestos!$E$11 | G21: =Supuestos!$E$12 | H21: =Supuestos!$E$13 | I21: =Supuestos!$E$14 | J21: =Supuestos!$E$15 | K21: =SUM(E21:J21) | L21: =IF(D21="Airbnb",Supuestos!$B$9,0)+Supuestos!$B$11+Supuestos!$B$12+Supuestos!$B$13+Supuestos!$B$14 | M21: =L21-K21
A22: 46310 | B22: Jueves | C22: S3 | D22: Airbnb | E22: =IF(D22="Airbnb",Supuestos!$E$9*(1+Supuestos!$E$10),0) | F22: =Supuestos!$E$11 | G22: =Supuestos!$E$12 | H22: =Supuestos!$E$13 | I22: =Supuestos!$E$14 | J22: =Supuestos!$E$15 | K22: =SUM(E22:J22) | L22: =IF(D22="Airbnb",Supuestos!$B$9,0)+Supuestos!$B$11+Supuestos!$B$12+Supuestos!$B$13+Supuestos!$B$14 | M22: =L22-K22
A23: 46311 | B23: Viernes | C23: S3 | D23: Airbnb | E23: =IF(D23="Airbnb",Supuestos!$E$9*(1+Supuestos!$E$10),0) | F23: =Supuestos!$E$11 | G23: =Supuestos!$E$12 | H23: =Supuestos!$E$13 | I23: =Supuestos!$E$14 | J23: =Supuestos!$E$15 | K23: =SUM(E23:J23) | L23: =IF(D23="Airbnb",Supuestos!$B$9,0)+Supuestos!$B$11+Supuestos!$B$12+Supuestos!$B$13+Supuestos!$B$14 | M23: =L23-K23
A24: 46312 | B24: Sábado | C24: S3 | D24: Airbnb | E24: =IF(D24="Airbnb",Supuestos!$E$9*(1+Supuestos!$E$10),0) | F24: =Supuestos!$E$11 | G24: =Supuestos!$E$12 | H24: =Supuestos!$E$13 | I24: =Supuestos!$E$14 | J24: =Supuestos!$E$15 | K24: =SUM(E24:J24) | L24: =IF(D24="Airbnb",Supuestos!$B$9,0)+Supuestos!$B$11+Supuestos!$B$12+Supuestos!$B$13+Supuestos!$B$14 | M24: =L24-K24 | N24: Fin de semana
A25: 46313 | B25: Domingo | C25: S3 | D25: Airbnb | E25: =IF(D25="Airbnb",Supuestos!$E$9*(1+Supuestos!$E$10),0) | F25: =Supuestos!$E$11 | G25: =Supuestos!$E$12 | H25: =Supuestos!$E$13 | I25: =Supuestos!$E$14 | J25: =Supuestos!$E$15 | K25: =SUM(E25:J25) | L25: =IF(D25="Airbnb",Supuestos!$B$9,0)+Supuestos!$B$11+Supuestos!$B$12+Supuestos!$B$13+Supuestos!$B$14 | M25: =L25-K25 | N25: Fin de semana
A26: 46314 | B26: Lunes | C26: S4 | D26: Airbnb | E26: =IF(D26="Airbnb",Supuestos!$E$9*(1+Supuestos!$E$10),0) | F26: =Supuestos!$E$11 | G26: =Supuestos!$E$12 | H26: =Supuestos!$E$13 | I26: =Supuestos!$E$14 | J26: =Supuestos!$E$15 | K26: =SUM(E26:J26) | L26: =IF(D26="Airbnb",Supuestos!$B$9,0)+Supuestos!$B$11+Supuestos!$B$12+Supuestos!$B$13+Supuestos!$B$14 | M26: =L26-K26
A27: 46315 | B27: Martes | C27: S4 | D27: Airbnb | E27: =IF(D27="Airbnb",Supuestos!$E$9*(1+Supuestos!$E$10),0) | F27: =Supuestos!$E$11 | G27: =Supuestos!$E$12 | H27: =Supuestos!$E$13 | I27: =Supuestos!$E$14 | J27: =Supuestos!$E$15 | K27: =SUM(E27:J27) | L27: =IF(D27="Airbnb",Supuestos!$B$9,0)+Supuestos!$B$11+Supuestos!$B$12+Supuestos!$B$13+Supuestos!$B$14 | M27: =L27-K27
A28: 46316 | B28: Miércoles | C28: S4 | D28: Airbnb | E28: =IF(D28="Airbnb",Supuestos!$E$9*(1+Supuestos!$E$10),0) | F28: =Supuestos!$E$11 | G28: =Supuestos!$E$12 | H28: =Supuestos!$E$13 | I28: =Supuestos!$E$14 | J28: =Supuestos!$E$15 | K28: =SUM(E28:J28) | L28: =IF(D28="Airbnb",Supuestos!$B$9,0)+Supuestos!$B$11+Supuestos!$B$12+Supuestos!$B$13+Supuestos!$B$14 | M28: =L28-K28
A29: 46317 | B29: Jueves | C29: S4 | D29: Airbnb | E29: =IF(D29="Airbnb",Supuestos!$E$9*(1+Supuestos!$E$10),0) | F29: =Supuestos!$E$11 | G29: =Supuestos!$E$12 | H29: =Supuestos!$E$13 | I29: =Supuestos!$E$14 | J29: =Supuestos!$E$15 | K29: =SUM(E29:J29) | L29: =IF(D29="Airbnb",Supuestos!$B$9,0)+Supuestos!$B$11+Supuestos!$B$12+Supuestos!$B$13+Supuestos!$B$14 | M29: =L29-K29
A30: 46318 | B30: Viernes | C30: S4 | D30: Airbnb | E30: =IF(D30="Airbnb",Supuestos!$E$9*(1+Supuestos!$E$10),0) | F30: =Supuestos!$E$11 | G30: =Supuestos!$E$12 | H30: =Supuestos!$E$13 | I30: =Supuestos!$E$14 | J30: =Supuestos!$E$15 | K30: =SUM(E30:J30) | L30: =IF(D30="Airbnb",Supuestos!$B$9,0)+Supuestos!$B$11+Supuestos!$B$12+Supuestos!$B$13+Supuestos!$B$14 | M30: =L30-K30
A31: 46319 | B31: Sábado | C31: S4 | D31: Airbnb | E31: =IF(D31="Airbnb",Supuestos!$E$9*(1+Supuestos!$E$10),0) | F31: =Supuestos!$E$11 | G31: =Supuestos!$E$12 | H31: =Supuestos!$E$13 | I31: =Supuestos!$E$14 | J31: =Supuestos!$E$15 | K31: =SUM(E31:J31) | L31: =IF(D31="Airbnb",Supuestos!$B$9,0)+Supuestos!$B$11+Supuestos!$B$12+Supuestos!$B$13+Supuestos!$B$14 | M31: =L31-K31 | N31: Fin de semana
A32: 46320 | B32: Domingo | C32: S4 | D32: Casa Joaquín | E32: =IF(D32="Airbnb",Supuestos!$E$9*(1+Supuestos!$E$10),0) | F32: =Supuestos!$E$11 | G32: =Supuestos!$E$12 | H32: =Supuestos!$E$13 | I32: =Supuestos!$E$14 | J32: =Supuestos!$E$15 | K32: =SUM(E32:J32) | L32: =IF(D32="Airbnb",Supuestos!$B$9,0)+Supuestos!$B$11+Supuestos!$B$12+Supuestos!$B$13+Supuestos!$B$14 | M32: =L32-K32 | N32: SUPUESTO: check-out Airbnb y te mudas a casa de Joaquín (10 noches). Si son otras fechas, cambia la columna D.
A33: 46321 | B33: Lunes | C33: S5 | D33: Casa Joaquín | E33: =IF(D33="Airbnb",Supuestos!$E$9*(1+Supuestos!$E$10),0) | F33: =Supuestos!$E$11 | G33: =Supuestos!$E$12 | H33: =Supuestos!$E$13 | I33: =Supuestos!$E$14 | J33: =Supuestos!$E$15 | K33: =SUM(E33:J33) | L33: =IF(D33="Airbnb",Supuestos!$B$9,0)+Supuestos!$B$11+Supuestos!$B$12+Supuestos!$B$13+Supuestos!$B$14 | M33: =L33-K33
A34: 46322 | B34: Martes | C34: S5 | D34: Casa Joaquín | E34: =IF(D34="Airbnb",Supuestos!$E$9*(1+Supuestos!$E$10),0) | F34: =Supuestos!$E$11 | G34: =Supuestos!$E$12 | H34: =Supuestos!$E$13 | I34: =Supuestos!$E$14 | J34: =Supuestos!$E$15 | K34: =SUM(E34:J34) | L34: =IF(D34="Airbnb",Supuestos!$B$9,0)+Supuestos!$B$11+Supuestos!$B$12+Supuestos!$B$13+Supuestos!$B$14 | M34: =L34-K34
A35: 46323 | B35: Miércoles | C35: S5 | D35: Casa Joaquín | E35: =IF(D35="Airbnb",Supuestos!$E$9*(1+Supuestos!$E$10),0) | F35: =Supuestos!$E$11 | G35: =Supuestos!$E$12 | H35: =Supuestos!$E$13 | I35: =Supuestos!$E$14 | J35: =Supuestos!$E$15 | K35: =SUM(E35:J35) | L35: =IF(D35="Airbnb",Supuestos!$B$9,0)+Supuestos!$B$11+Supuestos!$B$12+Supuestos!$B$13+Supuestos!$B$14 | M35: =L35-K35
A36: 46324 | B36: Jueves | C36: S5 | D36: Casa Joaquín | E36: =IF(D36="Airbnb",Supuestos!$E$9*(1+Supuestos!$E$10),0) | F36: =Supuestos!$E$11 | G36: =Supuestos!$E$12 | H36: =Supuestos!$E$13 | I36: =Supuestos!$E$14 | J36: =Supuestos!$E$15 | K36: =SUM(E36:J36) | L36: =IF(D36="Airbnb",Supuestos!$B$9,0)+Supuestos!$B$11+Supuestos!$B$12+Supuestos!$B$13+Supuestos!$B$14 | M36: =L36-K36
A37: 46325 | B37: Viernes | C37: S5 | D37: Casa Joaquín | E37: =IF(D37="Airbnb",Supuestos!$E$9*(1+Supuestos!$E$10),0) | F37: =Supuestos!$E$11 | G37: =Supuestos!$E$12 | H37: =Supuestos!$E$13 | I37: =Supuestos!$E$14 | J37: =Supuestos!$E$15 | K37: =SUM(E37:J37) | L37: =IF(D37="Airbnb",Supuestos!$B$9,0)+Supuestos!$B$11+Supuestos!$B$12+Supuestos!$B$13+Supuestos!$B$14 | M37: =L37-K37
A38: 46326 | B38: Sábado | C38: S5 | D38: Casa Joaquín | E38: =IF(D38="Airbnb",Supuestos!$E$9*(1+Supuestos!$E$10),0) | F38: =Supuestos!$E$11 | G38: =Supuestos!$E$12 | H38: =Supuestos!$E$13 | I38: =Supuestos!$E$14 | J38: =Supuestos!$E$15 | K38: =SUM(E38:J38) | L38: =IF(D38="Airbnb",Supuestos!$B$9,0)+Supuestos!$B$11+Supuestos!$B$12+Supuestos!$B$13+Supuestos!$B$14 | M38: =L38-K38 | N38: Fin de semana
A39: 46327 | B39: Domingo | C39: S5 | D39: Casa Joaquín | E39: =IF(D39="Airbnb",Supuestos!$E$9*(1+Supuestos!$E$10),0) | F39: =Supuestos!$E$11 | G39: =Supuestos!$E$12 | H39: =Supuestos!$E$13 | I39: =Supuestos!$E$14 | J39: =Supuestos!$E$15 | K39: =SUM(E39:J39) | L39: =IF(D39="Airbnb",Supuestos!$B$9,0)+Supuestos!$B$11+Supuestos!$B$12+Supuestos!$B$13+Supuestos!$B$14 | M39: =L39-K39 | N39: Termina el horario de verano en EE.UU. (PST).
A40: 46328 | B40: Lunes | C40: S6 | D40: Casa Joaquín | E40: =IF(D40="Airbnb",Supuestos!$E$9*(1+Supuestos!$E$10),0) | F40: =Supuestos!$E$11 | G40: =Supuestos!$E$12 | H40: =Supuestos!$E$13 | I40: =Supuestos!$E$14 | J40: =Supuestos!$E$15 | K40: =SUM(E40:J40) | L40: =IF(D40="Airbnb",Supuestos!$B$9,0)+Supuestos!$B$11+Supuestos!$B$12+Supuestos!$B$13+Supuestos!$B$14 | M40: =L40-K40
A41: 46329 | B41: Martes | C41: S6 | D41: Casa Joaquín | E41: =IF(D41="Airbnb",Supuestos!$E$9*(1+Supuestos!$E$10),0) | F41: =Supuestos!$E$11 | G41: =Supuestos!$E$12 | H41: =Supuestos!$E$13 | I41: =Supuestos!$E$14 | J41: =Supuestos!$E$15 | K41: =SUM(E41:J41) | L41: =IF(D41="Airbnb",Supuestos!$B$9,0)+Supuestos!$B$11+Supuestos!$B$12+Supuestos!$B$13+Supuestos!$B$14 | M41: =L41-K41
...

Sheet Politica Yuno
A1: Yuno Travel & Expense Policy v1.0 (abr-2026) · lo que aplica a este viaje
A2: Fuente: Google Doc 'Travel & Expense Policy' (Finance). Página de ciudad: San Francisco (Parte 3). Topes en USD, duros; exceder sin aprobación escrita = descuento de nómina.
A4: Categoría (San Francisco) | B4: Tope | C4: Unidad | D4: Nota de la política
A5: Hotel / Airbnb por noche (sin impuestos) | B5: 220 | C5: USD/noche | D5: 3 estrellas equivalente. Airbnb permitido si cumple el tope. Estadías 7+ noches: contactar a Finance antes de reservar. Considerar Oakland/South Bay si es mucho más barato y BART es práctico.
A6: Desayuno | B6: 15 | C6: USD/comida | D6: Recibo autogenerado si < $30. Tip incluido en el tope.
A7: Almuerzo | B7: 25 | C7: USD/comida | D7: Recibo autogenerado si < $30. Tip incluido en el tope.
A8: Cena | B8: 50 | C8: USD/comida | D8: Recibo obligatorio. Una bebida con la comida es aceptable dentro del tope. Tip incluido.
A9: Comida con equipo / cliente, por persona | B9: 85 | C9: USD/persona | D9: Etiquetar a todos los asistentes en RAMP + propósito de negocio + recibo siempre.
A10: Transporte local por día | B10: 55 | C10: USD/día | D10: Uber por defecto; transporte público primero donde exista. BART cubre SFO: siempre primera opción. Lyft solo si Uber no está disponible.
A11: Tope total diario implícito (alojamiento + 3 comidas + transporte) | B11: =B5+B6+B7+B8+B10 | C11: USD/día | D11: Suma de los topes individuales: $220 + $15 + $25 + $50 + $55 = $365. Referencia GSA FY2026 para SF: $272 lodging + $92 M&IE = $364.
A13: Regla global | B13: Qué significa para este viaje | C13: Estado / acción
A14: Aprobación en #travel-requests antes de reservar (§2) | B14: Vuelo y alojamiento deben tener hilo aprobado por Lex o Joha. El DM con Justo/Sean no es el hilo oficial. | C14: Vuelo: hilo del 14-sep OK. Airbnb: abrir hilo con el link del listing antes de pagar.
A15: Reserva con 10+ días de anticipación (§2, §3) | B15: Salida 28-sep. La reserva del Airbnb debería estar hecha antes del 18-sep; si no, pedir aprobación escrita del Region Leader. | C15: Verificar.
A16: Estadías de 7+ noches (§4) | B16: Contactar a Finance antes de reservar. Aplica de lleno (27 noches en Airbnb). | C16: Escribir a Finance / #travel-requests.
A17: Todo con tarjeta RAMP (§1, §7) | B17: Nada con tarjeta personal salvo autorización escrita de Finance. Cargos personales: avisar y reembolsar en 5 días hábiles. | C17: Usar RAMP para Airbnb, comidas, transporte, eSIM.
A18: Topes por comida, no por día (§5) | B18: $15 desayuno / $25 almuerzo / $50 cena. No se pueden sumar (p. ej. saltar desayuno y gastar $40 en almuerzo no aplica). | C18: Presupuesto construido por comida.
A19: Tips dentro del tope (§5, NA) | B19: En EE.UU. el tip (18–20%) va dentro del tope, no encima. Un almuerzo de $25 en menú excede el tope tras tax + tip. | C19: Apuntar a ~$19 en menú para almuerzo y ~$38 en cena.
A20: Reconciliación antes del 5 del mes siguiente (§8) | B20: Recibo + memo con propósito + categoría (+ asistentes en comidas grupales). | C20: 5-oct, 5-nov, 5-dic.
A21: Transporte: público primero, Uber por defecto (§6) | B21: BART desde SFO; Muni/BART dentro de SF; Uber cuando no sea práctico. Car rental requiere Region Leader. | C21: Muni pass 'A' $104/mes + BART SFO.
A22: Viaje internacional (§9) | B22: Seguro de viaje lo da la empresa (verificar con People). SIM/datos reembolsables con recibo. Sin adelantos de efectivo. | C22: Confirmar seguro con People antes del 28-sep.
A23: Bleisure (§10) | B23: Días personales corren por tu cuenta. Si extiendes, avisar a Region Leader y Finance. Con tiquete flex, volver antes no tiene costo de política. | C23: N/A por ahora.
A24: No reembolsable | B24: Minibar, room service, pay-per-view, alcohol como ítem dominante, upgrades de seguro en alquiler de autos, car service privado. | C24: —

Sheet Research SF
A1: Research de costos reales en San Francisco (sep-2026)
A2: Fuentes públicas consultadas el 22-sep-2026. Los rangos alimentan las columnas Realista y Ahorro de Supuestos.
A4: Ítem | B4: Valor / rango | C4: Cómo lo usé | D4: Fuente
A5: Airbnb SF: tarifa promedio por noche | B5: $276 promedio; mediana $186; cuartil inferior $121; top 25% $314 | C5: Ahorro = $121 (unidad). Referencia para validar el listing. | D5: https://www.airroi.com/airbnb-data/united-states/california/san-francisco
A6: Airbnb SF: ingreso mensual mediano por listing | B6: $3,301 / mes | C6: Consistente con el '<$4k/mes' de Sean para el listing elegido. | D6: https://www.airroi.com/airbnb-data/united-states/california/san-francisco
A7: Apartamentos amoblados por mes (Airbnb-friendly buildings) | B7: $2,030 – $4,244 / mes (NEMA $3,168; HQ $2,310; 77 Bluxome $2,030; Azure $4,244) | C7: Alternativa si el Airbnb cae. Con 30+ noches no hay TOT. | D7: https://www.airbnb.com/airbnb-friendly/apartments/san-francisco-ca
A8: Hotel 3 estrellas SF por noche | B8: $160 – $189 promedio; fines de semana hasta $332 | C8: Comparación vs tope $220. Un hotel 3* solo cabe entre semana. | D8: https://www.booking.com/threestars/city/us/san-francisco.html
A9: Impuestos alojamiento < 30 noches | B9: TOT 14% + Tourism Improvement District 2,25% (Zona 1) | C9: Supuestos fila 10. 30+ noches = exento. | D9: https://sftreasurer.org/business/taxes-fees/transient-occupancy-tax-tot
A10: Airbnb: fee de servicio al huésped 2026 | B10: Migró al host (15,5%); el huésped ve precio total sin fee separado | C10: No añadí fee de servicio aparte. | D10: https://www.airbnb.com/help/article/1857
A11: GSA per diem SF FY2026 (gobierno EE.UU.) | B11: Lodging $272 / noche; M&IE $92 / día | C11: Benchmark externo para validar topes Yuno ($220 / $90). | D11: https://www.gsa.gov/travel/plan-book/per-diem-rates/per-diem-rates-results?action=perdiems_report&city=san+Francisco&fiscal_year=2026&state=CA
A12: Café / desayuno | B12: Café $4–6 (latte $5,55); pastry/bagel $5–7 | C12: Realista desayuno $12. | D12: https://www.expatistan.com/cost-of-living/san-francisco
A13: Almuerzo casual | B13: $15–25 en menú; combo fast-food ~$12 | C13: Realista almuerzo $25 con tax + tip. | D13: https://www.worldcostofliving.com/city/san-francisco-usa
A14: Cena mid-range | B14: Plato $20–40; comida para dos $59–120; 3 tiempos ~$100 | C14: Realista cena $45. | D14: https://www.expatistan.com/cost-of-living/san-francisco
A15: Recargos en restaurantes | B15: Sales tax 8,625% + SF Mandate (health) 3–7% + tip 17–22% = ~30% sobre el menú | C15: Explica por qué el tope de $25 se alcanza con un plato de ~$19. | D15: https://www.sfchronicle.com/food/restaurants/article/surcharge-fee-san-francisco-19561318.php
... A24: Costo de vida general SF | B24: Comida 30,5% sobre promedio EE.UU. ($522/mes individual) | C24: Contexto. | D24: https://www.salary.com/research/cost-of-living/san-francisco-ca

Sheet Comparacion
A1: Política Yuno vs GSA vs mercado real de San Francisco (por día / por noche)
A2: Positivo en 'Margen' = el tope de Yuno alcanza. Negativo = el mercado supera el tope.
A4: Categoría | B4: Tope Yuno SF | C4: GSA FY2026 (benchmark) | D4: Mercado SF: rango bajo | E4: Mercado SF: rango alto | F4: Realista usado | G4: Margen tope vs realista | H4: Comentario
A5: Alojamiento por noche (tu parte, sin impuestos) | B5: 220 | C5: 272 | D5: 60.5 | E5: 186 | F5: =Supuestos!C9 | G5: =B5-F5 | H5: Compartiendo 2BR quedas a ~30% del tope. Solo (entire place mediana $186) también cabe; hotel 3* fin de semana ($332) no.
A6: Desayuno | B6: 15 | C6: 20 | D6: 8 | E6: 15 | F6: =Supuestos!C11 | G6: =B6-F6 | H6: Cabe. Café + pastry con tip ronda $12. GSA reparte $92 M&IE aprox. 20/25/40 + incidentales.
A7: Almuerzo | B7: 25 | C7: 25 | D7: 20 | E7: 33 | F7: =Supuestos!C12 | G7: =B7-F7 | H7: Justo. Con tax + mandate + tip un plato de $25 en menú sale ~$33. Apuntar a ≤$19 en menú.
A8: Cena | B8: 50 | C8: 42 | D8: 35 | E8: 55 | F8: =Supuestos!C13 | G8: =B8-F8 | H8: Cabe en mid-range. Una cena con entrada + plato + bebida en SoMa/Mission supera $50.
A9: Transporte por día | B9: 55 | C9: 5 | D9: 6 | E9: 30 | F9: =Supuestos!C14 | G9: =B9-F9 | H9: Muy holgado. GSA da $5 de incidentales; aquí Muni pass + Uber ocasional ~$15.
A10: Total por día (alojamiento + comidas + transporte) | B10: =SUM(B5:B9) | C10: =SUM(C5:C9) | D10: =SUM(D5:D9) | E10: =SUM(E5:E9) | F10: =SUM(F5:F9) | G10: =B10-F10 | H10: Tope Yuno $365/día vs GSA $364/día: alineados. Tu gasto realista ronda $160/día con el Airbnb compartido.
A13: Totales del viaje por escenario (38 días, 27 noches Airbnb + 10 en casa de Joaquín)
A14: Escenario | B14: Total viaje (con vuelo) | C14: Total sin vuelo | D14: Promedio por día sin vuelo | E14: vs tope de política
A15: Política (tope máximo) | B15: =Resumen!B26 | C15: =Resumen!B27 | D15: =Resumen!B28 | E15: =Resumen!B26-B15
A16: Realista (mercado SF) | B16: =Resumen!C26 | C16: =Resumen!C27 | D16: =Resumen!C28 | E16: =Resumen!B26-B16
A17: Ahorro | B17: =Resumen!D26 | C17: =Resumen!D27 | D17: =Resumen!D28 | E17: =Resumen!B26-B17
