Workbook

Sheet Context
B2: Business Case Template - Outreach
B4: Instructions | I4: Leyenda
B5: 1. Remember is a template, please make a copy of the document. 2. This is a tool for the Sales Team (mainly SDR team) to create a a priori business case for incluencing the prospect to have a conversation with us. 3. The main objective of this document is for us to demostrate that we can: a. Boost Revenue (higher acceptance rates, new APMs at checkout, local processing with MoR/local processors, less fraud) b. Reduce Costs (Lower MDR due to localized processing, lower MDR due to higher bargaining power with PSPs, Lower integration efforts/costs/team hours) 4. This document Should not be shared with merchants, but rather share the Google Slide doc, where all info is centralized and summarized - Business Case Template - COMPANY & Yuno | I5: Market/Region | J5: Color
I6: LATAM
I7: North America (NA)
I8: EMEA/EU
I9: APAC
B14: Business Case - Payins Tab | I14: Leyenda
B15: Business Case - Payins 1. As you need to perform a business case to compare the value of Yuno you can obtain a basic BC in the sheet "BC Pay-ins Tab". In this tab you'll need to: a. Create a per company&market. (Eg. if this document is for AIRBNB, We'll need to have a "BC Pay-Ins LATAM", "BC Pay-ins APAC"..."BC Pay-ins N"). 2. Inputs that you need to place: a. From other documents: i. Annual Revenue (brought from Worldwide Focus Accounts or external source) b. From SimilarWeb / Bloomberg / etc. i. Annual Total Visits ii. Web Traffic (Share of Wallet - SoW) c. From SDR research i. Average Ticket Value (ATV) ii. Share of Wallet (SoW) Cards - This is based on Company/Market Checkout iii. Share of Wallet (SoW) APMs - This is based on Company/Market Checkout iv. Local Entities per market v. Current APMs - This is based on Company/Market Checkout vi. APMs to Integrate - This is based on Company/Market Checkout vii. (%) Incremental Transactions - This is based on Company/Market Checkout, SoW Cards and SoW APMs viii. (%) TPV from Cards to APMs - This is based on Company/Market Checkout, SoW Cards and SoW APMs viii. APMs MDR Cost - This is linked to MDR costs research per country | I15: Apects | J15: Color
I16: Inputs SDR | J16: Blue and Yellow
I17: Similar Web / Research / Bloomberg | J17: Red
I18: Value brought from other tabs. | J18: Green
I19: Add to Business Case Template - COMPANY & Yuno | J19: *
B27: BC Devs./Engineering Integrations Savings Tab | I27: Leyenda
B28: 1. In the tab "BC Developments/Engineering Integrations Savings" you'll find further information about possible savings on developments based on prior BC Pay-ins inputs: a. Create a per company&market. (Eg. if this document is for AIRBNB, We'll need to have a "BC Devs./Engineering Integrations Savings LatAm", "BC Devs./Engineering Integrations Savings APAC"..."BC Devs./Engineering Integrations Savin N") 2. Inputs that you need to place: a. From other tabs/documents: i. Current APMs - "BC Pay-ins" tab ii. APMs to Integrate - "BC Pay-ins" tab iii. Local entity? - "BC Pay-ins" tab | I28: Apects | J28: Color
I29: Inputs SDR | J29: Blue and Yellow
I30: Similar Web / Research / Bloomberg | J30: Red
I31: Value brought from other tabs. | J31: Green
I32: Add to Business Case Template - COMPANY & Yuno | J32: *

Sheet Aceptance Rate Delta per Indust
D2: Δ acceptance rate (%) | F2: MDR (%) Local/CB per Industry | H2: Take Rate (%) per Industry | J2: Conversions | N2: Estimated monthly cost for each integration per team per region
B3: Industry | C3: AVG GM% | D3: Lower Range | E3: Higher Range | F3: Local MDR | G3: Cross-Border MDR | H3: Lower Range | I3: Higher Range | J3: VtC (%) | K3: CtS (%) | M3: Team | N3: LATAM | O3: BRAZIL | P3: US | Q3: APAC | R3: EMEA
B4: Neobanks | C4: 0.35 | D4: 0.03 | E4: 0.05 | F4: 0.018 | G4: 0.04 | H4: 0.01 | I4: 0.03 | J4: 0.2 | K4: 0.8 | M4: Product | N4: 1350 | O4: 1500 | P4: 3000 | Q4: 1800 | R4: 2400
B5: Remittance | C5: 0.05 | D5: 0.03 | E5: 0.05 | F5: 0.02 | G5: 0.055 | H5: 0.01 | I5: 0.05 | J5: 0.25 | K5: 0.85 | M5: Engineering | N5: 6300 | O5: 7000 | P5: 14000 | Q5: 8400 | R5: 11200
B6: Social/Advertising | C6: 0.6 | D6: 0.01 | E6: 0.03 | F6: 0.015 | G6: 0.035 | H6: 0.2 | I6: 0.4 | J6: 0.1 | K6: 0.7 | M6: Fraud/Risk | N6: 1350 | O6: 1500 | P6: 3000 | Q6: 1800 | R6: 2400
B7: Streaming | C7: 0.4 | D7: 0.02 | E7: 0.05 | F7: 0.018 | G7: 0.04 | H7: 0.15 | I7: 0.3 | J7: 0.15 | K7: 0.75 | M7: Treasury | N7: 810 | O7: 900 | P7: 1800 | Q7: 1080 | R7: 1440
B8: SuperApps/Delivery Apps | C8: 0.1 | D8: 0.05 | E8: 0.1 | F8: 0.025 | G8: 0.05 | H8: 0.1 | I8: 0.25 | J8: 0.18 | K8: 0.8 | M8: Compliance | N8: 900 | O8: 1000 | P8: 2000 | Q8: 1200 | R8: 1600
B9: Cinema | C9: 0.08 | D9: 0.03 | E9: 0.05 | F9: 0.017 | G9: 0.038 | H9: 0.1 | I9: 0.15 | J9: 0.22 | K9: 0.85 | M9: Finance | N9: 675 | O9: 750 | P9: 1500 | Q9: 900 | R9: 1200
B10: Ticketing | C10: 0.15 | D10: 0.03 | E10: 0.05 | F10: 0.019 | G10: 0.042 | H10: 0.1 | I10: 0.2 | J10: 0.2 | K10: 0.8 | M10: Banking & Payments | N10: 1575 | O10: 1750 | P10: 3500 | Q10: 2100 | R10: 2800
B11: Payroll | C11: 0.15 | D11: 0.01 | E11: 0.03 | F11: 0.015 | G11: 0.03 | H11: 0.005 | I11: 0.02 | J11: 0.3 | K11: 0.9
B12: PSP | C12: 0.4 | D12: 0.02 | E12: 0.05 | F12: 0.022 | G12: 0.045 | H12: 0.003 | I12: 0.015 | J12: 0.25 | K12: 0.85
B13: Telecom | C13: 0.15 | D13: 0.02 | E13: 0.04 | F13: 0.016 | G13: 0.035 | H13: 0.01 | I13: 0.03 | J13: 0.2 | K13: 0.8
B14: Adult Content | C14: 0.08 | D14: 0.03 | E14: 0.06 | F14: 0.035 | G14: 0.07 | H14: 0.2 | I14: 0.4 | J14: 0.12 | K14: 0.7
B15: Crypto | C15: 0.6 | D15: 0.02 | E15: 0.05 | F15: 0.032 | G15: 0.065 | H15: 0.001 | I15: 0.02 | J15: 0.15 | K15: 0.75
B16: Dating | C16: 0.08 | D16: 0.03 | E16: 0.06 | F16: 0.028 | G16: 0.06 | H16: 0.2 | I16: 0.3 | J16: 0.1 | K16: 0.7
B17: Gambling/Sports Betting | C17: 0.4 | D17: 0.02 | E17: 0.04 | F17: 0.035 | G17: 0.075 | H17: 0.05 | I17: 0.15 | J17: 0.18 | K17: 0.8
B18: Gaming | C18: 0.4 | D18: 0.03 | E18: 0.06 | F18: 0.028 | G18: 0.05 | H18: 0.2 | I18: 0.3 | J18: 0.2 | K18: 0.85
B19: Investing | C19: 0.6 | D19: 0.01 | E19: 0.03 | F19: 0.025 | G19: 0.05 | H19: 0.005 | I19: 0.02 | J19: 0.25 | K19: 0.9
B20: Airlines | C20: 0.05 | D20: 0.05 | E20: 0.1 | F20: 0.025 | G20: 0.055 | H20: 0.02 | I20: 0.04 | J20: 0.22 | K20: 0.85
B21: Train/bus/cruise Tickets | C21: 0.1 | D21: 0.04 | E21: 0.08 | F21: 0.02 | G21: 0.042 | H21: 0.05 | I21: 0.1 | J21: 0.2 | K21: 0.8
B22: Car Rental | C22: 0.15 | D22: 0.03 | E22: 0.06 | F22: 0.022 | G22: 0.048 | H22: 0.1 | I22: 0.15 | J22: 0.18 | K22: 0.8
... B40: Insurance | C40: 0.18 | D40: 0.02 | E40: 0.04 | F40: 0.02 | G40: 0.04 | H40: 0.05 | I40: 0.15 | J40: 0.22 | K40: 0.85

Sheet APMs
A1: Region | B1: Country | C1: APMs & Approx. Share | D1: Key Notes
A2: Latin America
B3: 🇧🇷 Brazil | C3: Visa/Mastercard/Elo (credit) ~44% | Pix ~40% | Boleto Bancário ~5% | Debit Cards ~4% | Mercado Pago, PicPay ~4% | BNPL ~2% | D3: Pix projected #1 by 2027. Elo is local scheme. Parcelamento (installments) deeply embedded.
B4: 🇲🇽 Mexico | C4: Visa/Mastercard (credit) ~35% | Debit Cards ~18% | Mercado Pago, Spin by OXXO, Rappi Pay ~15% | OXXO Pay ~12% | SPEI ~10% | Cash on Delivery ~5% | CoDi/DiMo ~3% | Kueski Pay, Aplazo ~2% | D4: OXXO Pay critical for unbanked. MSI installments standard. CoDi/DiMo slow vs Pix.
B5: 🇦🇷 Argentina | C5: Visa/Mastercard (credit) ~32% | Mercado Pago, Ualá, MODO ~25% | Debit Cards ~18% | Transferencias 3.0 / QR ~12% | Rapipago, Pago Fácil ~5% | Cash ~5% | BNPL ~3% | D5: Cuotas (installments) essential due to inflation. MODO enables QR interoperability.
B6: 🇨🇴 Colombia | C6: Visa/Mastercard (credit) ~30% | PSE ~28% | Nequi, Daviplata ~15% | Debit Cards ~12% | Efecty, Baloto ~8% | Cash ~5% | Addi, Sistecrédito ~2% | D6: PSE growing fast, could match cards by 2026. Nequi (Bancolombia) dominant.
B7: 🇵🇪 Peru | C7: Yape, Plin ~35% | Visa/Mastercard (credit) ~18% | PagoEfectivo, SafetyPay ~12% | Debit Cards ~12% | Bank Transfer ~10% | Cash ~8% | BNPL ~2% | D7: Yape (BCP) is #1. Central bank mandated Yape/Plin interoperability.
B8: 🇵🇾 Paraguay | C8: Cash ~35% | Visa/Mastercard (credit) ~20% | Debit Cards ~15% | Tigo Money, Personal Pay ~15% | SIPAP ~10% | Aquí Pago ~5% | D8: Low banking penetration. Telco-led mobile money dominates.
B9: 🇺🇾 Uruguay | C9: Debit Cards ~30% | Visa/Mastercard/OCA (credit) ~25% | Bank Transfer ~15% | Prex, Midinero ~12% | Cash ~10% | Abitab, RedPagos ~5% | BNPL ~3% | D9: OCA is dominant local card. Govt pushed debit via VAT discounts.
A11: North America
B12: 🇺🇸 USA | C12: Visa/Mastercard/Amex/Discover (credit) ~32% | PayPal ~15% | Apple Pay, Google Pay ~12% | Debit Cards ~20% | Affirm, Klarna, Afterpay ~5% | ACH ~5% | Venmo, Cash App ~4% | Amazon Pay ~3% | D12: PayPal ~15% of e-com. Apple Pay fastest growing. Rewards culture drives credit.
B13: 🇨🇦 Canada | C13: Visa/Mastercard/Amex (credit) ~35% | PayPal ~12% | Apple Pay, Google Pay ~10% | Interac (debit) ~20% | Interac e-Transfer ~8% | Klarna, PayBright ~5% | Bank Transfer ~5% | Amazon Pay ~3% | D13: Interac dominant local debit + e-Transfer for A2A.
A15: Europe
B16: 🇵🇹 Portugal | C16: MB Way, Multibanco ~40% | Visa/Mastercard (credit) ~25% | Debit Cards ~12% | PayPal ~10% | SEPA Transfer ~5% | Apple Pay, Google Pay ~4% | Klarna ~2% | D16: MB Way is national standard. Very high local payment adoption.
B17: 🇪🇸 Spain | C17: Visa/Mastercard ~35% | Bizum ~15% | PayPal ~15% | Apple Pay, Google Pay ~8% | SEPA Transfer ~7% | Klarna, Sequra ~5% | Cash (Contrareembolso) ~3% | Wero ~2% | D17: Bizum: 20M+ users, launching NFC POS 2025. Sequra is local BNPL leader.
B18: 🇫🇷 France | C18: Carte Bancaire (CB) ~35% | Visa/Mastercard ~18% | PayPal ~12% | Apple Pay, Google Pay ~8% | Paylib → Wero ~6% | SEPA Transfer ~5% | Alma, Floa, Klarna ~5% | D18: Carte Bancaire is national scheme. Alma is local BNPL leader. Paylib migrating to Wero.
B19: 🇩🇪 Germany | C19: PayPal ~28% | Kauf auf Rechnung (invoice) ~18% | Visa/Mastercard/Girocard ~15% | SEPA Lastschrift ~12% | Sofort (Klarna) ~8% | Klarna BNPL ~5% | Giropay ~4% | Apple Pay, Google Pay ~4% | Amazon Pay ~4% | Wero ~2% | D19: PayPal #1 — unique in Europe. Invoice deeply cultural. 82% abandon without preferred method.
B20: 🇬🇧 United Kingdom | C20: Visa/Mastercard (debit) ~38% | Visa/Mastercard (credit) ~20% | PayPal ~15% | Apple Pay, Google Pay ~10% | Open Banking ~5% | Klarna, Clearpay ~5% | BACS Direct Debit ~4% | Amazon Pay ~3% | D20: 57% use mobile wallets. 25% used BNPL in 2024. Open Banking: 31M payments March 2025.
B21: 🇳🇱 Netherlands | C21: iDEAL ~70% | Visa/Mastercard ~10% | PayPal ~5% | Klarna, Riverty ~5% | Bancontact ~3% | Apple Pay, Google Pay ~3% | SEPA Direct Debit ~2% | Wero / iDEAL 2.0 ~2% | D21: iDEAL: 1.3B txns/year, €100B+ volume. Migrating into Wero.
B22: 🇧🇪 Belgium | C22: Bancontact ~55% | Visa/Mastercard ~15% | PayPal ~10% | Payconiq → Wero ~5% | SEPA Transfer ~5% | Apple Pay, Google Pay ~4% | iDEAL ~3% | Klarna ~3% | D22: Bancontact dominant. Payconiq transitioning to Wero.
B23: 🇨🇭 Switzerland | C23: Visa/Mastercard (credit) ~30% | TWINT ~25% | Debit Cards ~12% | PayPal ~10% | Rechnung (invoice) ~10% | Apple Pay, Google Pay ~5% | SEPA Transfer ~3% | Klarna ~3% | PostFinance ~2% | D23: TWINT is national mobile app. Invoice culture like Germany.
B24: 🇸🇪 Sweden | C24: Swish ~30% | Visa/Mastercard ~25% | Klarna ~20% | PayPal ~8% | Apple Pay, Google Pay ~7% | Autogiro ~5% | Bank Transfer ~3% | Trustly ~2% | D24: Swish: 8.5M users (85% pop). Klarna born here. Trustly pioneered open banking.
B25: 🇮🇹 Italy | C25: Visa/Mastercard/PostePay ~35% | PayPal ~20% | Apple Pay, Satispay ~10% | MyBank ~10% | Cash (Contrassegno) ~8% | Scalapay, Klarna ~5% | SEPA Direct Debit ~5% | Bancomat Pay ~4% | Wero ~1% | D25: PostePay (prepaid) very popular. Satispay is local mobile payment.
B26: 🇷🇺 Russia | C26: Mir ~40% | SBP ~25% | YooMoney, QIWI ~15% | SberPay ~10% | Bank Transfer ~5% | Cash ~3% | Tinkoff Pay ~2% | D26: Mir replaced Visa/MC post-sanctions. SBP is central bank instant. Isolated ecosystem.
B27: 🇺🇦 Ukraine | C27: Visa/Mastercard ~45% | Privat24, Monobank ~20% | Apple Pay, Google Pay ~12% | Cash ~10% | Bank Transfer ~8% | SEP (instant) ~3% | BNPL ~2% | D27: Privat24 dominant. Monobank growing fast. War accelerated digital adoption.
... B35: 🇮🇪 Ireland | C35: Visa/Mastercard (Debit) ~45% | Credit Cards ~15% | PayPal ~12% | Apple Pay, Google Pay ~10% | Revolut ~8% | Bank Transfer (SEPA) ~5% | BNPL (Klarna) ~3% | Cash ~2% | D35: Visa-dominant market (80%+ card share). Revolut has 3M+ users (60% of pop). Contactless 87% of POS. Cash dropped from 38% (2019) to ~15% at POS. Strong SEPA/open banking growth.
A37: Middle East
B38: 🇶🇦 Qatar | C38: Visa/Mastercard ~40% | Apple Pay, Samsung Pay ~20% | Cash ~15% | NAPS ~10% | Tabby, Tamara ~5% | Bank Transfer ~5% | QR Payments ~3% | PayPal ~2% | D38: High card penetration in GCC. NAPS is national payment system.
B39: 🇦🇪 UAE | C39: Visa/Mastercard/Amex (credit) ~35% | Apple Pay, Samsung Pay, Google Pay ~25% | Debit Cards ~12% | Cash ~10% | Tabby, Tamara, Postpay ~8% | Bank Transfer ~5% | Careem Pay ~3% | PayPal ~2% | D39: Wallets projected 42% by 2027. Tabby & Tamara: 10M users each.
B40: 🇸🇦 Saudi Arabia | C40: MADA ~35% | Apple Pay, STC Pay ~22% | Visa/Mastercard (credit) ~15% | Cash ~10% | Tabby, Tamara, Madfu ~8% | SADAD ~5% | SARIE ~3% | Samsung Pay, Google Pay ~2% | D40: MADA: 93% domestic card share. Vision 2030 targets 70% cashless.
B41: 🇵🇰 Pakistan | C41: Cash ~40% | JazzCash, Easypaisa ~25% | RAAST ~12% | Debit Cards ~10% | Visa/Mastercard (credit) ~5% | NayaPay, SadaPay ~5% | Agent Banking ~3% | D41: JazzCash & Easypaisa: 40M+ users. RAAST instant growing rapidly.
B42: 🇧🇭 Bahrain | C42: Visa/Mastercard ~35% | BenefitPay, Fawri+ ~25% | Apple Pay ~15% | Cash ~10% | Tabby, Tamara ~5% | Bank Transfer ~5% | SADAD ~5% | D42: World leader in RTP consumer adoption. 60% electronic via Fawri+.
B43: 🇰🇼 Kuwait | C43: Visa/Mastercard/KNET ~45% | Apple Pay, Samsung Pay ~20% | Cash ~15% | Bank Transfer ~8% | Tabby, Tamara ~7% | KNET Pay ~5% | D43: KNET dominant local network.
B44: 🇴🇲 Oman | C44: Visa/Mastercard ~35% | Cash ~25% | Apple Pay ~12% | OmanNet ~10% | Thawani ~8% | Tabby ~5% | Islamic Banking ~5% | D44: Thawani is local platform. Sharia-compliant options important.
B45: 🇯🇴 Jordan | C45: Cash ~30% | Visa/Mastercard ~30% | eFAWATEERcom ~12% | Zain Cash, Orange Money ~10% | CliQ ~8% | PayPal ~5% | Apple Pay ~3% | BNPL ~2% | D45: eFAWATEERcom national bill payment. CliQ is central bank instant.
B46: 🇮🇱 Israel | C46: Visa/Mastercard/Isracard ~45% | Bit ~15% | PayPal ~10% | Apple Pay, Google Pay ~10% | Debit Cards ~8% | Bank Transfer ~5% | BNPL ~5% | PayBox ~2% | D46: Isracard dominant. Bit leading mobile payment. BNPL growing 36% annually.
A48: Africa
B49: 🇿🇦 South Africa | C49: Visa/Mastercard ~35% | Ozow, Stitch (Instant EFT) ~25% | Apple Pay, SnapScan ~12% | Cash ~10% | PayPal ~5% | PayJustNow, Payflex ~5% | Capitec Pay ~5% | Zapper ~3% | D49: Instant EFT dominant for e-com. Capitec banking app growing fast.
B50: 🇲🇦 Morocco | C50: Cash ~40% | CMI/Visa/Mastercard ~25% | Bank Transfer ~10% | M-Wallet, inwi money ~10% | Apple Pay ~5% | PayPal ~5% | Maroc Telecommerce ~3% | BNPL ~2% | D50: CMI is local interbank center. Apple Pay recently launched.
B51: 🇪🇬 Egypt | C51: Cash ~40% | Fawry, Vodafone Cash ~20% | Visa/Mastercard/Meeza ~20% | InstaPay ~8% | Bank Transfer ~5% | ValU, Shahry ~4% | PayPal ~3% | D51: Fawry: 35M+ users. Meeza national card. InstaPay is CBE instant platform.
...

Sheet RESUMEN
B1: ID GOOGLE SHEETS | C1: 1TRy3fAUDaErkQpDapQym9qGf4fMsS0IU4Xd9sa9BRHQ | D1: *The ID of this document - find it in the URL. It is the alphanumeric combination between d/ & /edit.
B2: ID GOOGLE SLIDES | C2: 16Olp5AT392u3bWuFRpx4iEvjqmIN1MVTXt_iwJZhJN0 | D2: *The ID of the Google Slides that will be linked to this BC - find it in the URL. It is the alphanumeric combination between d/ & /edit.
B3: Company | C3: Bumble | D3: *Company name
B4: Industry | C4: Dating | D4: *Company Industry
B5: TPV Acceptance Rate Uplift - Total | C5: ='BC Pay-ins LatAm'!H19+' BC Pay-ins NA'!H19+'BC Pay-ins APAC'!H19+'BC Pay-ins EMEA'!H19 -> 34.993347 | D5: =ROUNDDOWN(C5-1,0) -> 33 | E5: =ROUNDUP(C5+2,0) -> 37 | F5: *Gotten automatically from formulas | G5: PROBLEM 1 | H5: Dependencies on a single provider
B6: Fee Renegociation - Total | C6: ='BC Pay-ins LatAm'!H27+'BC Pay-ins LatAm'!H47+' BC Pay-ins NA'!H27+' BC Pay-ins NA'!H47+'BC Pay-ins APAC'!H27+'BC Pay-ins APAC'!H47+'BC Pay-ins EMEA'!H27+'BC Pay-ins EMEA'!H47 -> 7.0255396 | D6: =ROUNDDOWN(C6-1,0) -> 6 | E6: =ROUNDUP(C6+2,0) -> 10 | F6: *Gotten automatically from formulas | G6: PROBLEM 2 | H6: No fallbacks or smart routing
B7: New APM TPV Growth - Total | C7: ='BC Pay-ins LatAm'!H37+' BC Pay-ins NA'!H37+'BC Pay-ins APAC'!H37+'BC Pay-ins EMEA'!H37 -> 90.27132 | D7: =ROUNDDOWN(C7-1,0) -> 89 | E7: =ROUNDUP(C7+2,0) -> 93 | F7: *Gotten automatically from formulas | G7: PROBLEM 3 | H7: High transactional costs
B8: Engineering Cost Savings - total | C8: =(Sheet5!H41+Sheet6!H41+Sheet7!H41+'BC Devs.Eng. Integrations Savin'!H41) -> 5.4216 | D8: =ROUNDDOWN(C8-1,0) -> 4 | E8: =ROUNDUP(C8+2,0) -> 8 | F8: *Gotten automatically from formulas | G8: PROBLEM 4 | H8: Need of alternative payment methods (APMs) that can help increase sales
B9: Total Benefit | C9: =SUM(C5:C8) -> 137.71181 | D9: =ROUNDDOWN(C9-1,0) -> 136 | E9: =ROUNDUP(C9+2,0) -> 140 | F9: *Gotten automatically from formulas | G9: PROBLEM 5 | H9: Fear of reconciliation issues when using multiple payment providers; with us, everything is reconciled in one place
B10: Sdr Name | C10: Germán Tatis
B11: CORREO | C11: german.tatis@y.uno | D11: *SDR mail of who is sending the BC
B12: Key Inputs
B13: Annual Total Visits (Similar Web) | C13: 600000000 | D13: *Take the total annual visits from similarweb based on company domain
B14: Annual Revenue | C14: 1071600000 | D14: *This it gotten from CHATGPT Deep research/public Financial Reports. Very important as it is a point of reference for us to have better/conservative outputs.
B15: Take Rate | C15: 0.6 | D15: *Gotten automatically from other tabs
B16: Total Processed Value | C16: =C14/C15 -> 1786000000 | D16: =C16/1000000 -> 1786 | E16: *Gotten automatically from formulas
D17: ='BC Pay-ins LatAm'!H11+' BC Pay-ins NA'!H11+'BC Pay-ins EMEA'!H11+'BC Pay-ins APAC'!H11 -> 962.934
B18: Blue and Yellow | C18: Inputs SDR | D18: ='BC Pay-ins LatAm'!H4+' BC Pay-ins NA'!H4+'BC Pay-ins EMEA'!H4+'BC Pay-ins APAC'!H4 -> 0.728
B19: Red | C19: Similar Web / Research / Bloomberg | D19: =C16*D18 -> 1300208000
B20: Green | C20: Values brought from other tables/formulas
B21: * | C21: Send to presentation
C22: =(Sheet5!K42+Sheet6!K42+Sheet7!K42+'BC Devs.Eng. Integrations Savin'!K42) -> 20.25
B23: Amount of years | C23: =CONCATENATE(ROUNDUP(C22,2)," ","years") -> 20.25 years | D23: =ROUNDDOWN(C24-1,0) -> 19 | E23: =ROUNDUP(C24+1,0) -> 22 | F23: *Gotten automatically from other tabs
C24: =ROUNDUP(C22,2) -> 20.25
B29: a | C29: =C5 -> 34.993347
B30: b | C30: =C7 -> 90.27132
B31: c | C31: ='BC Pay-ins LatAm'!D37+'BC Pay-ins LatAm'!D56+' BC Pay-ins NA'!D37+' BC Pay-ins NA'!D56+'BC Pay-ins EMEA'!D37+'BC Pay-ins EMEA'!D56+'BC Pay-ins APAC'!D37+'BC Pay-ins APAC'!D56 -> 16.04292
B32: d | C32: =C6 -> 7.0255396
B33: e | C33: =sum('BC Pay-ins LatAm'!C34:G34)+SUM(' BC Pay-ins NA'!C34:G34)+SUM('BC Pay-ins EMEA'!C34:G34)+SUM('BC Pay-ins APAC'!C34:G34) -> 53
B34: f | C34: =C8 -> 5.4216
B35: g | C35: =C23 -> 20.25 years

Sheet BC Pay-ins LatAm
C2: TOP COUNTRIES AT REGION
B3: Aspect/Country | C3: Mexico | D3: Brazil | E3: Argentina | F3: Colombia | G3: Peru | H3: Total | J3: Range A | K3: Range A | M3: Explanation
B4: Web Traffic (SoW) | C4: 0.0455 | D4: 0.0295 | E4: 0.0278 | F4: 0.0252 | G4: 0.0159 | H4: =SUM(C4:G4) -> 0.1439 | M4: *This is coming from Similarweb: is the share (%) of web traffic visits per market.
B5: Web Traffic Visits | C5: =C4*RESUMEN!$C$13 -> 27300000 | D5: =D4*RESUMEN!$C$13 -> 17700000 | E5: =E4*RESUMEN!$C$13 -> 16680000 | F5: =F4*RESUMEN!$C$13 -> 15120000 | G5: =G4*RESUMEN!$C$13 -> 9540000
B6: Conversion | C6: 0.1 | D6: 0.1 | E6: 0.1 | F6: 0.1 | G6: 0.1
B7: View to Checkout | C7: =VLOOKUP(RESUMEN!$C$4,'Aceptance Rate Delta per Indust'!$B$3:$K$40,9,false) -> 0.1 | D7: =VLOOKUP(RESUMEN!$C$4,'Aceptance Rate Delta per Indust'!$B$3:$K$40,9,false) -> 0.1 | E7: =VLOOKUP(RESUMEN!$C$4,'Aceptance Rate Delta per Indust'!$B$3:$K$40,9,false) -> 0.1 | F7: =VLOOKUP(RESUMEN!$C$4,'Aceptance Rate Delta per Indust'!$B$3:$K$40,9,false) -> 0.1 | G7: =VLOOKUP(RESUMEN!$C$4,'Aceptance Rate Delta per Indust'!$B$3:$K$40,9,false) -> 0.1
B8: Checkout Succesfull | C8: =VLOOKUP(RESUMEN!$C$4,'Aceptance Rate Delta per Indust'!$B$3:$K$40,10,false) -> 0.7 | D8: =VLOOKUP(RESUMEN!$C$4,'Aceptance Rate Delta per Indust'!$B$3:$K$40,10,false) -> 0.7 | E8: =VLOOKUP(RESUMEN!$C$4,'Aceptance Rate Delta per Indust'!$B$3:$K$40,10,false) -> 0.7 | F8: =VLOOKUP(RESUMEN!$C$4,'Aceptance Rate Delta per Indust'!$B$3:$K$40,10,false) -> 0.7 | G8: =VLOOKUP(RESUMEN!$C$4,'Aceptance Rate Delta per Indust'!$B$3:$K$40,10,false) -> 0.7
B9: Succesful Transactions (x Year) | C9: =(ROUND(C5*C6,0)) -> 2730000 | D9: =(ROUND(D5*D6,0)) -> 1770000 | E9: =(ROUND(E5*E6,0)) -> 1668000 | F9: =(ROUND(F5*F6,0)) -> 1512000 | G9: =(ROUND(G5*G6,0)) -> 954000
B10: ATV | C10: 20 | D10: 20 | E10: 20 | F10: 20 | G10: 20 | M10: *Average Ticket Value. You can get this from Chagpt - be aware that in some cases ATV con change per market, as some markets are more expensive than others.
B11: TPV (x Year) | C11: =(RESUMEN!$C$13*C4*C6*C10)/1000000 -> 54.6 | D11: =(RESUMEN!$C$13*D4*D6*D10)/1000000 -> 35.4 | E11: =(RESUMEN!$C$13*E4*E6*E10)/1000000 -> 33.36 | F11: =(RESUMEN!$C$13*F4*F6*F10)/1000000 -> 30.24 | G11: =(RESUMEN!$C$13*G4*G6*G10)/1000000 -> 19.08 | H11: =SUM(C11:G11) -> 172.68
B12: SoW Cards (%) | C12: 1 | D12: 1 | E12: 1 | F12: 1 | G12: 1 | M12: *Take into consideration which APMs the merchant has/lack in the checkout of each market, and the relevance of the APMs they have/lack. If the merchant does not have any APM available, then the SoW cards would be 100%.
B13: TPV Cards (x Year) | C13: =(C12*C11) -> 54.6 | D13: =(D12*D11) -> 35.4 | E13: =(E12*E11) -> 33.36 | F13: =(F12*F11) -> 30.24 | G13: =G12*G11 -> 19.08 | H13: =SUM(C13:G13) -> 172.68 | M13: *Millions/year
B14: SoW APMs (%) | C14: =1-C12 -> 0 | D14: =1-D12 -> 0 | E14: =1-E12 -> 0 | F14: =1-F12 -> 0 | G14: =1-G12 -> 0 | M14: *SoW APMs is automatically calculated when inputing the SoW cards.
B15: TPV APMs (x Year) | C15: =C14*C11 -> 0 | D15: =D14*D11 -> 0 | E15: =E14*E11 -> 0 | F15: =F14*F11 -> 0 | G15: =G14*G11 -> 0
B17: Cards
B18: Δ Acceptance rate (%) | C18: 0.05 | D18: 0.05 | E18: 0.05 | F18: 0.05 | G18: 0.05 | H18: *
B19: Incremental TPV | C19: =C13*C18 -> 2.73 | D19: =D13*D18 -> 1.77 | E19: =E13*E18 -> 1.668 | F19: =F13*F18 -> 1.512 | G19: =G13*G18 -> 0.954 | H19: =SUM(C19:G19) -> 8.634 | J19: =rounddown(H19-1,0) -> 7 | K19: =ROUNDUP(H19-1,0)+1 -> 9 | M19: *Millions/year
B20: Incremental Revenue | C20: =C19*RESUMEN!$C$15 -> 1.638 | D20: =D19*RESUMEN!$C$15 -> 1.062 | E20: =E19*RESUMEN!$C$15 -> 1.0008 | F20: =F19*RESUMEN!$C$15 -> 0.9072 | G20: =G19*RESUMEN!$C$15 -> 0.5724 | H20: =SUM(C20:G20) -> 5.1804 | J20: =rounddown(H20-1,0) -> 4 | K20: =ROUNDUP(H20-1,0)+1 -> 6 | M20: *Millions/year
B22: Annual Cards TPV/Country | C22: =C$11*C12+C19 -> 57.33 | D22: =D$11*D12+D19 -> 37.17 | E22: =E$11*E12+E19 -> 35.028 | F22: =F$11*F12+F19 -> 31.752 | G22: =G$11*G12+G19 -> 20.034
B23: Local entity? | C23: no | D23: no | E23: no | F23: no | G23: no | M23: *You need to research if they do or if they dont have a local entity in each of the markets. By doing this, we could get to the assumption of what XB/Local MDR they are paying, and how much could help them reduce MDR fees.
B24: Current MDR based on Local Entity | C24: =if(C23="Yes",VLOOKUP(RESUMEN!$C$4,'Aceptance Rate Delta per Indust'!$B$3:$G$40,5,FALSE),VLOOKUP(RESUMEN!$C$4,'Aceptance Rate Delta per Indust'!$B$3:$G$40,6,FALSE)) -> 0.06 | D24: =if(D23="Yes",VLOOKUP(RESUMEN!$C$4,'Aceptance Rate Delta per Indust'!$B$3:$G$40,5,FALSE),VLOOKUP(RESUMEN!$C$4,'Aceptance Rate Delta per Indust'!$B$3:$G$40,6,FALSE)) -> 0.06 | E24: =if(E23="Yes",VLOOKUP(RESUMEN!$C$4,'Aceptance Rate Delta per Indust'!$B$3:$G$40,5,FALSE),VLOOKUP(RESUMEN!$C$4,'Aceptance Rate Delta per Indust'!$B$3:$G$40,6,FALSE)) -> 0.06 | F24: =if(F23="Yes",VLOOKUP(RESUMEN!$C$4,'Aceptance Rate Delta per Indust'!$B$3:$G$40,5,FALSE),VLOOKUP(RESUMEN!$C$4,'Aceptance Rate Delta per Indust'!$B$3:$G$40,6,FALSE)) -> 0.06 | G24: =if(G23="Yes",VLOOKUP(RESUMEN!$C$4,'Aceptance Rate Delta per Indust'!$B$3:$G$40,5,FALSE),VLOOKUP(RESUMEN!$C$4,'Aceptance Rate Delta per Indust'!$B$3:$G$40,6,FALSE)) -> 0.06 | M24: *If they have a local entity, we will assume that they are paying local MDR fees - if they don't have a local entity, we assume they are processing under Cross Border fees.
B25: Reduction in MDR | C25: =IFS(C23="Yes",-0.2%,C23="No",-1%) -> -0.01 | D25: =IFS(D23="Yes",-0.2%,D23="No",-1%) -> -0.01 | E25: =IFS(E23="Yes",-0.2%,E23="No",-1%) -> -0.01 | F25: =IFS(F23="Yes",-0.2%,F23="No",-1%) -> -0.01 | G25: =IFS(G23="Yes",-0.2%,G23="No",-1%) -> -0.01 | M25: *If they have local entity, we assume that maybe we can reduce their MDR fee in 0.2% due to local gateway/aggregators introductions. If they dont have local entity, we assume that we are going help them to move from Cross Border Fees to MoR fees.
B26: New MDR | C26: =C24+C25 -> 0.05 | D26: =D24+D25 -> 0.05 | E26: =E24+E25 -> 0.05 | F26: =F24+F25 -> 0.05 | G26: =G24+G25 -> 0.05
B27: MDR Reduction | C27: =C25*C22*-1 -> 0.5733 | D27: =D25*D22*-1 -> 0.3717 | E27: =E25*E22*-1 -> 0.35028 | F27: =F25*F22*-1 -> 0.31752 | G27: =G25*G22*-1 -> 0.20034 | H27: =SUM(C27:G27) -> 1.81314 | I27: * | J27: =rounddown(H27-1,0) -> 0 | K27: =ROUNDUP(H27-1,0)+1 -> 2 | M27: *Millions/year
B29: Cards Benefit (revenue) | C29: =C27+C20 -> 2.2113 | D29: =D27+D20 -> 1.4337 | E29: =E27+E20 -> 1.35108 | F29: =F27+F20 -> 1.22472 | G29: =G27+G20 -> 0.77274 | H29: =SUM(C29:G29) -> 6.99354 | J29: * | M29: *This is the sum of the incremental revenue generated when increasing acceptance rate, and the MDR reduction generated when working with Yuno.
B31: APMs | C31: OXXO, SPEI, Apple Pay, Google Pay, PayPal | D31: PIX, NuPay, Boleto, Elo, PicPay | E31: Mercado Pago, MODO, Rapipago | F31: PSE, Nequi, Efecty, Daviplata | G31: Yape, PagoEfectivo, PLIN | M31: *Which APMs is the merchant laking of in each of the markets?
B32: Annual APMs TPV/Country | C32: =C11*C14 -> 0 | D32: =D11*D14 -> 0 | E32: =E11*E14 -> 0 | F32: =F11*F14 -> 0 | G32: =G11*G14 -> 0
B33: Current APMs | C33: 0 | D33: 0 | E33: 0 | F33: 0 | G33: 0 | M33: *How many APMs does the merchant has at checkout in each of the markets
B34: APMs to Integrate | C34: 5 | D34: 5 | E34: 3 | F34: 4 | G34: 0 | M34: *How many APMs could the merchat enable through our API? (AKA. Which crucial APMs are they lacking of in each of the markets?
B36: (%) Incremental Transactions | C36: 0.15 | D36: 0.18 | E36: 0.1 | F36: 0.12 | G36: 0.14 | M36: *This is the % of new transactios coming through when enabling those new APMs. We need to be conservative here: - If we are offering relevant/crucial APMs: 8% - 12% (eg. PIX in Brazil, UPI in India, PayPal in UK) - If we are offering not that much relevant APMs in the market: 2% - 4% (eg. Boleto in Brazil, Dale in Colombia).
B37: APMs Incremental TPV | C37: =((1+C35)+(1+C36)-1)*C11-C11 -> 8.19 | D37: =((1+D35)+(1+D36)-1)*D11-D11 -> 6.372 | E37: =((1+E35)+(1+E36)-1)*E11-E11 -> 3.336 | F37: =((1+F35)+(1+F36)-1)*F11-F11 -> 3.6288 | G37: =((1+G35)+(1+G36)-1)*G11-G11 -> 2.6712 | H37: =SUM(C37:G37) -> 24.198 | J37: =rounddown(H37-1,0) -> 23 | K37: =ROUNDUP(H37-1,0)+1 -> 25 | M37: *Millions/year
B39: APMs Incremental Revenue | C39: =C37*RESUMEN!$C$15 -> 4.914 | D39: =D37*RESUMEN!$C$15 -> 3.8232 | E39: =E37*RESUMEN!$C$15 -> 2.0016 | F39: =F37*RESUMEN!$C$15 -> 2.17728 | G39: =G37*RESUMEN!$C$15 -> 1.60272 | H39: =SUM(C39:G39) -> 14.5188 | J39: =rounddown(H39-1,0) -> 13 | K39: =ROUNDUP(H39-1,0)+1 -> 15 | M39: *Millions/year
B41: (%) TPV from Cards to APMs | C41: 0.06 | D41: 0.08 | E41: 0.05 | F41: 0.05 | G41: 0.06 | M41: *This is the % of card transactions shifted to APMs transactions thanks of them being enabled. We need to be conservative here: - If we are offering relevant/crucial APMs: 4% - 5% (eg. PIX in Brazil, UPI in India, PayPal in UK) - If we are offering not that much relevant APMs in the market: 1% - 2.5% (eg. Boleto in Brazil, Dale in Colombia).
B42: APMs Shifted TPV | C42: =C41*C11 -> 3.276 | D42: =D41*D11 -> 2.832 | E42: =E41*E11 -> 1.668 | F42: =F41*F11 -> 1.512 | G42: =G41*G11 -> 1.1448
B44: Cards MDR | C44: =C24 -> 0.06 | D44: =D24 -> 0.06 | E44: =E24 -> 0.06 | F44: =F24 -> 0.06 | G44: =G24 -> 0.06
B45: APMs MDR Cost | C45: 0.012 | D45: 0.012 | E45: 0.012 | F45: 0.012 | G45: 0.012
B47: APM MDR Savings | C47: =(C42+C37)*(C44-C45) -> 0.550368 | D47: =(D42+D37)*(D44-D45) -> 0.441792 | E47: =(E42+E37)*(E44-E45) -> 0.240192 | F47: =(F42+F37)*(F44-F45) -> 0.2467584 | G47: =(G42+G37)*(G44-G45) -> 0.183168 | H47: =SUM(C47:G47) -> 1.6622784 | J47: =if(H47>1,ROUNDUP(H47-1,0),H47) -> 1 | K47: =if(H47>1,ROUNDUP(H47-1,0),H47)+2 -> 3 | M47: *Millions/year
B49: APMs Benefit | C49: =C47+C39 -> 5.464368 | D49: =D47+D39 -> 4.264992 | E49: =E47+E39 -> 2.241792 | F49: =F47+F39 -> 2.4240384 | G49: =G47+G39 -> 1.785888 | H49: =SUM(C49:G49) -> 16.181078 | M49: *This is the sum of the incremental revenue generated when including new APMs, and the MDR savings thanks to transactions going through APMs rather than cards.

Sheet BC Devs.Eng. Integrations Savin
F2: Dev Engineering Cost Reduction
B3: Region | C3: LATAM | E3: Aspect/Country | F3: ='BC Pay-ins LatAm'!C3 -> Mexico | G3: ='BC Pay-ins LatAm'!D3 -> Brazil | H3: ='BC Pay-ins LatAm'!E3 -> Argentina | I3: ='BC Pay-ins LatAm'!F3 -> Colombia | J3: ='BC Pay-ins LatAm'!G3 -> Peru | K3: Cost Per integration/Month | L3: Total Cost Per Integration | M3: Total Cost for all Integrations
B4: Company | C4: =RESUMEN!$C$3 -> Bumble | E4: APMs | P4: AGREGAR: 1. COSTO DE MANTENER LAS CONEXIONES POR AÑO - EJ: 80H/AÑO - HACIENDO ACTUALZIACIONES. 2. COSTO TIME TO MARKET
B5: Industry | C5: =RESUMEN!$C$4 -> Dating | E5: Current APMs | F5: ='BC Pay-ins LatAm'!C33 -> 0 | G5: ='BC Pay-ins LatAm'!D33 -> 0 | H5: ='BC Pay-ins LatAm'!E33 -> 0 | I5: ='BC Pay-ins LatAm'!F33 -> 0 | J5: ='BC Pay-ins LatAm'!G33 -> 0 | L5: =SUM(F5:J5) -> 0
E6: APMs to Integrate | F6: ='BC Pay-ins LatAm'!C34 -> 5 | G6: ='BC Pay-ins LatAm'!D34 -> 5 | H6: ='BC Pay-ins LatAm'!E34 -> 3 | I6: ='BC Pay-ins LatAm'!F34 -> 4 | J6: ='BC Pay-ins LatAm'!G34 -> 0 | L6: =SUM(F6:J6) -> 17
E7: Time to integrate +1 APM (Months) | F7: =$C$11 -> 3 | G7: =$C$11 -> 3 | H7: =$C$11 -> 3 | I7: =$C$11 -> 3 | J7: =$C$11 -> 3 | L7: 3
E8: Total time of integration (Months) | F8: =F7*F6 -> 15 | G8: =G7*G6 -> 15 | H8: =H7*H6 -> 9 | I8: =I7*I6 -> 12 | J8: =J7*J6 -> 0 | L8: =SUM(F8:J8) -> 51
B9: Key Inputs | E9: Cost per month to integrate +1 APM /month | K9: =SUM(K10:K16) -> 21600 | M9: =SUM(M10:M16) -> 1101600 | N9: *
B10: Time to integrate | C10: Months | E10: Product | F10: - | G10: - | H10: - | I10: - | J10: - | K10: 2250 | L10: =$K$10*$L$7 -> 6750 | M10: =L10*$L$6 -> 114750
B11: APMs | C11: 3 | E11: Engineering | F11: - | G11: - | H11: - | I11: - | J11: - | K11: 10500 | L11: =$K$11*$L$7 -> 31500 | M11: =L11*$L$6 -> 535500
B12: Cards | C12: 4 | E12: Fraud/Risk | F12: - | G12: - | H12: - | I12: - | J12: - | K12: 2250 | L12: =$K$12*$L$7 -> 6750 | M12: =L12*$L$6 -> 114750
E13: Treasury | F13: - | G13: - | H13: - | I13: - | J13: - | K13: 1350 | L13: =$K$13*$L$7 -> 4050 | M13: =L13*$L$6 -> 68850
B14: Blue and Yellow | C14: Inputs SDR | E14: Compliance | F14: - | G14: - | H14: - | I14: - | J14: - | K14: 1500 | L14: =$K$14*$L$7 -> 4500 | M14: =L14*$L$6 -> 76500
B15: Red | C15: Similar Web / Research / Bloomberg | E15: Finance | F15: - | G15: - | H15: - | I15: - | J15: - | K15: 1125 | L15: =$K$15*$L$7 -> 3375 | M15: =L15*$L$6 -> 57375
B16: Green | C16: Formulas de reglas establecidas en otras hojas | E16: Banking & Payments | F16: - | G16: - | H16: - | I16: - | J16: - | K16: 2625 | L16: =$K$16*$L$7 -> 7875 | M16: =L16*$L$6 -> 133875
B17: * | C17: Send to presentation
E18: Cards
E19: Local entity? | F19: ='BC Pay-ins LatAm'!$C$23 -> no | G19: ='BC Pay-ins LatAm'!$D$23 -> no | H19: ='BC Pay-ins LatAm'!$E$23 -> no | I19: ='BC Pay-ins LatAm'!$F$23 -> no | J19: ='BC Pay-ins LatAm'!$G$23 -> no
E20: Need MoR/Local Processing Integration? | F20: =if(F19="Yes","No","Yes") -> Yes | G20: =if(G19="Yes","No","Yes") -> Yes | H20: =if(H19="Yes","No","Yes") -> Yes | I20: =if(I19="Yes","No","Yes") -> Yes | J20: =if(J19="Yes","No","Yes") -> Yes
E21: MoR/Local Processor to Integrate | F21: =if(F19="yes",1,2) -> 2 | G21: =if(G19="yes",1,2) -> 2 | H21: =if(H19="yes",1,2) -> 2 | I21: =if(I19="yes",1,2) -> 2 | J21: =if(J19="yes",1,2) -> 2 | L21: =SUM(F21:J21) -> 10
E22: Time to integrate +1 PSP (Months) | F22: =$C$12 -> 4 | G22: =$C$12 -> 4 | H22: =$C$12 -> 4 | I22: =$C$12 -> 4 | J22: =$C$12 -> 4 | L22: 4
E23: Total time of integration (Months) | F23: =F22*F21 -> 8 | G23: =G22*G21 -> 8 | H23: =H22*H21 -> 8 | I23: =I22*I21 -> 8 | J23: =J22*J21 -> 8 | L23: =SUM(F23:J23) -> 40
E24: Cost per month to integrate +1 PSP | K24: =SUM(K25:K31) -> 21600 | L24: =$K$24*$L$22 -> 86400 | M24: =L24*L22 -> 345600 | N24: *
E25: Product | F25: - | G25: - | H25: - | I25: - | J25: - | K25: 2250 | L25: =$K$25*$L$22 -> 9000 | M25: =$L$25*$L$21 -> 90000
E26: Engineering | F26: - | G26: - | H26: - | I26: - | J26: - | K26: 10500 | L26: =$K$26*$L$22 -> 42000 | M26: =$L$26*$L$21 -> 420000
E27: Fraud/Risk | F27: - | G27: - | H27: - | I27: - | J27: - | K27: 2250 | L27: =$K$27*$L$22 -> 9000 | M27: =$L$27*$L$21 -> 90000
E28: Treasury | F28: - | G28: - | H28: - | I28: - | J28: - | K28: 1350 | L28: =$K$28*$L$22 -> 5400 | M28: =$L$28*$L$21 -> 54000
E29: Compliance | F29: - | G29: - | H29: - | I29: - | J29: - | K29: 1500 | L29: =$K$29*$L$22 -> 6000 | M29: =$L$29*$L$21 -> 60000
E30: Finance | F30: - | G30: - | H30: - | I30: - | J30: - | K30: 1125 | L30: =$K$30*$L$22 -> 4500 | M30: =$L$30*$L$21 -> 45000
E31: Banking & Payments | F31: - | G31: - | H31: - | I31: - | J31: - | K31: 2625 | L31: =$K$31*$L$22 -> 10500 | M31: =$L$31*$L$21 -> 105000
E33: Total Dev/Engineering Savings | F33: APMs | G33: CARDS | H33: TOTAL | J33: Total time spent on integrations
E34: Product | F34: =M10 -> 114750 | G34: =M25 -> 90000 | H34: =SUM(F34:G34) -> 204750 | I34: * | J34: Months | K34: =($L$6*$L$7)+($L$21*$L$22) -> 91
E35: Engineering | F35: =M11 -> 535500 | G35: =M26 -> 420000 | H35: =SUM(F35:G35) -> 955500 | I35: * | J35: Years | K35: =round(K34/12,0) -> 8
E36: Fraud/Risk | F36: =M12 -> 114750 | G36: =M27 -> 90000 | H36: =SUM(F36:G36) -> 204750 | I36: * | J36: Yuno integration
E37: Treasury | F37: =M13 -> 68850 | G37: =M28 -> 54000 | H37: =SUM(F37:G37) -> 122850 | I37: * | J37: Months | K37: 2
E38: Compliance | F38: =M14 -> 76500 | G38: =M29 -> 60000 | H38: =SUM(F38:G38) -> 136500 | I38: * | J38: Difference | K38: =K34-K37 -> 89
E39: Finance | F39: =M15 -> 57375 | G39: =M30 -> 45000 | H39: =SUM(F39:G39) -> 102375 | I39: *
E40: Banking & Payments | F40: =M16 -> 133875 | G40: =M31 -> 105000 | H40: =SUM(F40:G40) -> 238875 | I40: * | J40: Total time saved (Months) | K40: =K38 -> 89 | L40: *
E41: Total Dev/Engineering Savings | F41: =SUM(F34:F40) -> 1101600 | G41: =SUM(G34:G40) -> 864000 | H41: =SUM(H34:H40)/1000000 -> 1.9656 | I41: * | J41: Total time saved (Years) | K41: =CONCATENATE(ROUNDUP(K42,2)," ","years") -> 7.42 years | L41: *
K42: =K40/12 -> 7.4166667

Sheet  BC Pay-ins NA
C2: TOP COUNTRIES AT REGION
B3: Aspect/Country | C3: United States | D3: Canada | H3: Total | J3: Range A | K3: Range A | M3: Explanation
B4: Web Traffic (SoW) | C4: 0.2284 | D4: 0.0332 | H4: =SUM(C4:G4) -> 0.2616 | M4: *This is coming from Similarweb: is the share (%) of web traffic visits per market.
B5: Web Traffic Visits | C5: =C4*RESUMEN!$C$13 -> 137040000 | D5: =D4*RESUMEN!$C$13 -> 19920000
B6: Conversion | C6: 0.1 | D6: 0.1
B7: View to Checkout | C7: =VLOOKUP(RESUMEN!$C$4,'Aceptance Rate Delta per Indust'!$B$3:$K$40,9,false) -> 0.1 | D7: =VLOOKUP(RESUMEN!$C$4,'Aceptance Rate Delta per Indust'!$B$3:$K$40,9,false) -> 0.1
B8: Checkout Succesfull | C8: =VLOOKUP(RESUMEN!$C$4,'Aceptance Rate Delta per Indust'!$B$3:$K$40,10,false) -> 0.7 | D8: =VLOOKUP(RESUMEN!$C$4,'Aceptance Rate Delta per Indust'!$B$3:$K$40,10,false) -> 0.7
B9: Succesful Transactions (x Year) | C9: =(ROUND(C5*C6,0)) -> 13704000 | D9: =(ROUND(D5*D6,0)) -> 1992000
B10: ATV | C10: 25 | D10: 23 | M10: *Average Ticket Value. You can get this from Chagpt - be aware that in some cases ATV con change per market, as some markets are more expensive than others.
B11: TPV (x Year) | C11: =(RESUMEN!$C$13*C4*C6*C10)/1000000 -> 342.6 | D11: =(RESUMEN!$C$13*D4*D6*D10)/1000000 -> 45.816 | H11: =SUM(C11:G11) -> 388.416
B12: SoW Cards (%) | C12: 0.95 | D12: 0.95 | M12: *Take into consideration which APMs the merchant has/lack in the checkout of each market, and the relevance of the APMs they have/lack. If the merchant does not have any APM available, then the SoW cards would be 100%.
B13: TPV Cards (x Year) | C13: =(C12*C11) -> 325.47 | D13: =(D12*D11) -> 43.5252 | H13: =SUM(C13:G13) -> 368.9952 | M13: *Millions/year
B14: SoW APMs (%) | C14: =1-C12 -> 0.05 | D14: =1-D12 -> 0.05 | M14: *SoW APMs is automatically calculated when inputing the SoW cards.
B15: TPV APMs (x Year) | C15: =C14*C11 -> 17.13 | D15: =D14*D11 -> 2.2908
B17: Cards
B18: Δ Acceptance rate (%) | C18: 0.03 | D18: 0.035 | H18: *
B19: Incremental TPV | C19: =C13*C18 -> 9.7641 | D19: =D13*D18 -> 1.523382 | H19: =SUM(C19:G19) -> 11.287482 | J19: =rounddown(H19-1,0) -> 10 | K19: =ROUNDUP(H19-1,0)+1 -> 12 | M19: *Millions/year
B20: Incremental Revenue | C20: =C19*RESUMEN!$C$15 -> 5.85846 | D20: =D19*RESUMEN!$C$15 -> 0.9140292 | H20: =SUM(C20:G20) -> 6.7724892 | J20: =rounddown(H20-1,0) -> 5 | K20: =ROUNDUP(H20-1,0)+1 -> 7 | M20: *Millions/year
B22: Annual Cards TPV/Country | C22: =C$11*C12+C19 -> 335.2341 | D22: =D$11*D12+D19 -> 45.048582
B23: Local entity? | C23: Yes | D23: Yes | M23: *You need to research if they do or if they dont have a local entity in each of the markets. By doing this, we could get to the assumption of what XB/Local MDR they are paying, and how much could help them reduce MDR fees.
B24: Current MDR based on Local Entity | C24: =if(C23="Yes",VLOOKUP(RESUMEN!$C$4,'Aceptance Rate Delta per Indust'!$B$3:$G$40,5,FALSE),VLOOKUP(RESUMEN!$C$4,'Aceptance Rate Delta per Indust'!$B$3:$G$40,6,FALSE)) -> 0.028 | D24: =if(D23="Yes",VLOOKUP(RESUMEN!$C$4,'Aceptance Rate Delta per Indust'!$B$3:$G$40,5,FALSE),VLOOKUP(RESUMEN!$C$4,'Aceptance Rate Delta per Indust'!$B$3:$G$40,6,FALSE)) -> 0.028 | M24: *If they have a local entity, we will assume that they are paying local MDR fees - if they don't have a local entity, we assume they are processing under Cross Border fees.
B25: Reduction in MDR | C25: =IFS(C23="Yes",-0.2%,C23="No",-1%) -> -0.002 | D25: =IFS(D23="Yes",-0.2%,D23="No",-1%) -> -0.002 | M25: *If they have local entity, we assume that maybe we can reduce their MDR fee in 0.2% due to local gateway/aggregators introductions. If they dont have local entity, we assume that we are going help them to move from Cross Border Fees to MoR fees.
B26: New MDR | C26: =C24+C25 -> 0.026 | D26: =D24+D25 -> 0.026
B27: MDR Reduction | C27: =C25*C22*-1 -> 0.6704682 | D27: =D25*D22*-1 -> 0.090097164 | H27: =SUM(C27:G27) -> 0.76056536 | I27: * | J27: =rounddown(H27-1,0) -> 0 | K27: =ROUNDUP(H27-1,0)+1 -> 0 | M27: *Millions/year
B29: Cards Benefit (revenue) | C29: =C27+C20 -> 6.5289282 | D29: =D27+D20 -> 1.0041264 | H29: =SUM(C29:G29) -> 7.5330546 | J29: * | M29: *This is the sum of the incremental revenue generated when increasing acceptance rate, and the MDR reduction generated when working with Yuno.
B31: APMs | C31: Apple Pay, Google Pay, Venmo, Cash App Pay | D31: Interac, Apple Pay, Google Pay | M31: *Which APMs is the merchant laking of in each of the markets?
B32: Annual APMs TPV/Country | C32: =C11*C14 -> 17.13 | D32: =D11*D14 -> 2.2908
B33: Current APMs | C33: 1 | D33: 3 | M33: *How many APMs does the merchant has at checkout in each of the markets
A34: **Esto deberia ser "programable" en base a cuantos APMs tiene el merchant y cuantos "buenos apms" hay por integrar | B34: APMs to Integrate | C34: 4 | D34: 3 | M34: *How many APMs could the merchat enable through our API? (AKA. Which crucial APMs are they lacking of in each of the markets?
A36: **Esto deberia ser "programable" en base a cuantos APMs tiene el merchant y cuantos "buenos apms" hay por integrar | B36: (%) Incremental Transactions | C36: 0.07 | D36: 0.07 | M36: *This is the % of new transactios coming through when enabling those new APMs. We need to be conservative here: - If we are offering relevant/crucial APMs: 8% - 12% (eg. PIX in Brazil, UPI in India, PayPal in UK) - If we are offering not that much relevant APMs in the market: 2% - 4% (eg. Boleto in Brazil, Dale in Colombia).
B37: APMs Incremental TPV | C37: =((1+C35)+(1+C36)-1)*C11-C11 -> 23.982 | D37: =((1+D35)+(1+D36)-1)*D11-D11 -> 3.20712 | H37: =SUM(C37:G37) -> 27.18912 | J37: =rounddown(H37-1,0) -> 26 | K37: =ROUNDUP(H37-1,0)+1 -> 28 | M37: *Millions/year
B39: APMs Incremental Revenue | C39: =C37*RESUMEN!$C$15 -> 14.3892 | D39: =D37*RESUMEN!$C$15 -> 1.924272 | H39: =SUM(C39:G39) -> 16.313472 | J39: =rounddown(H39-1,0) -> 15 | K39: =ROUNDUP(H39-1,0)+1 -> 17 | M39: *Millions/year
B41: (%) TPV from Cards to APMs | C41: 0.02 | D41: 0.03 | M41: *This is the % of card transactions shifted to APMs transactions thanks of them being enabled. We need to be conservative here: - If we are offering relevant/crucial APMs: 4% - 5% (eg. PIX in Brazil, UPI in India, PayPal in UK) - If we are offering not that much relevant APMs in the market: 1% - 2.5% (eg. Boleto in Brazil, Dale in Colombia).
B42: APMs Shifted TPV | C42: =C41*C11 -> 6.852 | D42: =D41*D11 -> 1.37448
B44: Cards MDR | C44: =C24 -> 0.028 | D44: =D24 -> 0.028
B45: APMs MDR Cost | C45: 0.012 | D45: 0.012
B47: APM MDR Savings | C47: =(C42+C37)*(C44-C45) -> 0.493344 | D47: =(D42+D37)*(D44-D45) -> 0.0733056 | H47: =SUM(C47:G47) -> 0.5666496 | J47: =if(H47>1,ROUNDUP(H47-1,0),H47) -> 0.5666496 | K47: =if(H47>1,ROUNDUP(H47-1,0),H47)+2 -> 2.5666496 | M47: *Millions/year
B49: APMs Benefit | C49: =C47+C39 -> 14.882544 | D49: =D47+D39 -> 1.9975776 | H49: =SUM(C49:G49) -> 16.880122 | M49: *This is the sum of the incremental revenue generated when including new APMs, and the MDR savings thanks to transactions going through APMs rather than cards.

Sheet Sheet5
B2: Company | C2: MSC Cruises | F2: Dev Engineering Cost Reduction
E3: Aspect/Country | F3: =' BC Pay-ins NA'!C3 -> United States | G3: =' BC Pay-ins NA'!D3 -> Canada | H3: =' BC Pay-ins NA'!E3 | I3: =' BC Pay-ins NA'!F3 | J3: =' BC Pay-ins NA'!G3 | K3: Cost Per integration/Month | L3: Total Cost Per Integration | M3: Total Cost for all Integrations
B4: Region | C4: LATAM | E4: APMs | P4: AGREGAR: 1. COSTO DE MANTENER LAS CONEXIONES POR AÑO - EJ: 80H/AÑO - HACIENDO ACTUALZIACIONES. 2. COSTO TIME TO MARKET
B5: Industry | C5: Train/bus/cruise Tickets | E5: Current APMs | F5: =' BC Pay-ins NA'!C33 -> 1 | G5: =' BC Pay-ins NA'!D33 -> 3 | L5: =SUM(F5:J5) -> 4
E6: APMs to Integrate | F6: =' BC Pay-ins NA'!C34 -> 4 | G6: =' BC Pay-ins NA'!D34 -> 3 | L6: =SUM(F6:J6) -> 7
E7: Time to integrate +1 APM (Months) | F7: =$C$11 -> 3 | G7: =$C$11 -> 3 | L7: 3
E8: Total time of integration (Months) | F8: =F7*F6 -> 12 | G8: =G7*G6 -> 9 | L8: =SUM(F8:J8) -> 21
B9: Key Inputs | E9: Cost per month to integrate +1 APM /month | K9: =SUM(K10:K16) -> 21600 | M9: =SUM(M10:M16) -> 453600 | N9: *
B10: Time to integrate | C10: Months | E10: Product | F10: - | G10: - | K10: 2250 | L10: =$K$10*$L$7 -> 6750 | M10: =L10*$L$6 -> 47250
B11: APMs | C11: 3 | E11: Engineering | F11: - | G11: - | K11: 10500 | L11: =$K$11*$L$7 -> 31500 | M11: =L11*$L$6 -> 220500
B12: Cards | C12: 4 | E12: Fraud/Risk | F12: - | G12: - | K12: 2250 | L12: =$K$12*$L$7 -> 6750 | M12: =L12*$L$6 -> 47250
E13: Treasury | F13: - | G13: - | K13: 1350 | L13: =$K$13*$L$7 -> 4050 | M13: =L13*$L$6 -> 28350
B14: Blue and Yellow | C14: Inputs SDR | E14: Compliance | F14: - | G14: - | K14: 1500 | L14: =$K$14*$L$7 -> 4500 | M14: =L14*$L$6 -> 31500
B15: Red | C15: Similar Web / Research / Bloomberg | E15: Finance | F15: - | G15: - | K15: 1125 | L15: =$K$15*$L$7 -> 3375 | M15: =L15*$L$6 -> 23625
B16: Green | C16: Formulas de reglas establecidas en otras hojas | E16: Banking & Payments | F16: - | G16: - | K16: 2625 | L16: =$K$16*$L$7 -> 7875 | M16: =L16*$L$6 -> 55125
B17: * | C17: Send to presentation
E18: Cards
E19: Local entity? | F19: =' BC Pay-ins NA'!C23 -> Yes | G19: =' BC Pay-ins NA'!D23 -> Yes
E20: Need MoR/Local Processing Integration? | F20: =if(F19="Yes","No","Yes") -> No | G20: =if(G19="Yes","No","Yes") -> No
E21: MoR/Local Processor to Integrate | F21: =if(F19="yes",1,2) -> 1 | G21: =if(G19="yes",1,2) -> 1 | L21: =SUM(F21:J21) -> 2
E22: Time to integrate +1 PSP (Months) | F22: =$C$12 -> 4 | G22: =$C$12 -> 4 | L22: 4
E23: Total time of integration (Months) | F23: =F22*F21 -> 4 | G23: =G22*G21 -> 4 | L23: =SUM(F23:J23) -> 8
E24: Cost per month to integrate +1 PSP | K24: =SUM(K25:K31) -> 21600 | L24: =$K$24*$L$22 -> 86400 | M24: =L24*L22 -> 345600 | N24: *
E25: Product | F25: - | G25: - | K25: 2250 | L25: =$K$25*$L$22 -> 9000 | M25: =$L$25*$L$21 -> 18000
E26: Engineering | F26: - | G26: - | K26: 10500 | L26: =$K$26*$L$22 -> 42000 | M26: =$L$26*$L$21 -> 84000
E27: Fraud/Risk | F27: - | G27: - | K27: 2250 | L27: =$K$27*$L$22 -> 9000 | M27: =$L$27*$L$21 -> 18000
E28: Treasury | F28: - | G28: - | K28: 1350 | L28: =$K$28*$L$22 -> 5400 | M28: =$L$28*$L$21 -> 10800
E29: Compliance | F29: - | G29: - | K29: 1500 | L29: =$K$29*$L$22 -> 6000 | M29: =$L$29*$L$21 -> 12000
E30: Finance | F30: - | G30: - | K30: 1125 | L30: =$K$30*$L$22 -> 4500 | M30: =$L$30*$L$21 -> 9000
E31: Banking & Payments | F31: - | G31: - | K31: 2625 | L31: =$K$31*$L$22 -> 10500 | M31: =$L$31*$L$21 -> 21000
E33: Total Dev/Engineering Savings | F33: APMs | G33: CARDS | H33: TOTAL | J33: Total time spent on integrations
E34: Product | F34: =M10 -> 47250 | G34: =M25 -> 18000 | H34: =SUM(F34:G34) -> 65250 | I34: * | J34: Months | K34: =($L$6*$L$7)+($L$21*$L$22) -> 29
E35: Engineering | F35: =M11 -> 220500 | G35: =M26 -> 84000 | H35: =SUM(F35:G35) -> 304500 | I35: * | J35: Years | K35: =round(K34/12,0) -> 2
E36: Fraud/Risk | F36: =M12 -> 47250 | G36: =M27 -> 18000 | H36: =SUM(F36:G36) -> 65250 | I36: * | J36: Yuno integration
E37: Treasury | F37: =M13 -> 28350 | G37: =M28 -> 10800 | H37: =SUM(F37:G37) -> 39150 | I37: * | J37: Months | K37: 2
E38: Compliance | F38: =M14 -> 31500 | G38: =M29 -> 12000 | H38: =SUM(F38:G38) -> 43500 | I38: * | J38: Difference | K38: =K34-K37 -> 27
E39: Finance | F39: =M15 -> 23625 | G39: =M30 -> 9000 | H39: =SUM(F39:G39) -> 32625 | I39: *
E40: Banking & Payments | F40: =M16 -> 55125 | G40: =M31 -> 21000 | H40: =SUM(F40:G40) -> 76125 | I40: * | J40: Total time saved (Months) | K40: =K38 -> 27 | L40: *
E41: Total Dev/Engineering Savings | F41: =SUM(F34:F40) -> 453600 | G41: =SUM(G34:G40) -> 172800 | H41: =SUM(H34:H40)/1000000 -> 0.6264 | I41: * | J41: Total time saved (Years) | K41: =CONCATENATE(ROUNDUP(K42,2)," ","years") -> 2.25 years | L41: *
K42: =K40/12 -> 2.25

Sheet BC Pay-ins EMEA
C2: TOP COUNTRIES AT REGION
B3: Aspect/Country | C3: Germany | D3: United Kingdom | E3: Spain | F3: Netherlands | G3: France | H3: Total | J3: Range A | K3: Range A | M3: Explanation
B4: Web Traffic (SoW) | C4: 0.069 | D4: 0.0485 | E4: 0.0401 | F4: 0.022 | G4: 0.0217 | H4: =SUM(C4:G4) -> 0.2013 | M4: *This is coming from Similarweb: is the share (%) of web traffic visits per market.
B5: Web Traffic Visits | C5: =C4*RESUMEN!$C$13 -> 41400000 | D5: =D4*RESUMEN!$C$13 -> 29100000 | E5: =E4*RESUMEN!$C$13 -> 24060000 | F5: =F4*RESUMEN!$C$13 -> 13200000 | G5: =G4*RESUMEN!$C$13 -> 13020000
B6: Conversion | C6: 0.1 | D6: 0.1 | E6: 0.1 | F6: 0.1 | G6: 0.1
B7: View to Checkout | C7: =VLOOKUP(RESUMEN!$C$4,'Aceptance Rate Delta per Indust'!$B$3:$K$40,9,false) -> 0.1 | D7: =VLOOKUP(RESUMEN!$C$4,'Aceptance Rate Delta per Indust'!$B$3:$K$40,9,false) -> 0.1 | E7: =VLOOKUP(RESUMEN!$C$4,'Aceptance Rate Delta per Indust'!$B$3:$K$40,9,false) -> 0.1 | F7: =VLOOKUP(RESUMEN!$C$4,'Aceptance Rate Delta per Indust'!$B$3:$K$40,9,false) -> 0.1 | G7: =VLOOKUP(RESUMEN!$C$4,'Aceptance Rate Delta per Indust'!$B$3:$K$40,9,false) -> 0.1
B8: Checkout Succesfull | C8: =VLOOKUP(RESUMEN!$C$4,'Aceptance Rate Delta per Indust'!$B$3:$K$40,10,false) -> 0.7 | D8: =VLOOKUP(RESUMEN!$C$4,'Aceptance Rate Delta per Indust'!$B$3:$K$40,10,false) -> 0.7 | E8: =VLOOKUP(RESUMEN!$C$4,'Aceptance Rate Delta per Indust'!$B$3:$K$40,10,false) -> 0.7 | F8: =VLOOKUP(RESUMEN!$C$4,'Aceptance Rate Delta per Indust'!$B$3:$K$40,10,false) -> 0.7 | G8: =VLOOKUP(RESUMEN!$C$4,'Aceptance Rate Delta per Indust'!$B$3:$K$40,10,false) -> 0.7
B9: Succesful Transactions (x Year) | C9: =(ROUND(C5*C6,0)) -> 4140000 | D9: =(ROUND(D5*D6,0)) -> 2910000 | E9: =(ROUND(E5*E6,0)) -> 2406000 | F9: =(ROUND(F5*F6,0)) -> 1320000 | G9: =(ROUND(G5*G6,0)) -> 1302000
B10: ATV | C10: 22 | D10: 23 | E10: 18 | F10: 22 | G10: 20 | M10: *Average Ticket Value. You can get this from Chagpt - be aware that in some cases ATV con change per market, as some markets are more expensive than others.
B11: TPV (x Year) | C11: =(RESUMEN!$C$13*C4*C6*C10)/1000000 -> 91.08 | D11: =(RESUMEN!$C$13*D4*D6*D10)/1000000 -> 66.93 | E11: =(RESUMEN!$C$13*E4*E6*E10)/1000000 -> 43.308 | F11: =(RESUMEN!$C$13*F4*F6*F10)/1000000 -> 29.04 | G11: =(RESUMEN!$C$13*G4*G6*G10)/1000000 -> 26.04 | H11: =SUM(C11:G11) -> 256.398
B12: SoW Cards (%) | C12: 1 | D12: 0.95 | E12: 1 | F12: 1 | G12: 1 | M12: *Take into consideration which APMs the merchant has/lack in the checkout of each market, and the relevance of the APMs they have/lack. If the merchant does not have any APM available, then the SoW cards would be 100%.
B13: TPV Cards (x Year) | C13: =(C12*C11) -> 91.08 | D13: =(D12*D11) -> 63.5835 | E13: =(E12*E11) -> 43.308 | F13: =(F12*F11) -> 29.04 | G13: =G12*G11 -> 26.04 | H13: =SUM(C13:G13) -> 253.0515 | M13: *Millions/year
B14: SoW APMs (%) | C14: =1-C12 -> 0 | D14: =1-D12 -> 0.05 | E14: =1-E12 -> 0 | F14: =1-F12 -> 0 | G14: =1-G12 -> 0 | M14: *SoW APMs is automatically calculated when inputing the SoW cards.
B15: TPV APMs (x Year) | C15: =C14*C11 -> 0 | D15: =D14*D11 -> 3.3465 | E15: =E14*E11 -> 0 | F15: =F14*F11 -> 0 | G15: =G14*G11 -> 0
B17: Cards
B18: Δ Acceptance rate (%) | C18: 0.03 | D18: 0.03 | E18: 0.03 | F18: 0.06 | G18: 0.03 | H18: *
B19: Incremental TPV | C19: =C13*C18 -> 2.7324 | D19: =D13*D18 -> 1.907505 | E19: =E13*E18 -> 1.29924 | F19: =F13*F18 -> 1.7424 | G19: =G13*G18 -> 0.7812 | H19: =SUM(C19:G19) -> 8.462745 | J19: =rounddown(H19-1,0) -> 7 | K19: =ROUNDUP(H19-1,0)+1 -> 9 | M19: *Millions/year
B20: Incremental Revenue | C20: =C19*RESUMEN!$C$15 -> 1.63944 | D20: =D19*RESUMEN!$C$15 -> 1.144503 | E20: =E19*RESUMEN!$C$15 -> 0.779544 | F20: =F19*RESUMEN!$C$15 -> 1.04544 | G20: =G19*RESUMEN!$C$15 -> 0.46872 | H20: =SUM(C20:G20) -> 5.077647 | J20: =rounddown(H20-1,0) -> 4 | K20: =ROUNDUP(H20-1,0)+1 -> 6 | M20: *Millions/year
B22: Annual Cards TPV/Country | C22: =C$11*C12+C19 -> 93.8124 | D22: =D$11*D12+D19 -> 65.491005 | E22: =E$11*E12+E19 -> 44.60724 | F22: =F$11*F12+F19 -> 30.7824 | G22: =G$11*G12+G19 -> 26.8212
B23: Local entity? | C23: Yes | D23: Yes | E23: Yes | F23: Yes | G23: Yes | M23: *You need to research if they do or if they dont have a local entity in each of the markets. By doing this, we could get to the assumption of what XB/Local MDR they are paying, and how much could help them reduce MDR fees.
B24: Current MDR based on Local Entity | C24: =if(C23="Yes",VLOOKUP(RESUMEN!$C$4,'Aceptance Rate Delta per Indust'!$B$3:$G$40,5,FALSE),VLOOKUP(RESUMEN!$C$4,'Aceptance Rate Delta per Indust'!$B$3:$G$40,6,FALSE)) -> 0.028 | D24: =if(D23="Yes",VLOOKUP(RESUMEN!$C$4,'Aceptance Rate Delta per Indust'!$B$3:$G$40,5,FALSE),VLOOKUP(RESUMEN!$C$4,'Aceptance Rate Delta per Indust'!$B$3:$G$40,6,FALSE)) -> 0.028 | E24: =if(E23="Yes",VLOOKUP(RESUMEN!$C$4,'Aceptance Rate Delta per Indust'!$B$3:$G$40,5,FALSE),VLOOKUP(RESUMEN!$C$4,'Aceptance Rate Delta per Indust'!$B$3:$G$40,6,FALSE)) -> 0.028 | F24: =if(F23="Yes",VLOOKUP(RESUMEN!$C$4,'Aceptance Rate Delta per Indust'!$B$3:$G$40,5,FALSE),VLOOKUP(RESUMEN!$C$4,'Aceptance Rate Delta per Indust'!$B$3:$G$40,6,FALSE)) -> 0.028 | G24: =if(G23="Yes",VLOOKUP(RESUMEN!$C$4,'Aceptance Rate Delta per Indust'!$B$3:$G$40,5,FALSE),VLOOKUP(RESUMEN!$C$4,'Aceptance Rate Delta per Indust'!$B$3:$G$40,6,FALSE)) -> 0.028 | M24: *If they have a local entity, we will assume that they are paying local MDR fees - if they don't have a local entity, we assume they are processing under Cross Border fees.
B25: Reduction in MDR | C25: =IFS(C23="Yes",-0.2%,C23="No",-1%) -> -0.002 | D25: =IFS(D23="Yes",-0.2%,D23="No",-1%) -> -0.002 | E25: =IFS(E23="Yes",-0.2%,E23="No",-1%) -> -0.002 | F25: =IFS(F23="Yes",-0.2%,F23="No",-1%) -> -0.002 | G25: =IFS(G23="Yes",-0.2%,G23="No",-1%) -> -0.002 | M25: *If they have local entity, we assume that maybe we can reduce their MDR fee in 0.2% due to local gateway/aggregators introductions. If they dont have local entity, we assume that we are going help them to move from Cross Border Fees to MoR fees.
B26: New MDR | C26: =C24+C25 -> 0.026 | D26: =D24+D25 -> 0.026 | E26: =E24+E25 -> 0.026 | F26: =F24+F25 -> 0.026 | G26: =G24+G25 -> 0.026
B27: MDR Reduction | C27: =C25*C22*-1 -> 0.1876248 | D27: =D25*D22*-1 -> 0.13098201 | E27: =E25*E22*-1 -> 0.08921448 | F27: =F25*F22*-1 -> 0.0615648 | G27: =G25*G22*-1 -> 0.0536424 | H27: =SUM(C27:G27) -> 0.52302849 | I27: * | J27: =rounddown(H27-1,0) -> 0 | K27: =ROUNDUP(H27-1,0)+1 -> 0 | M27: *Millions/year
B29: Cards Benefit (revenue) | C29: =C27+C20 -> 1.8270648 | D29: =D27+D20 -> 1.275485 | E29: =E27+E20 -> 0.86875848 | F29: =F27+F20 -> 1.1070048 | G29: =G27+G20 -> 0.5223624 | H29: =SUM(C29:G29) -> 5.6006755 | J29: * | M29: *This is the sum of the incremental revenue generated when increasing acceptance rate, and the MDR reduction generated when working with Yuno.
B31: APMs | C31: SEPA Direct Debit, Klarna, Sofort, PayPal | D31: Open Banking, Klarna, Apple Pay | E31: Bizum, SEPA, Apple Pay | F31: iDEAL, SEPA, Bancontact | G31: Carte Bancaire, SEPA, Apple Pay | M31: *Which APMs is the merchant laking of in each of the markets?
B32: Annual APMs TPV/Country | C32: =C11*C14 -> 0 | D32: =D11*D14 -> 3.3465 | E32: =E11*E14 -> 0 | F32: =F11*F14 -> 0 | G32: =G11*G14 -> 0
B33: Current APMs | C33: 0 | D33: 2 | E33: 2 | F33: 2 | G33: 2 | M33: *How many APMs does the merchant has at checkout in each of the markets
A34: **Esto deberia ser "programable" en base a cuantos APMs tiene el merchant y cuantos "buenos apms" hay por integrar | B34: APMs to Integrate | C34: 4 | D34: 3 | E34: 3 | F34: 3 | G34: 3 | M34: *How many APMs could the merchat enable through our API? (AKA. Which crucial APMs are they lacking of in each of the markets?
A36: **Esto deberia ser "programable" en base a cuantos APMs tiene el merchant y cuantos "buenos apms" hay por integrar | B36: (%) Incremental Transactions | C36: 0.07 | D36: 0.06 | E36: 0.1 | F36: 0.1 | G36: 0.07 | M36: *This is the % of new transactios coming through when enabling those new APMs. We need to be conservative here: - If we are offering relevant/crucial APMs: 8% - 12% (eg. PIX in Brazil, UPI in India, PayPal in UK) - If we are offering not that much relevant APMs in the market: 2% - 4% (eg. Boleto in Brazil, Dale in Colombia).
B37: APMs Incremental TPV | C37: =((1+C35)+(1+C36)-1)*C11-C11 -> 6.3756 | D37: =((1+D35)+(1+D36)-1)*D11-D11 -> 4.0158 | E37: =((1+E35)+(1+E36)-1)*E11-E11 -> 4.3308 | F37: =((1+F35)+(1+F36)-1)*F11-F11 -> 2.904 | G37: =((1+G35)+(1+G36)-1)*G11-G11 -> 1.8228 | H37: =SUM(C37:G37) -> 19.449 | J37: =rounddown(H37-1,0) -> 18 | K37: =ROUNDUP(H37-1,0)+1 -> 20 | M37: *Millions/year
B39: APMs Incremental Revenue | C39: =C37*RESUMEN!$C$15 -> 3.82536 | D39: =D37*RESUMEN!$C$15 -> 2.40948 | E39: =E37*RESUMEN!$C$15 -> 2.59848 | F39: =F37*RESUMEN!$C$15 -> 1.7424 | G39: =G37*RESUMEN!$C$15 -> 1.09368 | H39: =SUM(C39:G39) -> 11.6694 | J39: =rounddown(H39-1,0) -> 10 | K39: =ROUNDUP(H39-1,0)+1 -> 12 | M39: *Millions/year
B41: (%) TPV from Cards to APMs | C41: 0.03 | D41: 0.02 | E41: 0.04 | F41: 0.05 | G41: 0.03 | M41: *This is the % of card transactions shifted to APMs transactions thanks of them being enabled. We need to be conservative here: - If we are offering relevant/crucial APMs: 4% - 5% (eg. PIX in Brazil, UPI in India, PayPal in UK) - If we are offering not that much relevant APMs in the market: 1% - 2.5% (eg. Boleto in Brazil, Dale in Colombia).
B42: APMs Shifted TPV | C42: =C41*C11 -> 2.7324 | D42: =D41*D11 -> 1.3386 | E42: =E41*E11 -> 1.73232 | F42: =F41*F11 -> 1.452 | G42: =G41*G11 -> 0.7812
B44: Cards MDR | C44: =C24 -> 0.028 | D44: =D24 -> 0.028 | E44: =E24 -> 0.028 | F44: =F24 -> 0.028 | G44: =G24 -> 0.028
B45: APMs MDR Cost | C45: 0.012 | D45: 0.012 | E45: 0.012 | F45: 0.012 | G45: 0.012
B47: APM MDR Savings | C47: =(C42+C37)*(C44-C45) -> 0.145728 | D47: =(D42+D37)*(D44-D45) -> 0.0856704 | E47: =(E42+E37)*(E44-E45) -> 0.09700992 | F47: =(F42+F37)*(F44-F45) -> 0.069696 | G47: =(G42+G37)*(G44-G45) -> 0.041664 | H47: =SUM(C47:G47) -> 0.43976832 | J47: =if(H47>1,ROUNDUP(H47-1,0),H47) -> 0.43976832 | K47: =if(H47>1,ROUNDUP(H47-1,0),H47)+2 -> 2.4397683 | M47: *Millions/year
B49: APMs Benefit | C49: =C47+C39 -> 3.971088 | D49: =D47+D39 -> 2.4951504 | E49: =E47+E39 -> 2.6954899 | F49: =F47+F39 -> 1.812096 | G49: =G47+G39 -> 1.135344 | H49: =SUM(C49:G49) -> 12.109168 | M49: *This is the sum of the incremental revenue generated when including new APMs, and the MDR savings thanks to transactions going through APMs rather than cards.

Sheet Sheet6
B2: Company | C2: AIRBNB | F2: Dev Engineering Cost Reduction
E3: Aspect/Country | F3: ='BC Pay-ins EMEA'!C3 -> Germany | G3: ='BC Pay-ins EMEA'!D3 -> United Kingdom | H3: ='BC Pay-ins EMEA'!E3 -> Spain | I3: ='BC Pay-ins EMEA'!F3 -> Netherlands | J3: ='BC Pay-ins EMEA'!G3 -> France | K3: Cost Per integration/Month | L3: Total Cost Per Integration | M3: Total Cost for all Integrations
B4: Region | C4: LATAM | E4: APMs | P4: AGREGAR: 1. COSTO DE MANTENER LAS CONEXIONES POR AÑO - EJ: 80H/AÑO - HACIENDO ACTUALZIACIONES. 2. COSTO TIME TO MARKET
B5: Industry | C5: Travel/OTAs | E5: Current APMs | F5: ='BC Pay-ins EMEA'!C33 -> 0 | G5: ='BC Pay-ins EMEA'!D33 -> 2 | H5: ='BC Pay-ins EMEA'!E33 -> 2 | I5: ='BC Pay-ins EMEA'!F33 -> 2 | J5: ='BC Pay-ins EMEA'!G33 -> 2 | L5: =SUM(F5:J5) -> 8
E6: APMs to Integrate | F6: ='BC Pay-ins EMEA'!C34 -> 4 | G6: ='BC Pay-ins EMEA'!D34 -> 3 | H6: ='BC Pay-ins EMEA'!E34 -> 3 | I6: ='BC Pay-ins EMEA'!F34 -> 3 | J6: ='BC Pay-ins EMEA'!G34 -> 3 | L6: =SUM(F6:J6) -> 16
E7: Time to integrate +1 APM (Months) | F7: =$C$11 -> 3 | G7: =$C$11 -> 3 | H7: =$C$11 -> 3 | I7: =$C$11 -> 3 | J7: =$C$11 -> 3 | L7: 3
E8: Total time of integration (Months) | F8: =F7*F6 -> 12 | G8: =G7*G6 -> 9 | H8: =H7*H6 -> 9 | I8: =I7*I6 -> 9 | J8: =J7*J6 -> 9 | L8: =SUM(F8:J8) -> 48
B9: Key Inputs | E9: Cost per month to integrate +1 APM /month | K9: =SUM(K10:K16) -> 21600 | M9: =SUM(M10:M16) -> 1036800 | N9: *
B10: Time to integrate | C10: Months | E10: Product | F10: - | G10: - | H10: - | I10: - | J10: - | K10: 2250 | L10: =$K$10*$L$7 -> 6750 | M10: =L10*$L$6 -> 108000
B11: APMs | C11: 3 | E11: Engineering | F11: - | G11: - | H11: - | I11: - | J11: - | K11: 10500 | L11: =$K$11*$L$7 -> 31500 | M11: =L11*$L$6 -> 504000
B12: Cards | C12: 4 | E12: Fraud/Risk | F12: - | G12: - | H12: - | I12: - | J12: - | K12: 2250 | L12: =$K$12*$L$7 -> 6750 | M12: =L12*$L$6 -> 108000
